Workbook

Sheet Birbank Ştat
A1: New | B1: Cəmi | C1: İşçi sayı | D1: müvəqqəti | E1: vakant | F1: Non agile, agile, filial | G1: qeyd | H1: Vertical | I1: Pashapay | J1: Birmarket | K1: Paşa holding | L1: Future lab | M1: Cəmi keçid sayı
A2: Data governance ekspert mərkəzi | B2: 19 | C2: 20 | D2: 0 | E2: =B2-C2+D2 -> -1 | F2: Agile | G2: mənfilər-atrən səfərli HRBP məlumat verilib-04.10.2026 mail | H2: Ekosistem | I2: =COUNTIFS('baza-04.10.2026'!C:C,'Birbank Ştat'!A:A,'baza-04.10.2026'!I:I,"Bir Payment") -> 0 | J2: =COUNTIFS('baza-04.10.2026'!C:C,'Birbank Ştat'!A:A,'baza-04.10.2026'!I:I,"BirMarket") -> 5 | K2: =COUNTIFS('baza-04.10.2026'!C:C,'Birbank Ştat'!A:A,'baza-04.10.2026'!I:I,"Paşa Holding") -> 1 | L2: =COUNTIFS('baza-04.10.2026'!C:C,'Birbank Ştat'!A:A,'baza-04.10.2026'!I:I,"Future lab") -> 0 | M2: =Table2[[#This Row],[Pashapay]]+Table2[[#This Row],[Birmarket]]+Table2[[#This Row],[Paşa holding]]+Table2[[#This Row],[Future lab]] -> 6
A3: Ekvayrinq texnologiyaları sahəsi | B3: 3 | C3: 4 | D3: 0 | E3: =B3-C3+D3 -> -1 | F3: Agile | G3: mənfilər-atrən səfərli HRBP məlumat verilib-04.10.2026 mail | H3: Payment | I3: =COUNTIFS('baza-04.10.2026'!C:C,'Birbank Ştat'!A:A,'baza-04.10.2026'!I:I,"Bir Payment") -> 0 | J3: =COUNTIFS('baza-04.10.2026'!C:C,'Birbank Ştat'!A:A,'baza-04.10.2026'!I:I,"BirMarket") -> 0 | K3: =COUNTIFS('baza-04.10.2026'!C:C,'Birbank Ştat'!A:A,'baza-04.10.2026'!I:I,"Paşa Holding") -> 0 | L3: =COUNTIFS('baza-04.10.2026'!C:C,'Birbank Ştat'!A:A,'baza-04.10.2026'!I:I,"Future lab") -> 0 | M3: =Table2[[#This Row],[Pashapay]]+Table2[[#This Row],[Birmarket]]+Table2[[#This Row],[Paşa holding]]+Table2[[#This Row],[Future lab]] -> 0
A4: Maliyyə hesabatlığı və mühasibatlıq departamenti | B4: 38 | C4: 38 | D4: 0 | E4: =B4-C4+D4 -> 0 | F4: Non-Agile | H4: Fintech | I4: =COUNTIFS('baza-04.10.2026'!C:C,'Birbank Ştat'!A:A,'baza-04.10.2026'!I:I,"Bir Payment") -> 3 | J4: =COUNTIFS('baza-04.10.2026'!C:C,'Birbank Ştat'!A:A,'baza-04.10.2026'!I:I,"BirMarket") -> 1 | K4: =COUNTIFS('baza-04.10.2026'!C:C,'Birbank Ştat'!A:A,'baza-04.10.2026'!I:I,"Paşa Holding") -> 0 | L4: =COUNTIFS('baza-04.10.2026'!C:C,'Birbank Ştat'!A:A,'baza-04.10.2026'!I:I,"Future lab") -> 0 | M4: =Table2[[#This Row],[Pashapay]]+Table2[[#This Row],[Birmarket]]+Table2[[#This Row],[Paşa holding]]+Table2[[#This Row],[Future lab]] -> 4
A5: Komplayens departamenti | B5: 53 | C5: 54 | D5: 2 | E5: =B5-C5+D5 -> 1 | F5: Non-Agile | G5: 1 hüquqdan | H5: Fintech | I5: =COUNTIFS('baza-04.10.2026'!C:C,'Birbank Ştat'!A:A,'baza-04.10.2026'!I:I,"Bir Payment") -> 3 | J5: =COUNTIFS('baza-04.10.2026'!C:C,'Birbank Ştat'!A:A,'baza-04.10.2026'!I:I,"BirMarket") -> 1 | K5: =COUNTIFS('baza-04.10.2026'!C:C,'Birbank Ştat'!A:A,'baza-04.10.2026'!I:I,"Paşa Holding") -> 0 | L5: =COUNTIFS('baza-04.10.2026'!C:C,'Birbank Ştat'!A:A,'baza-04.10.2026'!I:I,"Future lab") -> 0 | M5: =Table2[[#This Row],[Pashapay]]+Table2[[#This Row],[Birmarket]]+Table2[[#This Row],[Paşa holding]]+Table2[[#This Row],[Future lab]] -> 4
A6: Kart biznesi ekspert mərkəzi | B6: 12 | C6: 12 | D6: 0 | E6: =B6-C6+D6 -> 0 | F6: Agile | H6: Payment | I6: =COUNTIFS('baza-04.10.2026'!C:C,'Birbank Ştat'!A:A,'baza-04.10.2026'!I:I,"Bir Payment") -> 0 | J6: =COUNTIFS('baza-04.10.2026'!C:C,'Birbank Ştat'!A:A,'baza-04.10.2026'!I:I,"BirMarket") -> 0 | K6: =COUNTIFS('baza-04.10.2026'!C:C,'Birbank Ştat'!A:A,'baza-04.10.2026'!I:I,"Paşa Holding") -> 0 | L6: =COUNTIFS('baza-04.10.2026'!C:C,'Birbank Ştat'!A:A,'baza-04.10.2026'!I:I,"Future lab") -> 0 | M6: =Table2[[#This Row],[Pashapay]]+Table2[[#This Row],[Birmarket]]+Table2[[#This Row],[Paşa holding]]+Table2[[#This Row],[Future lab]] -> 0
A7: Rəqəmsal həllər sahəsi | B7: 6 | C7: 6 | D7: 0 | E7: =B7-C7+D7 -> 0 | F7: Agile | H7: Fintech | I7: =COUNTIFS('baza-04.10.2026'!C:C,'Birbank Ştat'!A:A,'baza-04.10.2026'!I:I,"Bir Payment") -> 0 | J7: =COUNTIFS('baza-04.10.2026'!C:C,'Birbank Ştat'!A:A,'baza-04.10.2026'!I:I,"BirMarket") -> 0 | K7: =COUNTIFS('baza-04.10.2026'!C:C,'Birbank Ştat'!A:A,'baza-04.10.2026'!I:I,"Paşa Holding") -> 0 | L7: =COUNTIFS('baza-04.10.2026'!C:C,'Birbank Ştat'!A:A,'baza-04.10.2026'!I:I,"Future lab") -> 0 | M7: =Table2[[#This Row],[Pashapay]]+Table2[[#This Row],[Birmarket]]+Table2[[#This Row],[Paşa holding]]+Table2[[#This Row],[Future lab]] -> 0
A8: Beynəlxalq hesabatlıq və MİS departamenti | B8: 15 | C8: 14 | D8: 1 | E8: =B8-C8+D8 -> 2 | F8: Non-Agile | G8: 1 elave pashapaydan, 1 elave yaz İH-tamilla x | H8: Ekosistem | I8: =COUNTIFS('baza-04.10.2026'!C:C,'Birbank Ştat'!A:A,'baza-04.10.2026'!I:I,"Bir Payment") -> 0 | J8: =COUNTIFS('baza-04.10.2026'!C:C,'Birbank Ştat'!A:A,'baza-04.10.2026'!I:I,"BirMarket") -> 0 | K8: =COUNTIFS('baza-04.10.2026'!C:C,'Birbank Ştat'!A:A,'baza-04.10.2026'!I:I,"Paşa Holding") -> 0 | L8: =COUNTIFS('baza-04.10.2026'!C:C,'Birbank Ştat'!A:A,'baza-04.10.2026'!I:I,"Future lab") -> 0 | M8: =Table2[[#This Row],[Pashapay]]+Table2[[#This Row],[Birmarket]]+Table2[[#This Row],[Paşa holding]]+Table2[[#This Row],[Future lab]] -> 0
A9: FinTech arxitektura və İT idarəetmə prosesi | B9: 3 | C9: 3 | D9: 0 | E9: =B9-C9+D9 -> 0 | F9: Agile | H9: Fintech | I9: =COUNTIFS('baza-04.10.2026'!C:C,'Birbank Ştat'!A:A,'baza-04.10.2026'!I:I,"Bir Payment") -> 0 | J9: =COUNTIFS('baza-04.10.2026'!C:C,'Birbank Ştat'!A:A,'baza-04.10.2026'!I:I,"BirMarket") -> 0 | K9: =COUNTIFS('baza-04.10.2026'!C:C,'Birbank Ştat'!A:A,'baza-04.10.2026'!I:I,"Paşa Holding") -> 0 | L9: =COUNTIFS('baza-04.10.2026'!C:C,'Birbank Ştat'!A:A,'baza-04.10.2026'!I:I,"Future lab") -> 0 | M9: =Table2[[#This Row],[Pashapay]]+Table2[[#This Row],[Birmarket]]+Table2[[#This Row],[Paşa holding]]+Table2[[#This Row],[Future lab]] -> 0
A10: Prosessinq sahəsi | B10: 3 | C10: 3 | D10: 0 | E10: =B10-C10+D10 -> 0 | F10: Agile | H10: Payment | I10: =COUNTIFS('baza-04.10.2026'!C:C,'Birbank Ştat'!A:A,'baza-04.10.2026'!I:I,"Bir Payment") -> 0 | J10: =COUNTIFS('baza-04.10.2026'!C:C,'Birbank Ştat'!A:A,'baza-04.10.2026'!I:I,"BirMarket") -> 0 | K10: =COUNTIFS('baza-04.10.2026'!C:C,'Birbank Ştat'!A:A,'baza-04.10.2026'!I:I,"Paşa Holding") -> 0 | L10: =COUNTIFS('baza-04.10.2026'!C:C,'Birbank Ştat'!A:A,'baza-04.10.2026'!I:I,"Future lab") -> 0 | M10: =Table2[[#This Row],[Pashapay]]+Table2[[#This Row],[Birmarket]]+Table2[[#This Row],[Paşa holding]]+Table2[[#This Row],[Future lab]] -> 0
A11: FinTech platformalar sahəsi | B11: 3 | C11: 3 | D11: 0 | E11: =B11-C11+D11 -> 0 | F11: Agile | H11: Fintech | I11: =COUNTIFS('baza-04.10.2026'!C:C,'Birbank Ştat'!A:A,'baza-04.10.2026'!I:I,"Bir Payment") -> 0 | J11: =COUNTIFS('baza-04.10.2026'!C:C,'Birbank Ştat'!A:A,'baza-04.10.2026'!I:I,"BirMarket") -> 0 | K11: =COUNTIFS('baza-04.10.2026'!C:C,'Birbank Ştat'!A:A,'baza-04.10.2026'!I:I,"Paşa Holding") -> 0 | L11: =COUNTIFS('baza-04.10.2026'!C:C,'Birbank Ştat'!A:A,'baza-04.10.2026'!I:I,"Future lab") -> 0 | M11: =Table2[[#This Row],[Pashapay]]+Table2[[#This Row],[Birmarket]]+Table2[[#This Row],[Paşa holding]]+Table2[[#This Row],[Future lab]] -> 0
A12: Ödəniş və transferlər sahəsi | B12: 3 | C12: 3 | D12: 0 | E12: =B12-C12+D12 -> 0 | F12: Agile | H12: Payment | I12: =COUNTIFS('baza-04.10.2026'!C:C,'Birbank Ştat'!A:A,'baza-04.10.2026'!I:I,"Bir Payment") -> 0 | J12: =COUNTIFS('baza-04.10.2026'!C:C,'Birbank Ştat'!A:A,'baza-04.10.2026'!I:I,"BirMarket") -> 0 | K12: =COUNTIFS('baza-04.10.2026'!C:C,'Birbank Ştat'!A:A,'baza-04.10.2026'!I:I,"Paşa Holding") -> 0 | L12: =COUNTIFS('baza-04.10.2026'!C:C,'Birbank Ştat'!A:A,'baza-04.10.2026'!I:I,"Future lab") -> 0 | M12: =Table2[[#This Row],[Pashapay]]+Table2[[#This Row],[Birmarket]]+Table2[[#This Row],[Paşa holding]]+Table2[[#This Row],[Future lab]] -> 0
A13: Özünəxidmət terminalları sahəsi | B13: 2 | C13: 2 | D13: 0 | E13: =B13-C13+D13 -> 0 | F13: Agile | H13: Payment | I13: =COUNTIFS('baza-04.10.2026'!C:C,'Birbank Ştat'!A:A,'baza-04.10.2026'!I:I,"Bir Payment") -> 1 | J13: =COUNTIFS('baza-04.10.2026'!C:C,'Birbank Ştat'!A:A,'baza-04.10.2026'!I:I,"BirMarket") -> 0 | K13: =COUNTIFS('baza-04.10.2026'!C:C,'Birbank Ştat'!A:A,'baza-04.10.2026'!I:I,"Paşa Holding") -> 0 | L13: =COUNTIFS('baza-04.10.2026'!C:C,'Birbank Ştat'!A:A,'baza-04.10.2026'!I:I,"Future lab") -> 0 | M13: =Table2[[#This Row],[Pashapay]]+Table2[[#This Row],[Birmarket]]+Table2[[#This Row],[Paşa holding]]+Table2[[#This Row],[Future lab]] -> 1
A14: Kart klirinqi və hesablaşmalar şöbəsi | B14: 12 | C14: 11 | D14: 0 | E14: =B14-C14+D14 -> 1 | F14: Non-Agile | H14: Payment | I14: =COUNTIFS('baza-04.10.2026'!C:C,'Birbank Ştat'!A:A,'baza-04.10.2026'!I:I,"Bir Payment") -> 0 | J14: =COUNTIFS('baza-04.10.2026'!C:C,'Birbank Ştat'!A:A,'baza-04.10.2026'!I:I,"BirMarket") -> 0 | K14: =COUNTIFS('baza-04.10.2026'!C:C,'Birbank Ştat'!A:A,'baza-04.10.2026'!I:I,"Paşa Holding") -> 0 | L14: =COUNTIFS('baza-04.10.2026'!C:C,'Birbank Ştat'!A:A,'baza-04.10.2026'!I:I,"Future lab") -> 0 | M14: =Table2[[#This Row],[Pashapay]]+Table2[[#This Row],[Birmarket]]+Table2[[#This Row],[Paşa holding]]+Table2[[#This Row],[Future lab]] -> 0
A15: Ödəniş platformaları sahəsi | B15: 4 | C15: 4 | D15: 0 | E15: =B15-C15+D15 -> 0 | F15: Agile | H15: Payment | I15: =COUNTIFS('baza-04.10.2026'!C:C,'Birbank Ştat'!A:A,'baza-04.10.2026'!I:I,"Bir Payment") -> 0 | J15: =COUNTIFS('baza-04.10.2026'!C:C,'Birbank Ştat'!A:A,'baza-04.10.2026'!I:I,"BirMarket") -> 0 | K15: =COUNTIFS('baza-04.10.2026'!C:C,'Birbank Ştat'!A:A,'baza-04.10.2026'!I:I,"Paşa Holding") -> 0 | L15: =COUNTIFS('baza-04.10.2026'!C:C,'Birbank Ştat'!A:A,'baza-04.10.2026'!I:I,"Future lab") -> 0 | M15: =Table2[[#This Row],[Pashapay]]+Table2[[#This Row],[Birmarket]]+Table2[[#This Row],[Paşa holding]]+Table2[[#This Row],[Future lab]] -> 0
A16: Əməliyyatlar ofisi | B16: 1 | C16: 1 | D16: 0 | E16: =B16-C16+D16 -> 0 | F16: Non-Agile | H16: Fintech | I16: =COUNTIFS('baza-04.10.2026'!C:C,'Birbank Ştat'!A:A,'baza-04.10.2026'!I:I,"Bir Payment") -> 0 | J16: =COUNTIFS('baza-04.10.2026'!C:C,'Birbank Ştat'!A:A,'baza-04.10.2026'!I:I,"BirMarket") -> 0 | K16: =COUNTIFS('baza-04.10.2026'!C:C,'Birbank Ştat'!A:A,'baza-04.10.2026'!I:I,"Paşa Holding") -> 0 | L16: =COUNTIFS('baza-04.10.2026'!C:C,'Birbank Ştat'!A:A,'baza-04.10.2026'!I:I,"Future lab") -> 0 | M16: =Table2[[#This Row],[Pashapay]]+Table2[[#This Row],[Birmarket]]+Table2[[#This Row],[Paşa holding]]+Table2[[#This Row],[Future lab]] -> 0
A17: İnformasiya texnologiyaları idarəsi | B17: 2 | C17: 2 | D17: 0 | E17: =B17-C17+D17 -> 0 | F17: Agile | H17: Ekosistem | I17: =COUNTIFS('baza-04.10.2026'!C:C,'Birbank Ştat'!A:A,'baza-04.10.2026'!I:I,"Bir Payment") -> 0 | J17: =COUNTIFS('baza-04.10.2026'!C:C,'Birbank Ştat'!A:A,'baza-04.10.2026'!I:I,"BirMarket") -> 0 | K17: =COUNTIFS('baza-04.10.2026'!C:C,'Birbank Ştat'!A:A,'baza-04.10.2026'!I:I,"Paşa Holding") -> 0 | L17: =COUNTIFS('baza-04.10.2026'!C:C,'Birbank Ştat'!A:A,'baza-04.10.2026'!I:I,"Future lab") -> 0 | M17: =Table2[[#This Row],[Pashapay]]+Table2[[#This Row],[Birmarket]]+Table2[[#This Row],[Paşa holding]]+Table2[[#This Row],[Future lab]] -> 0
A18: Rəhbərlik | B18: 15 | C18: 15 | D18: 0 | E18: =B18-C18+D18 -> 0 | F18: Non-Agile | H18: Ekosistem | I18: =COUNTIFS('baza-04.10.2026'!C:C,'Birbank Ştat'!A:A,'baza-04.10.2026'!I:I,"Bir Payment") -> 1 | J18: =COUNTIFS('baza-04.10.2026'!C:C,'Birbank Ştat'!A:A,'baza-04.10.2026'!I:I,"BirMarket") -> 2 | K18: =COUNTIFS('baza-04.10.2026'!C:C,'Birbank Ştat'!A:A,'baza-04.10.2026'!I:I,"Paşa Holding") -> 0 | L18: =COUNTIFS('baza-04.10.2026'!C:C,'Birbank Ştat'!A:A,'baza-04.10.2026'!I:I,"Future lab") -> 0 | M18: =Table2[[#This Row],[Pashapay]]+Table2[[#This Row],[Birmarket]]+Table2[[#This Row],[Paşa holding]]+Table2[[#This Row],[Future lab]] -> 3
A19: Maliyyə risklərinin idarə edilməsi ofisi | B19: 1 | C19: 1 | D19: 0 | E19: =B19-C19+D19 -> 0 | F19: Non-Agile | H19: Fintech | I19: =COUNTIFS('baza-04.10.2026'!C:C,'Birbank Ştat'!A:A,'baza-04.10.2026'!I:I,"Bir Payment") -> 0 | J19: =COUNTIFS('baza-04.10.2026'!C:C,'Birbank Ştat'!A:A,'baza-04.10.2026'!I:I,"BirMarket") -> 0 | K19: =COUNTIFS('baza-04.10.2026'!C:C,'Birbank Ştat'!A:A,'baza-04.10.2026'!I:I,"Paşa Holding") -> 0 | L19: =COUNTIFS('baza-04.10.2026'!C:C,'Birbank Ştat'!A:A,'baza-04.10.2026'!I:I,"Future lab") -> 0 | M19: =Table2[[#This Row],[Pashapay]]+Table2[[#This Row],[Birmarket]]+Table2[[#This Row],[Paşa holding]]+Table2[[#This Row],[Future lab]] -> 0
A20: Strategiya idarəsi | B20: 1 | C20: 1 | D20: 0 | E20: =B20-C20+D20 -> 0 | F20: Non-Agile | H20: Ekosistem | I20: =COUNTIFS('baza-04.10.2026'!C:C,'Birbank Ştat'!A:A,'baza-04.10.2026'!I:I,"Bir Payment") -> 0 | J20: =COUNTIFS('baza-04.10.2026'!C:C,'Birbank Ştat'!A:A,'baza-04.10.2026'!I:I,"BirMarket") -> 0 | K20: =COUNTIFS('baza-04.10.2026'!C:C,'Birbank Ştat'!A:A,'baza-04.10.2026'!I:I,"Paşa Holding") -> 1 | L20: =COUNTIFS('baza-04.10.2026'!C:C,'Birbank Ştat'!A:A,'baza-04.10.2026'!I:I,"Future lab") -> 0 | M20: =Table2[[#This Row],[Pashapay]]+Table2[[#This Row],[Birmarket]]+Table2[[#This Row],[Paşa holding]]+Table2[[#This Row],[Future lab]] -> 1
... A24: Ödəniş texnologiyaları ofisi | B24: 1 | C24: 1 | D24: 0 | E24: =B24-C24+D24 -> 0 | F24: Agile | H24: Payment | I24: =COUNTIFS('baza-04.10.2026'!C:C,'Birbank Ştat'!A:A,'baza-04.10.2026'!I:I,"Bir Payment") -> 0 | J24: =COUNTIFS('baza-04.10.2026'!C:C,'Birbank Ştat'!A:A,'baza-04.10.2026'!I:I,"BirMarket") -> 0 | K24: =COUNTIFS('baza-04.10.2026'!C:C,'Birbank Ştat'!A:A,'baza-04.10.2026'!I:I,"Paşa Holding") -> 0 | L24: =COUNTIFS('baza-04.10.2026'!C:C,'Birbank Ştat'!A:A,'baza-04.10.2026'!I:I,"Future lab") -> 0 | M24: =Table2[[#This Row],[Pashapay]]+Table2[[#This Row],[Birmarket]]+Table2[[#This Row],[Paşa holding]]+Table2[[#This Row],[Future lab]] -> 0
A25: Analitika ekspert mərkəzi | B25: 2 | C25: 4 | D25: 0 | E25: 0 | F25: Agile | G25: köhnə strukturda qalan. 1-ini ilqar ocaqovda nəzərə almışam(əzizli yunis), 1 ni fintech analitika naildə, qaldı 2 ştat | H25: Payment | I25: =COUNTIFS('baza-04.10.2026'!C:C,'Birbank Ştat'!A:A,'baza-04.10.2026'!I:I,"Bir Payment") -> 0 | J25: =COUNTIFS('baza-04.10.2026'!C:C,'Birbank Ştat'!A:A,'baza-04.10.2026'!I:I,"BirMarket") -> 0 | K25: =COUNTIFS('baza-04.10.2026'!C:C,'Birbank Ştat'!A:A,'baza-04.10.2026'!I:I,"Paşa Holding") -> 0 | L25: =COUNTIFS('baza-04.10.2026'!C:C,'Birbank Ştat'!A:A,'baza-04.10.2026'!I:I,"Future lab") -> 0 | M25: =Table2[[#This Row],[Pashapay]]+Table2[[#This Row],[Birmarket]]+Table2[[#This Row],[Paşa holding]]+Table2[[#This Row],[Future lab]] -> 0
A26: Aİ və Data elmi ekspert mərkəzi | B26: 5 | C26: 5 | D26: 0 | E26: 0 | F26: Agile | G26: köhnə strukturda qalan | H26: Ekosistem | I26: =COUNTIFS('baza-04.10.2026'!C:C,'Birbank Ştat'!A:A,'baza-04.10.2026'!I:I,"Bir Payment") -> 0 | J26: =COUNTIFS('baza-04.10.2026'!C:C,'Birbank Ştat'!A:A,'baza-04.10.2026'!I:I,"BirMarket") -> 0 | K26: =COUNTIFS('baza-04.10.2026'!C:C,'Birbank Ştat'!A:A,'baza-04.10.2026'!I:I,"Paşa Holding") -> 0 | L26: =COUNTIFS('baza-04.10.2026'!C:C,'Birbank Ştat'!A:A,'baza-04.10.2026'!I:I,"Future lab") -> 0 | M26: =Table2[[#This Row],[Pashapay]]+Table2[[#This Row],[Birmarket]]+Table2[[#This Row],[Paşa holding]]+Table2[[#This Row],[Future lab]] -> 0
A27: Loyallıq məhsulları sahəsi | B27: 1 | C27: 1 | D27: 0 | E27: 0 | F27: Agile | G27: köhnə strukturda qalan | H27: Payment | I27: =COUNTIFS('baza-04.10.2026'!C:C,'Birbank Ştat'!A:A,'baza-04.10.2026'!I:I,"Bir Payment") -> 0 | J27: =COUNTIFS('baza-04.10.2026'!C:C,'Birbank Ştat'!A:A,'baza-04.10.2026'!I:I,"BirMarket") -> 0 | K27: =COUNTIFS('baza-04.10.2026'!C:C,'Birbank Ştat'!A:A,'baza-04.10.2026'!I:I,"Paşa Holding") -> 0 | L27: =COUNTIFS('baza-04.10.2026'!C:C,'Birbank Ştat'!A:A,'baza-04.10.2026'!I:I,"Future lab") -> 0 | M27: =Table2[[#This Row],[Pashapay]]+Table2[[#This Row],[Birmarket]]+Table2[[#This Row],[Paşa holding]]+Table2[[#This Row],[Future lab]] -> 0
A28: Data menecment ofisi | B28: 1 | C28: 0 | D28: 0 | E28: 0 | F28: Agile | G28: köhnə strukturda qalan-Shabanlı Seymur-ştatı hara verilməli | H28: Ekosistem | I28: =COUNTIFS('baza-04.10.2026'!C:C,'Birbank Ştat'!A:A,'baza-04.10.2026'!I:I,"Bir Payment") -> 0 | J28: =COUNTIFS('baza-04.10.2026'!C:C,'Birbank Ştat'!A:A,'baza-04.10.2026'!I:I,"BirMarket") -> 0 | K28: =COUNTIFS('baza-04.10.2026'!C:C,'Birbank Ştat'!A:A,'baza-04.10.2026'!I:I,"Paşa Holding") -> 0 | L28: =COUNTIFS('baza-04.10.2026'!C:C,'Birbank Ştat'!A:A,'baza-04.10.2026'!I:I,"Future lab") -> 0 | M28: =Table2[[#This Row],[Pashapay]]+Table2[[#This Row],[Birmarket]]+Table2[[#This Row],[Paşa holding]]+Table2[[#This Row],[Future lab]] -> 0
A29: Birbonus sahəsi | B29: 5 | C29: 4 | D29: 0 | E29: =B29-C29+D29 -> 1 | F29: Agile | H29: Payment | I29: =COUNTIFS('baza-04.10.2026'!C:C,'Birbank Ştat'!A:A,'baza-04.10.2026'!I:I,"Bir Payment") -> 0 | J29: =COUNTIFS('baza-04.10.2026'!C:C,'Birbank Ştat'!A:A,'baza-04.10.2026'!I:I,"BirMarket") -> 0 | K29: =COUNTIFS('baza-04.10.2026'!C:C,'Birbank Ştat'!A:A,'baza-04.10.2026'!I:I,"Paşa Holding") -> 0 | L29: =COUNTIFS('baza-04.10.2026'!C:C,'Birbank Ştat'!A:A,'baza-04.10.2026'!I:I,"Future lab") -> 0 | M29: =Table2[[#This Row],[Pashapay]]+Table2[[#This Row],[Birmarket]]+Table2[[#This Row],[Paşa holding]]+Table2[[#This Row],[Future lab]] -> 0
A30: Arxitektura ekspert mərkəzi | B30: 8 | C30: 7 | D30: 0 | E30: =B30-C30+D30 -> 1 | F30: Agile | H30: Ekosistem | I30: =COUNTIFS('baza-04.10.2026'!C:C,'Birbank Ştat'!A:A,'baza-04.10.2026'!I:I,"Bir Payment") -> 0 | J30: =COUNTIFS('baza-04.10.2026'!C:C,'Birbank Ştat'!A:A,'baza-04.10.2026'!I:I,"BirMarket") -> 0 | K30: =COUNTIFS('baza-04.10.2026'!C:C,'Birbank Ştat'!A:A,'baza-04.10.2026'!I:I,"Paşa Holding") -> 0 | L30: =COUNTIFS('baza-04.10.2026'!C:C,'Birbank Ştat'!A:A,'baza-04.10.2026'!I:I,"Future lab") -> 0 | M30: =Table2[[#This Row],[Pashapay]]+Table2[[#This Row],[Birmarket]]+Table2[[#This Row],[Paşa holding]]+Table2[[#This Row],[Future lab]] -> 0
A31: Məhsulların rəsmiləşdirilməsi sahəsi | B31: 5 | C31: 4 | D31: 0 | E31: =B31-C31+D31 -> 1 | F31: Agile | H31: Fintech | I31: =COUNTIFS('baza-04.10.2026'!C:C,'Birbank Ştat'!A:A,'baza-04.10.2026'!I:I,"Bir Payment") -> 0 | J31: =COUNTIFS('baza-04.10.2026'!C:C,'Birbank Ştat'!A:A,'baza-04.10.2026'!I:I,"BirMarket") -> 0 | K31: =COUNTIFS('baza-04.10.2026'!C:C,'Birbank Ştat'!A:A,'baza-04.10.2026'!I:I,"Paşa Holding") -> 0 | L31: =COUNTIFS('baza-04.10.2026'!C:C,'Birbank Ştat'!A:A,'baza-04.10.2026'!I:I,"Future lab") -> 0 | M31: =Table2[[#This Row],[Pashapay]]+Table2[[#This Row],[Birmarket]]+Table2[[#This Row],[Paşa holding]]+Table2[[#This Row],[Future lab]] -> 0
A32: İT proseslərinin idarə edilməsi funksional sahəsi | B32: 5 | C32: 4 | D32: 0 | E32: =B32-C32+D32 -> 1 | F32: Agile | H32: Ekosistem | I32: =COUNTIFS('baza-04.10.2026'!C:C,'Birbank Ştat'!A:A,'baza-04.10.2026'!I:I,"Bir Payment") -> 0 | J32: =COUNTIFS('baza-04.10.2026'!C:C,'Birbank Ştat'!A:A,'baza-04.10.2026'!I:I,"BirMarket") -> 0 | K32: =COUNTIFS('baza-04.10.2026'!C:C,'Birbank Ştat'!A:A,'baza-04.10.2026'!I:I,"Paşa Holding") -> 0 | L32: =COUNTIFS('baza-04.10.2026'!C:C,'Birbank Ştat'!A:A,'baza-04.10.2026'!I:I,"Future lab") -> 0 | M32: =Table2[[#This Row],[Pashapay]]+Table2[[#This Row],[Birmarket]]+Table2[[#This Row],[Paşa holding]]+Table2[[#This Row],[Future lab]] -> 0
A33: Ekosistem platforma və İD sahəsi | B33: 5 | C33: 4 | D33: 0 | E33: =B33-C33+D33 -> 1 | F33: Agile | H33: Ekosistem | I33: =COUNTIFS('baza-04.10.2026'!C:C,'Birbank Ştat'!A:A,'baza-04.10.2026'!I:I,"Bir Payment") -> 0 | J33: =COUNTIFS('baza-04.10.2026'!C:C,'Birbank Ştat'!A:A,'baza-04.10.2026'!I:I,"BirMarket") -> 0 | K33: =COUNTIFS('baza-04.10.2026'!C:C,'Birbank Ştat'!A:A,'baza-04.10.2026'!I:I,"Paşa Holding") -> 0 | L33: =COUNTIFS('baza-04.10.2026'!C:C,'Birbank Ştat'!A:A,'baza-04.10.2026'!I:I,"Future lab") -> 0 | M33: =Table2[[#This Row],[Pashapay]]+Table2[[#This Row],[Birmarket]]+Table2[[#This Row],[Paşa holding]]+Table2[[#This Row],[Future lab]] -> 0
A34: Xəzinədarlıq departamenti | B34: 21 | C34: 20 | D34: 0 | E34: =B34-C34+D34 -> 1 | F34: Non-Agile | H34: Fintech | I34: =COUNTIFS('baza-04.10.2026'!C:C,'Birbank Ştat'!A:A,'baza-04.10.2026'!I:I,"Bir Payment") -> 0 | J34: =COUNTIFS('baza-04.10.2026'!C:C,'Birbank Ştat'!A:A,'baza-04.10.2026'!I:I,"BirMarket") -> 0 | K34: =COUNTIFS('baza-04.10.2026'!C:C,'Birbank Ştat'!A:A,'baza-04.10.2026'!I:I,"Paşa Holding") -> 0 | L34: =COUNTIFS('baza-04.10.2026'!C:C,'Birbank Ştat'!A:A,'baza-04.10.2026'!I:I,"Future lab") -> 0 | M34: =Table2[[#This Row],[Pashapay]]+Table2[[#This Row],[Birmarket]]+Table2[[#This Row],[Paşa holding]]+Table2[[#This Row],[Future lab]] -> 0
A35: Kreditlərin hüquqi təqibi departamenti | B35: 58 | C35: 57 | D35: 0 | E35: =B35-C35+D35 -> 1 | F35: Non-Agile | H35: Fintech | I35: =COUNTIFS('baza-04.10.2026'!C:C,'Birbank Ştat'!A:A,'baza-04.10.2026'!I:I,"Bir Payment") -> 0 | J35: =COUNTIFS('baza-04.10.2026'!C:C,'Birbank Ştat'!A:A,'baza-04.10.2026'!I:I,"BirMarket") -> 0 | K35: =COUNTIFS('baza-04.10.2026'!C:C,'Birbank Ştat'!A:A,'baza-04.10.2026'!I:I,"Paşa Holding") -> 0 | L35: =COUNTIFS('baza-04.10.2026'!C:C,'Birbank Ştat'!A:A,'baza-04.10.2026'!I:I,"Future lab") -> 0 | M35: =Table2[[#This Row],[Pashapay]]+Table2[[#This Row],[Birmarket]]+Table2[[#This Row],[Paşa holding]]+Table2[[#This Row],[Future lab]] -> 0
A36: Model risklərinin idarəedilməsi ekspert mərkəzi | B36: 12 | C36: 11 | D36: 0 | E36: =B36-C36+D36 -> 1 | F36: Agile | H36: Ekosistem | I36: =COUNTIFS('baza-04.10.2026'!C:C,'Birbank Ştat'!A:A,'baza-04.10.2026'!I:I,"Bir Payment") -> 0 | J36: =COUNTIFS('baza-04.10.2026'!C:C,'Birbank Ştat'!A:A,'baza-04.10.2026'!I:I,"BirMarket") -> 0 | K36: =COUNTIFS('baza-04.10.2026'!C:C,'Birbank Ştat'!A:A,'baza-04.10.2026'!I:I,"Paşa Holding") -> 0 | L36: =COUNTIFS('baza-04.10.2026'!C:C,'Birbank Ştat'!A:A,'baza-04.10.2026'!I:I,"Future lab") -> 0 | M36: =Table2[[#This Row],[Pashapay]]+Table2[[#This Row],[Birmarket]]+Table2[[#This Row],[Paşa holding]]+Table2[[#This Row],[Future lab]] -> 0
A37: VİP müştərilərlə iş şöbəsi | B37: 9 | C37: 8 | D37: 0 | E37: =B37-C37+D37 -> 1 | F37: Non-Agile | H37: Fintech | I37: =COUNTIFS('baza-04.10.2026'!C:C,'Birbank Ştat'!A:A,'baza-04.10.2026'!I:I,"Bir Payment") -> 0 | J37: =COUNTIFS('baza-04.10.2026'!C:C,'Birbank Ştat'!A:A,'baza-04.10.2026'!I:I,"BirMarket") -> 0 | K37: =COUNTIFS('baza-04.10.2026'!C:C,'Birbank Ştat'!A:A,'baza-04.10.2026'!I:I,"Paşa Holding") -> 0 | L37: =COUNTIFS('baza-04.10.2026'!C:C,'Birbank Ştat'!A:A,'baza-04.10.2026'!I:I,"Future lab") -> 0 | M37: =Table2[[#This Row],[Pashapay]]+Table2[[#This Row],[Birmarket]]+Table2[[#This Row],[Paşa holding]]+Table2[[#This Row],[Future lab]] -> 0
A38: Aİ governance ekspert mərkəzi | B38: 15 | C38: 16 | D38: 3 | E38: =B38-C38+D38 -> 2 | F38: Agile | G38: 1 dene müşteri tecrubesinden | H38: Ekosistem | I38: =COUNTIFS('baza-04.10.2026'!C:C,'Birbank Ştat'!A:A,'baza-04.10.2026'!I:I,"Bir Payment") -> 0 | J38: =COUNTIFS('baza-04.10.2026'!C:C,'Birbank Ştat'!A:A,'baza-04.10.2026'!I:I,"BirMarket") -> 0 | K38: =COUNTIFS('baza-04.10.2026'!C:C,'Birbank Ştat'!A:A,'baza-04.10.2026'!I:I,"Paşa Holding") -> 0 | L38: =COUNTIFS('baza-04.10.2026'!C:C,'Birbank Ştat'!A:A,'baza-04.10.2026'!I:I,"Future lab") -> 1 | M38: =Table2[[#This Row],[Pashapay]]+Table2[[#This Row],[Birmarket]]+Table2[[#This Row],[Paşa holding]]+Table2[[#This Row],[Future lab]] -> 1
A39: Mikro biznes departamenti | B39: 19 | C39: 18 | D39: 0 | E39: =B39-C39+D39 -> 1 | F39: Non-Agile | H39: Fintech | I39: =COUNTIFS('baza-04.10.2026'!C:C,'Birbank Ştat'!A:A,'baza-04.10.2026'!I:I,"Bir Payment") -> 0 | J39: =COUNTIFS('baza-04.10.2026'!C:C,'Birbank Ştat'!A:A,'baza-04.10.2026'!I:I,"BirMarket") -> 0 | K39: =COUNTIFS('baza-04.10.2026'!C:C,'Birbank Ştat'!A:A,'baza-04.10.2026'!I:I,"Paşa Holding") -> 0 | L39: =COUNTIFS('baza-04.10.2026'!C:C,'Birbank Ştat'!A:A,'baza-04.10.2026'!I:I,"Future lab") -> 0 | M39: =Table2[[#This Row],[Pashapay]]+Table2[[#This Row],[Birmarket]]+Table2[[#This Row],[Paşa holding]]+Table2[[#This Row],[Future lab]] -> 0
A40: BirApp texnologiyası sahəsi | B40: 3 | C40: 2 | D40: 0 | E40: =B40-C40+D40 -> 1 | F40: Agile | H40: Ekosistem | I40: =COUNTIFS('baza-04.10.2026'!C:C,'Birbank Ştat'!A:A,'baza-04.10.2026'!I:I,"Bir Payment") -> 0 | J40: =COUNTIFS('baza-04.10.2026'!C:C,'Birbank Ştat'!A:A,'baza-04.10.2026'!I:I,"BirMarket") -> 0 | K40: =COUNTIFS('baza-04.10.2026'!C:C,'Birbank Ştat'!A:A,'baza-04.10.2026'!I:I,"Paşa Holding") -> 0 | L40: =COUNTIFS('baza-04.10.2026'!C:C,'Birbank Ştat'!A:A,'baza-04.10.2026'!I:I,"Future lab") -> 0 | M40: =Table2[[#This Row],[Pashapay]]+Table2[[#This Row],[Birmarket]]+Table2[[#This Row],[Paşa holding]]+Table2[[#This Row],[Future lab]] -> 0
A41: BirApp sahəsi | B41: 7 | C41: 6 | D41: 0 | E41: =B41-C41+D41 -> 1 | F41: Agile | H41: Ekosistem | I41: =COUNTIFS('baza-04.10.2026'!C:C,'Birbank Ştat'!A:A,'baza-04.10.2026'!I:I,"Bir Payment") -> 1 | J41: =COUNTIFS('baza-04.10.2026'!C:C,'Birbank Ştat'!A:A,'baza-04.10.2026'!I:I,"BirMarket") -> 0 | K41: =COUNTIFS('baza-04.10.2026'!C:C,'Birbank Ştat'!A:A,'baza-04.10.2026'!I:I,"Paşa Holding") -> 0 | L41: =COUNTIFS('baza-04.10.2026'!C:C,'Birbank Ştat'!A:A,'baza-04.10.2026'!I:I,"Future lab") -> 0 | M41: =Table2[[#This Row],[Pashapay]]+Table2[[#This Row],[Birmarket]]+Table2[[#This Row],[Paşa holding]]+Table2[[#This Row],[Future lab]] -> 1
A42: Məhsul və marketinq idarəsi | B42: 2 | C42: 1 | D42: 0 | E42: =B42-C42+D42 -> 1 | F42: Agile | H42: Ekosistem | I42: =COUNTIFS('baza-04.10.2026'!C:C,'Birbank Ştat'!A:A,'baza-04.10.2026'!I:I,"Bir Payment") -> 0 | J42: =COUNTIFS('baza-04.10.2026'!C:C,'Birbank Ştat'!A:A,'baza-04.10.2026'!I:I,"BirMarket") -> 0 | K42: =COUNTIFS('baza-04.10.2026'!C:C,'Birbank Ştat'!A:A,'baza-04.10.2026'!I:I,"Paşa Holding") -> 0 | L42: =COUNTIFS('baza-04.10.2026'!C:C,'Birbank Ştat'!A:A,'baza-04.10.2026'!I:I,"Future lab") -> 0 | M42: =Table2[[#This Row],[Pashapay]]+Table2[[#This Row],[Birmarket]]+Table2[[#This Row],[Paşa holding]]+Table2[[#This Row],[Future lab]] -> 0
A43: Pərakəndə məhsullar ofisi | B43: 1 | C43: 0 | D43: 0 | E43: =B43-C43+D43 -> 1 | F43: Agile | H43: Fintech | I43: =COUNTIFS('baza-04.10.2026'!C:C,'Birbank Ştat'!A:A,'baza-04.10.2026'!I:I,"Bir Payment") -> 0 | J43: =COUNTIFS('baza-04.10.2026'!C:C,'Birbank Ştat'!A:A,'baza-04.10.2026'!I:I,"BirMarket") -> 0 | K43: =COUNTIFS('baza-04.10.2026'!C:C,'Birbank Ştat'!A:A,'baza-04.10.2026'!I:I,"Paşa Holding") -> 0 | L43: =COUNTIFS('baza-04.10.2026'!C:C,'Birbank Ştat'!A:A,'baza-04.10.2026'!I:I,"Future lab") -> 0 | M43: =Table2[[#This Row],[Pashapay]]+Table2[[#This Row],[Birmarket]]+Table2[[#This Row],[Paşa holding]]+Table2[[#This Row],[Future lab]] -> 0
...

Sheet baza-04.10.2026
A1: Personal kod | B1: Soyadı, adı və ata adı (Surname, name, father name) | C1: Departament (Department) | D1: Şöbə (Section) | E1: Bölmə (Subsection) | F1: Vəzifə (Position) | G1: Aktiv, Passiv, HX, SM (Active, Passive,Social vacation) | H1: Status | I1: Keçid etdiyi şirkət | J1: Kapital Banka işə qəbul olunduğu tarix (Hire date) | K1: Non agile filial | L1: İşdən çıxma tarixi | M1: Qeyd
A2: 16457 | B2: Məmmədov Fərid Usad oğlu | C2: Müşahidə Şurası | D2: # | E2: # | F2: Müşahidə şurasının sədri (əvəzçilik qaydasında) | G2: A | H2: Daimi | J2: 45405 | K2: Non-Agile
A3: 10843 | B3: Həsənov Oqtay Arif oğlu | C3: Müşahidə Şurası | D3: # | E3: # | F3: Müşahidə şurasının üzvü, Audit komitəsinin sədri (əvəzçilik qaydasında) | G3: A | H3: Daimi | J3: 41654 | K3: Non-Agile
A4: 10925 | B4: Hüseynov Fərid Arif oğlu | C4: Rəhbərlik | D4: # | E4: # | F4: İdarə Heyətinin sədri, Baş icraçı direktor | G4: A | H4: Daimi | J4: 42125 | K4: Non-Agile
A5: 10722 | B5: Mirzəyev Cavid Akif oğlu | C5: Rəhbərlik | D5: # | E5: # | F5: İdarə Heyəti sədrinin I müavini | G5: A | H5: Daimi | J5: 41736 | K5: Non-Agile
A6: 10610 | B6: Hidayətzadə Fərid Səbuhi oğlu | C6: Rəhbərlik | D6: # | E6: # | F6: İdarə Heyəti sədrinin müavini, Baş Korporativ satış inzibatçısı | G6: A | H6: Daimi | J6: 41484 | K6: Non-Agile
A7: 18167 | B7: Orucov Calal Cümşüd oğlu | C7: Rəhbərlik | D7: # | E7: # | F7: İdarə Heyəti sədrinin müavini | G7: A | H7: Daimi | J7: 46027 | K7: Non-Agile | M7: 84 N-19.12.2025, 08 N-Emin M yerinə olması 30.01.2026
A8: 10002 | B8: Məmmədov Yaşar Zeynalabdı oğlu | C8: Rəhbərlik | D8: # | E8: # | F8: İdarə Heyəti sədrinin müavini | G8: A | H8: Daimi | J8: 37893 | K8: Non-Agile
A9: 10611 | B9: Abdullayev Kamal Nadir oğlu | C9: Rəhbərlik | D9: # | E9: # | F9: Baş komplayens inzibatçısı | G9: A | H9: Daimi | J9: 41484 | K9: Non-Agile
A10: 10963 | B10: Baxşiyev Ağarza Yaşar oğlu | C10: Rəhbərlik | D10: # | E10: # | F10: Baş Risk inzibatçısı | G10: A | H10: Daimi | J10: 42219 | K10: Non-Agile
A11: 18369 | B11: Atakişiyev Rauf Surxay oğlu | C11: Rəhbərlik | D11: # | E11: # | F11: Baş Maliyyə inzibatçısı | G11: A | H11: Daimi | J11: 46113 | K11: Non-Agile | M11: 23N-19.03.2026
A12: 10658 | B12: Məmmədov Emin Ağaverdi oğlu | C12: Rəhbərlik | D12: # | E12: # | F12: İdarə Heyəti sədrinin müşaviri | G12: A | H12: Daimi | J12: 41611 | K12: Non-Agile
A13: 18916 | B13: SZCZEPANSKI LUKASZ | C13: Rəhbərlik | D13: # | E13: # | F13: İdarə Heyəti sədrinin müşaviri | G13: A | H13: Daimi | J13: 46237 | K13: Non-Agile | M13: 58N-23.07.2026
A14: 18890 | B14: Qulaməliyev Rauf İlham oğlu | C14: Rəhbərlik | D14: # | E14: # | F14: İdarə Heyəti sədrinin müşaviri | G14: A | H14: Daimi | I14: BirMarket | J14: 46241 | K14: Non-Agile | M14: 58N-23.07.2026
A15: 18188 | B15: Məmmədov Samir Sabir oğlu | C15: Rəhbərlik | D15: # | E15: # | F15: İdarə Heyəti sədrinin müşaviri (əvəzçilik qaydasında) | G15: A | H15: Daimi | I15: BirMarket | J15: 46034 | K15: Non-Agile | M15: 02 N-12.01.2026
A16: 15131 | B16: Aslanov Mehti İsfəndiyar oğlu | C16: Rəhbərlik | D16: # | E16: # | F16: Müşavir (İdarə Heyətinin sədri/baş icraçı direktorun ekosistem üzrə) (əvəzçilik üzrə) | G16: A | H16: Daimi | J16: 44958 | K16: Non-Agile
A17: 11584 | B17: İslamov Fərid Abbas oğlu | C17: Rəhbərlik | D17: # | E17: # | F17: Ofis lideri | G17: A | H17: Daimi | J17: 42877 | K17: Agile
A18: 19018 | B18: VASILEVA EVGENIIA | C18: Rəhbərlik | D18: # | E18: # | F18: Aparat rəhbəri | G18: A | H18: Daimi | I18: Bir Payment | J18: 46254 | K18: Agile
A19: 15541 | B19: GROMOV MIKHAIL | C19: İnformasiya texnologiyaları idarəsi | D19: # | E19: # | F19: Baş direktor | G19: A | H19: Daimi | J19: 45114 | K19: Agile
A20: 16327 | B20: EVDOKIMOV MAKSIM | C20: Məhsul və marketinq idarəsi | D20: # | E20: # | F20: Baş direktor | G20: A | H20: Daimi | J20: 45344 | K20: Agile
A21: 18522 | B21: Nəbiyev Valeh Valeh oğlu | C21: Data və Aİ idarəsi | D21: # | E21: # | F21: Baş direktor | G21: A | H21: Daimi | I21: Paşa Holding | J21: 46143 | K21: Agile
A22: 18523 | B22: Məmmədov Ruslan Nəsir oğlu | C22: Strategiya idarəsi | D22: # | E22: # | F22: Baş direktor | G22: A | H22: Daimi | I22: Paşa Holding | J22: 46143 | K22: Non-Agile
A23: 160032 | B23: İbrahimov Məhəmməd Əhməd oğlu | C23: Əməliyyatlar ofisi | D23: # | E23: # | F23: Ofis lideri | G23: A | H23: Daimi | J23: 42311 | K23: Non-Agile
A24: 10431 | B24: Xan-Məmmədov Zakir Akif oğlu | C24: Ödəniş məhsulları ofisi | D24: # | E24: # | F24: Ofis lideri | G24: A | H24: Daimi | J24: 40253 | K24: Agile
A25: 10967 | B25: Səmədov Fərid Sirac oğlu | C25: Ödəniş texnologiyaları ofisi | D25: # | E25: # | F25: Ofis lideri | G25: A | H25: Daimi | J25: 42222 | K25: Agile
A26: 10516 | B26: Məmmədov Pərvin Zahid oğlu | C26: Maliyyə ofisi | D26: # | E26: # | F26: Ofis lideri | G26: A | H26: Daimi | J26: 41022 | K26: Non-Agile
A27: 13059 | B27: Mahmudxanov Xıdır Asif oğlu | C27: Maliyyə risklərinin idarə edilməsi ofisi | D27: # | E27: # | F27: Ofis lideri | G27: A | H27: Daimi | J27: 44228 | K27: Non-Agile
A28: 16326 | B28: IAKUBOV AIRAT | C28: İnformasiya texnologiyaları idarəsi | D28: # | E28: # | F28: Tribe tech lead | G28: A | H28: Daimi | J28: 45344 | K28: Agile
A29: 16075 | B29: Şükürov Elvin Elçin oğlu | C29: Ödəniş biznesinin mühəndislik ekspert mərkəzi | D29: # | E29: # | F29: Tribe tech lead | G29: A | H29: Daimi | J29: 45278 | K29: Agile
A30: 18483 | B30: İbrahimxanlı Murad Zeynal oğlu | C30: Ödəniş biznesinin mühəndislik ekspert mərkəzi | D30: Software chapter | E30: # | F30: Tech lead | G30: A | H30: Daimi | J30: 46146 | K30: Agile
A31: 18815 | B31: Məmmədzadə Samir Səfər oğlu | C31: Ödəniş biznesinin mühəndislik ekspert mərkəzi | D31: Software chapter | E31: # | F31: Tech lead (0,5 ştat vahidi üzrə əvəzçilik qaydasında) | G31: A | H31: Daimi | I31: Bir Payment | J31: 46213 | K31: Agile
A32: 18182 | B32: Əhmədov Kənan Fəxrəddin oğlu | C32: Kart məhsulları sahəsi | D32: # | E32: # | F32: Tribe tech lead | G32: A | H32: Daimi | J32: 46035 | K32: Agile
A33: 11886 | B33: Lətifov Fariz Məmməd oğlu | C33: FinTech mühəndislik ekspert mərkəzi | D33: # | E33: # | F33: Tribe tech lead | G33: A | H33: Daimi | J33: 43242 | K33: Agile
A34: 17254 | B34: Məmmədov İlqar Camal oğlu | C34: Ödəniş biznesinin mühəndislik ekspert mərkəzi | D34: # | E34: # | F34: Ekspert mərkəzinin lideri | G34: A | H34: Daimi | J34: 45691 | K34: Agile
A35: 16234 | B35: Əlizadə Teymur Vladimiroviç | C35: Ödəniş biznesinin TechOps funksional sahəsi | D35: # | E35: # | F35: Servis dayanıqlığı üzrə mühəndis | G35: A | H35: Daimi | J35: 45323 | K35: Agile
A36: 17485 | B36: SHATUNOV MAKSIM | C36: BirApp texnologiyası sahəsi | D36: # | E36: # | F36: Tribe tech lead | G36: A | H36: Daimi | J36: 45762 | K36: Agile
A37: 11527 | B37: Rəcəbova Samirə Fuad qızı | C37: BirApp texnologiyası sahəsi | D37: Birbank Platform | E37: # | F37: Məhsul sahibi | G37: A | H37: Daimi | J37: 42797 | K37: Agile
A38: 11536 | B38: Seyfullayev Şahmar Asəf oğlu | C38: Ödəniş biznesinin mühəndislik ekspert mərkəzi | D38: # | E38: # | F38: Tribe tech lead | G38: A | H38: Daimi | J38: 42808 | K38: Agile
A39: 18202 | B39: Mustafayev Kamran Çingiz oğlu | C39: Korporativ inkişaf və investor əlaqələri departamenti | D39: # | E39: # | F39: Menecer | G39: A | H39: Daimi | J39: 46055 | K39: Non-Agile
A40: 18268 | B40: RIZVANOV RUSTAM | C40: Korporativ inkişaf və investor əlaqələri departamenti | D40: # | E40: # | F40: Direktor müavini | G40: A | H40: Daimi | J40: 46084 | K40: Non-Agile
...

Sheet İxtisar
A1: Sahə | B1: Əvvəlki təsdiqlənən ştat sayı | C1: İxtisardan sonra təsdiqlənəcək ştat sayı | D1: İxtisar olunan ştat sayı | E1: İxtisardan əvvəlki vakant | F1: İxtisardan sonrakı vakant | G1: Status
A2: Filial | B2: 2007 | C2: 1950 | D2: 57 | E2: 106 | F2: =Table1[[#This Row],[İxtisardan əvvəlki vakant]]-Table1[[#This Row],[İxtisar olunan ştat sayı]] -> 49 | G2: Şifahi bildirilib ki yenə ixtisar olacaq
A3: FinTech mühəndislik ekspert mərkəzi | B3: 366 | C3: 357 | D3: 9 | E3: 45 | F3: =Table1[[#This Row],[İxtisardan əvvəlki vakant]]-Table1[[#This Row],[İxtisar olunan ştat sayı]] -> 36 | G3: Yeni layihələrə görə reserved saxlayır
A4: Korporativ katiblik şöbəsi | B4: 37.5 | C4: 35.5 | D4: 2 | E4: 7.5 | F4: =Table1[[#This Row],[İxtisardan əvvəlki vakant]]-Table1[[#This Row],[İxtisar olunan ştat sayı]] -> 5.5
A5: Texniki dəstək departamenti | B5: 61 | C5: 59 | D5: 2 | E5: 3 | F5: =Table1[[#This Row],[İxtisardan əvvəlki vakant]]-Table1[[#This Row],[İxtisar olunan ştat sayı]] -> 1
A6: Kredit risklərinin təhlili departamenti | B6: 133 | C6: =Table1[[#This Row],[Əvvəlki təsdiqlənən ştat sayı]]-17 -> 116 | D6: 17 | E6: 22 | F6: =Table1[[#This Row],[İxtisardan əvvəlki vakant]]-Table1[[#This Row],[İxtisar olunan ştat sayı]] -> 5
A7: CƏMİ | D7: =SUM(Table1[İxtisar olunan ştat sayı]) -> 87 | E7: =SUM(Table1[İxtisardan əvvəlki vakant]) -> 183.5 | F7: =SUM(Table1[İxtisardan sonrakı vakant]) -> 96.5

Sheet HR
A1: Sahə | B1: Struktur dəyişikliyindən əvvəl | C1: Hardan gəlib | D1: Say | E1: Struktur dəyişikliyindən sonra | F1: Faktiki işçi sayı | G1: Müvəqqəti işçi sayı | H1: Vakant ştat | J1: Ştat ixtisar-HR | K1: Strukturu | L1: İşdən çıxma tarixi
A2: Təşkilati inkişaf və HR texnologiyaları departamenti | B2: 0 | C2: İstedadların idarə edilməsi departamenti | D2: 48 | E2: =SUM(D2:D9) -> 84 | F2: 82 | G2: 3 | H2: 5 | J2: Abdullayeva Sugra | K2: İnsanlar və korporativ mədəniyyət departamenti-İnsan Resursları əməliyyatları və əmək haqqı hesablanması şöbəsi-İnsan Resursları üzrə baş mütəxəssis | L2: 46203 | M2: Birmarket
C3: Daxili kommunikasiya və Korporativ Sosial Məsuliyyət şöbəsi | D3: 8 | J3: Muradova Kəmalə | K3: İnsanlar və korporativ mədəniyyət departamenti-İnsan Resursları əməliyyatları və əmək haqqı hesablanması şöbəsi-İnsan Resursları üzrə mütəxəssis | L3: ştatı ixtisar edilib, özünü birmarketdə CC boş vakanta keçiriblər-08.06.2026
C4: Pashapay | D4: =5+4 -> 9 | J4: Kərimova Nəzrin | K4: İstedadların idarə edilməsi departamenti, Performansın idarə edilməsi və işçi bağlılığı şöbəsi, İnsan resursları üzrə mütəxəssis | L4: 46205 | M4: Pashapay
C5: BirMarket | D5: =7+5 -> 12 | J5: Məmmədova Səmidə | K5: İstedadların idarə edilməsi departamenti, İstedadların cəlbi və biznes partnyorluq şöbəsi,İnsan Resursları üzrə Biznes tərəfdaş | L5: 46224
C6: Pasha holding | D6: 2
C7: İstedadların idarə edilməsi departamenti(Xuraman H, Mujgan R) | D7: 2
C8: Pashapay(Zabeta) | D8: 1
C9: Future lab | D9: 2
A11: Vakantlar | B11: Şöbə | C11: Bölmə | D11: Vəzifə | E11: Yeni qəbul | F11: İşə başlama tarixi | G11: Status | H11: Qeyd
A12: 1 | B12: Təşkilati inkişaf və işçi bağlılığı funksional sahəsi | C12: - | D12: Aparıcı mütəxəssis | E12: Zeynalova Leyla Bəxtiyar | F12: 46307 | G12: İşə qəbul | H12: Elmira Hacıyeva
A13: 2 | B13: HR TechOps, performans və data funksional sahəsi | C13: Ecosystem HR data | D13: Mütəxəssis | E13: Əzizov Emil Müslət | F13: - | H13: Abdullayeva Gülşən
A14: 3 | B14: HR TechOps, performans və data funksional sahəsi | C14: Ecosystem HR operations & Service delivery | D14: Menecer | E14: Oktaylı İqrar Oktay | F14: 46310 | H14: Sunqarova Bikə Hacirabadan qızı
A15: 4 | B15: İşəgötürən brendi və KSM funksional sahəsi, İnternal communications function | C15: - | D15: Aparıcı mütəxəssis | H15: Abbasova Jalə Ceyhun qızı
A16: 5 | B16: Təşkilati inkişaf və işçi bağlılığı funksional sahəsi | C16: Learning & Development | D16: Menecer | G16: Vakant | H16: Mansurova Nərmin Şahin qızı
A21: Vakant olmalıdır amma ştat yoxdur | B21: Hansı şöbə | C21: Kimin yerinə | D21: Qeyd
A22: 1 | B22: Learning & Development | C22: Mujgan Rustəmli
A23: 2 | B23: Təşkilati inkişaf və işçi bağlılığı funksional sahəsi | C23: Nərmin Əhmədova
A24: 3 | B24: HR TechOps, performans və data funksional sahəsi | C24: George Bakhtin | D24: Ştatı Ayrat verməli
A25: 4 | B25: HRBP və istedad cəlbi funksional sahəsi | C25: Əliyeva Zəhra Abasəli qızı
A26: 5 | B26: HRBP və istedad cəlbi funksional sahəsi | C26: Əsgərova Mətanət Vaqif qızı
A27: 6 | B27: İşəgötürən brendi və KSM funksional sahəsi | C27: Baloğlanlı Ziyafət Seymur oğlu
A30: Sual altında olan məsələlər | B30: Hansı şöbə | C30: Ştat | D30: Qeyd
A31: 1 | B31: HRBP | C31: Cəbrayılov Fehruz Nizami oğlu | D31: Aygün xanımın şifahi razılığı əsasında işə götürülüb
C32: Şəfiyeva Nəzrin Fikrət qızı
A33: 3 | B33: İşəgötürən brendi və KSM funksional sahəsi | C33: Əhmədova Kəmalə Calalətdin qızı | D33: HR ştatından götürülüb
C34: Abbasova Jalə Ceyhun qızı | D34: HR ştatından götürülüb
C35: Rüstəmova Vəfa Elbrus qızı | D35: HR ştatından götürülüb

Sheet Pashapay ştat
A1: Row Labels | B1: Staff | C1: Vakant | F1: 46294
A2: None structure | B2: 30 | C2: 0
A3: Biznesin optimallaşdırılması şöbəsi | B3: 1 | C3: 0
A4: Daxili nəzarət şöbəsi | B4: 3 | C4: 0
A5: Frauda qarşı mübarizə şöbəsi | B5: 10 | C5: 0
A6: Hüquq Şöbəsi | B6: 3 | C6: 1
A7: İnformasiya təhlükəsizliyi şöbəsi | B7: 3 | C7: 0
A8: İnkassasiya Şöbəsi | B8: 165 | C8: 24
A9: İT şöbəsi | B9: 11 | C9: 0
A10: Kross-sərhəd və satış sahəsi | B10: 11 | C10: 3
A11: Məhsullar Şöbəsi | B11: 18 | C11: 5
A12: Audit komitəsi | B12: 3 | C12: 1
A13: Baş Komplayens inzibatçısı | B13: 1 | C13: 0
... A22: Terminal və ATM şəbəkəsinin idarə edilməsi departamenti | B22: 27 | C22: 0
A23: Grand Total | B23: =SUM(B2:B22) -> 591 | C23: =SUM(C2:C22) -> 55

Sheet birmarket ştat
A1: 46301
A2: Sahə adı | B2: İşçi sayı-əmək müqaviləsi | C2: Vakant sayı-əmək müqaviləsi | D2: İşçi sayı-xidməti müqavilə(expat) | E2: İşçi sayı-xidməti müqavilə(yerli) | F2: Vakant sayı-xidməti müqavilə(yerli)
A3: Kommersiya bloku | B3: 1 | C3: 2 | D3: 2
A4: Kommersiya blok/Elektronika sahəsi | B4: 11 | C4: 1
A5: Kommersiya bloku/Gözəllik sahəsi | B5: 6
A6: Kommersiya bloku/Ev əşyaları sahəsi | B6: 8
A7: Kommersiya blok/Gündəlik təlabat üçün istehlak sahəsi | B7: 8 | C7: 1
A8: Kommersiya bloku/Satışların təkmilləşdirilməsi departamenti | B8: 46
A9: Kommersiya bloku/Məzmun əməliyyatları şöbəsi | B9: 37
A10: Kommersiya bloku/Satıcı Məhsul departamenti | B10: 3 | D10: 1
A11: Təchizat Zənciri bloku | B11: 1
A12: Təchizat zənciri bloku/Logistika əməliyyatları departamenti | B12: 192 | C12: 6 | D12: 2 | E12: 455 | F12: 80
A13: Texnologiya şöbəsi | B13: 1 | C13: 1
A14: Monitorinq şöbəsi | B14: 3
A15: Məhsulun qaytarılması şöbəsi | B15: 9
A16: Kütləvi sərhəd keçidi şöbəsi | B16: 5
A17: Texniki xidmət və inzibati təsərrüfat şöbəsi | B17: 20
A18: Təchizat Zənciri bloku/Logistika Məhsul departamenti | B18: 3 | D18: 4
A19: İnkişaf bloku | B19: 2 | C19: 1 | D19: 5
A20: İnkişaf qrupu | B20: 2 | C20: 1 | D20: 1
A21: Data və analitika departamenti | B21: 11 | D21: 10
A22: Aİ və modelləşdirmə departamenti | B22: 8
A23: Məhsul və Texnologiyalar bloku | B23: 12 | D23: 7
A24: Məhsul və Texnologiyalar bloku/Mühəndislik departamenti | B24: 23 | D24: 103
A25: Maliyyə bloku
A26: Maliyyə bloku/Maliyyə hesabatları və mühasibatlıq departamenti | B26: 29
A27: Maliyyə planlaması və analitika departamenti | B27: 8 | C27: 2
A28: Maliyyə bloku/Hüquq, komplayens və sənədlərə nəzarət şöbəsi | B28: 2
A29: Maliyyə bloku/Satınalma və təchizat şöbəsi | B29: 2
A30: Maliyyə bloku/Maliyyə Xidmətləri və Ekosistem İnteqrasiyası bölməsi | B30: 1 | C30: 1
A31: İnsanlar və korporativ mədəniyyət bloku
A32: HR Biznes Tərəfdaşlığı şöbəsi | B32: 2
A33: İstedadların İdarə Edilməsi şöbəsi | B33: 3 | D33: 1
A34: Ümumi inzibati şöbəsi | B34: 7
A35: İdarəetmə və rəhbərlik | B35: 1
A36: Layihələrin idarə edilməsi departamenti | B36: 1
A37: Müştəri xidməti və marketpleys əməliyyatları departamenti | B37: 167 | C37: 10
A38: İşçi Performansının Təkmilləşdirilməsi Departamenti | B38: 2 | C38: 1 | D38: 3
A39: Sağlamlıq, əməyin təhlükəsizliyi və ətraf mühitin mühafizəsi şöbəsi | B39: 1
A40: Cəmi | B40: =SUM(B3:B39) -> 638 | C40: =SUM(C3:C39) -> 27 | D40: =SUM(D3:D39) -> 139 | E40: =SUM(E3:E39) -> 455 | F40: =SUM(F3:F39) -> 80

Sheet Pashapay işçi siyahısı
A1: Status | B1: ID | C1: Category (Main) | D1: Name Surname | E1: Soyad, Ad, Ata adı | F1: Department | G1: Departament | H1: Division | I1: Şöbə | J1: Position | K1: Mövcud Yeni Vəzifə | L1: Reporting to (Need Update) | M1: İşə qəbul tarixi | N1: Müqavilə bitmə tarixi | O1: Müqavilə müddəti | P1: RİM | Q1: Doğum tarixi | R1: Yaş | S1: FIN | T1: Vətəndaşlıq | U1: Seriya nömrəsi | V1: Ş.V bitmə tarixi | W1: İş rejimi | X1: Təhsil səv. | Y1: Cins | Z1: Əlaqə nömrəsi | AB1: Korporativ emai | AC1: Personal e-mail | AD1: Address of Registration | AE1: Residency Address | AF1: Familiy status | AG1: Children | AH1: Termination | AI1: Location
A2: Active | B2: ID-01 | C2: H | D2: Ilaha Zeynalova, Aflatun | E2: Zeynalova İlahə Əflatun qızı | F2: Terminal and ATM department | G2: Terminal və ATM şəbəkəsinin idarə edilməsi departamenti | H2: - | I2: - | J2: Head of Terminals Network Management | K2: Direktor | L2: Tağıyev Camal İlham oğlu | M2: 39819 | O2: Indefinite | Q2: 28620 | R2: 48.435616 | S2: 12P0418 | T2: Azerbaijan | U2: AZE 17622290 | W2: Full time | X2: Bachelor | Y2: Female | Z2: +994555050823 | AA2: +994555050823 | AB2: ilaha.zeynalova@pashapay.az | AD2: Bakı Şəh, A.İsgəndərov Küç ,Ev 1, M 12 | AE2: Bakı Şəh, A.İsgəndərov Küç ,Ev 1, M 12 | AF2: single | AG2: 0 | AI2: Port Baku 2
A3: Active | B3: ID-04 | C3: A | D3: Asim Bayramov, Sahib | E3: Bayramov Asim Sahib oğlu | F3: - | G3: - | H3: Encashment division | I3: İnkassasiya Şöbəsi | J3: Driver Incasator | K3: Sürücü inkassator | L3: Abbasova Nurlana Ramiz qızı | M3: 40508 | O3: Indefinite | P3: Baki | Q3: 31870 | R3: 39.531507 | S3: 385BR9W | T3: Azerbaijan | U3: AZE 15356388 | W3: Full time | Y3: Male | Z3: +994552801009 | AB3: - | AD3: Bakı Şəh.,Nərimanov Ray., Ş. Mustafayev Küç., Ev 5 M.16 | AE3: Bakı Şəh., Ş. Mustafayev Küç., Ev 5 M.16 | AF3: married | AG3: 2 | AI3: Sabail rayonu, Gülbala Əliyev 54C
A4: Active | B4: ID-05 | C4: TL | D4: Nurlan Mahmudov, Valeh | E4: Mahmudov Nurlan Valeh oğlu | F4: Terminal business support department | G4: Terminal biznesinə dəstək departamenti | H4: Encashment processes support division | I4: İnkassasiya proseslərinə dəstək şöbəsi | J4: Team Lead | K4: Qrup Rəhbəri | L4: Rüstəmzadə İlqar Vilayət oğlu | M4: 40592 | O4: Indefinite | Q4: 32181 | R4: 38.679452 | S4: 2CJ6GL0 | T4: Azerbaijan | U4: AZE 16433572 | W4: Full time | Y4: Male | Z4: +994555050888 | AA4: +994555050888 | AB4: nurlan.mahmudov@pashapay.az | AD4: Ağdam Ray., Saybalı K. | AE4: Bakı Şəh., Nəsimi R. Tbilisi Pr. 1058-Ci Məh, Bina 36A, M.56 | AF4: married | AG4: 1 | AI4: Sabail rayonu, Gülbala Əliyev 54C
A5: Active | B5: ID-06 | C5: M | D5: Shirinbika Mahmudova, Mushvig | E5: Mahmudova Şirinbikə Müşviq qızı | F5: Financial management department | G5: Maliyyə menecmenti departamenti | H5: Budget control division | I5: Büdcəyə nəzarət şöbəsi | J5: Manager | K5: Menecer | L5: Ağayev Mirşahin Mircəfər oğlu | M5: 40620 | O5: Indefinite | Q5: 33246 | R5: 35.761644 | S5: 54RXPZ2 | T5: Azerbaijan | U5: AZE 15972901 | W5: Full time | Y5: Female | Z5: +994502906868 | AA5: +994502906868 | AB5: shirin.makhmudova@pashapay.az | AD5: Bakı Şəh., Nəsimi R. Tbilisi Pr. 1058-Ci Məh, Bina 36A, M.56 | AE5: Bakı Şəh., Nəsimi R. Tbilisi Pr. 1058-Ci Məh, Bina 36A, M.56 | AF5: married | AG5: 1 | AI5: Port Baku 2
A6: Active | B6: ID-07 | C6: TL | D6: Bakhtiyar Abdul-Ahadov, Shahid | E6: Abdul-Əhədov Bəxtiyar Şahid oğlu | F6: Terminal business support department | G6: Terminal biznesinə dəstək departamenti | H6: Terminal maintenance division | I6: Texniki təmir şöbəsi | J6: Team Lead | K6: Qrup Rəhbəri | L6: Nəbiyev Namiq Şahbəddin oğlu | M6: 40833 | O6: Indefinite | Q6: 26583 | R6: 54.016438 | S6: 5Z2EVQX | T6: Azerbaijan | U6: AZE 16149326 | W6: Full time | Y6: Male | Z6: +994555050880 | AA6: +994555050880 | AB6: bakhtiyar.abdul-ahadov@pashapay.az | AD6: Bakı Şəh., Babək Pr-Ti. Ev. 13, M. 15 | AE6: Bakı Şəh., Babək Pr-Ti. Ev. 13, M. 15 | AF6: married | AG6: 2 | AI6: Sabail rayonu, Gülbala Əliyev 54C
A7: Active | B7: ID-08 | C7: S | D7: Saida Najafova, Ali | E7: Nəcəfova Səidə Əli qızı | F7: Customer excellence department | G7: Müştəri mükəmməlliyi departamenti | H7: Customer care division | I7: Müştəri xidmətləri şöbəsi | J7: Senior Front Office Specialist | K7: Ön Masa üzrə Baş Mütəxəssis | L7: Əmirov Savalan İsrəfil oğlu | M7: 40841 | O7: Indefinite | Q7: 32461 | R7: 37.912329 | S7: 3FYUDSZ | T7: Azerbaijan | U7: AZE 16880009 | W7: Full time | Y7: Female | Z7: +994555050859 | AA7: +994555050859 | AB7: saida.nacafova@pashapay.az | AD7: Sumqayıt Şəh., Corat Qəs.,2-Məhəllə.133A | AE7: Sumqayıt Şəh., 1 Mr, Ev. 5B\9, M. 46 | AF7: married | AG7: 1 | AI7: Xırdalan
A8: Disabled | B8: ID-09 | C8: S | D8: Shahin Jabbarov, Arif | E8: Cabbarov Şahin Arif oğlu | F8: Terminal business support department | G8: Terminal biznesinə dəstək departamenti | H8: Terminal maintenance division | I8: Texniki təmir şöbəsi | J8: Technician Specialist | K8: Texniki İşlər üzrə Mütəxəssis | L8: Nəbiyev Namiq Şahbəddin oğlu | M8: 40858 | O8: Indefinite | Q8: 30281 | R8: 43.884932 | S8: 123F2UX | T8: Azerbaijan | U8: AZE 17738710 | W8: Full time | Y8: Male | Z8: +994555050882 | AB8: - | AD8: Bakı Şəh., Ə.Cavad, Ev. 37 | AE8: Bakı Şəh., Ə.Cavad, Ev. 37 | AF8: married | AG8: 2 | AI8: Sabail rayonu, Gülbala Əliyev 54C
A9: Active | B9: ID-14 | C9: TL | D9: Parviz Mayilov, Anvar | E9: Mayılov Pərviz Ənvər oğlu | F9: Terminal business support department | G9: Terminal biznesinə dəstək departamenti | H9: Terminal maintenance division | I9: Texniki təmir şöbəsi | J9: Team Lead | K9: Qrup Rəhbəri | L9: Nəbiyev Namiq Şahbəddin oğlu | M9: 41052 | O9: Indefinite | Q9: 32226 | R9: 38.556164 | S9: 27R7T84 | T9: Azerbaijan | U9: AZE 13532074 | W9: Full time | Y9: Male | Z9: +994555050868 | AA9: +994555050868 | AB9: parviz.mayilov@pashapay.az | AD9: Bakı Şəh., Əmircan Qəs., E.Həsənov Küç., Ev 95.,M.67/68 | AE9: Bakı Şəh., Əmircan Qəs., E.Həsənov Küç., Ev 95.,M.67/68 | AF9: married | AG9: 3 | AI9: Sabail rayonu, Gülbala Əliyev 54C
A10: Active | B10: ID-15 | C10: A | D10: Azer Afandiyev, Dadash | E10: Əfəndiyev Azər Dadaş oğlu | F10: Terminal business support department | G10: Terminal biznesinə dəstək departamenti | H10: Terminal technical support division | I10: Terminallara texniki dəstək şöbəsi | J10: Technical worker on terminal payments | K10: Terminal ödənişləri üzrə texniki işçi | L10: Əlizadə Nicat Əşrəf oğlu | M10: 41309 | O10: Indefinite | Q10: 31043 | R10: 41.79726 | S10: 2C5U6NR | T10: Azerbaijan | U10: AA 1276075 | W10: Full time | Y10: Male | Z10: +994555050877 | AB10: - | AD10: Bakı Şəh.,Nərimanov Ray.,Azadlıq Pr.,Ev.116,M.146 | AE10: Bakı Şəh.,Azadlıq Pr., Ev.116.,M.146 | AF10: married | AG10: 2 | AI10: Sabail rayonu, Gülbala Əliyev 54C
A11: Active | B11: ID-16 | C11: A | D11: Samir Zeynalov, Nizami | E11: Zeynalov Samir Nizami oğlu | F11: Terminal business support department | G11: Terminal biznesinə dəstək departamenti | H11: Terminal technical support division | I11: Terminallara texniki dəstək şöbəsi | J11: Technical worker on terminal payments | K11: Terminal ödənişləri üzrə texniki işçi | L11: Əlizadə Nicat Əşrəf oğlu | M11: 41421 | O11: Indefinite | Q11: 28198 | R11: 49.591781 | S11: 3JVXJS3 | T11: Azerbaijan | U11: AZE 13516551 | W11: Full time | Y11: Male | Z11: +994555050856 | AB11: - | AD11: Gəncə Şəh.,Nizami Küç.,12-Dal.,Ev 17A | AE11: Gəncə Şəh.,Nizami Küç.,12-Dal.,Ev 17A | AF11: married | AG11: 2 | AI11: Gəncə RİM
A12: Active | B12: ID-20 | C12: A | D12: Gismat Mammadov, Ali | E12: Məmmədov Qismət Əli oğlu | F12: - | G12: - | H12: Encashment division | I12: İnkassasiya Şöbəsi | J12: Driver Incasator | K12: Sürücü inkassator | L12: Abbasova Nurlana Ramiz qızı | M12: 41487 | O12: Indefinite | P12: Sumqayıt RİM | Q12: 24196 | R12: 60.556164 | S12: 3DRGLDR | T12: Azerbaijan | U12: AZE 15772995 | W12: Full time | Y12: Male | Z12: +994555050732 | AB12: - | AD12: Sumqayıt Şəh.,Mik-13, Ev.40, M.8 | AE12: Sumqayıt Şəh.,Mik-13, Ev.4 , M.8 | AF12: married | AG12: 2 | AI12: Sumqayıt RİM
A13: Active | B13: ID-19 | C13: A | D13: Elvin Mukhtarov, Yagub | E13: Muxtarov Elvin Yaqub oğlu | F13: - | G13: - | H13: Encashment division | I13: İnkassasiya Şöbəsi | J13: Cash Collector | K13: Kassir inkassator | L13: Abbasova Nurlana Ramiz qızı | M13: 41487 | O13: Indefinite | P13: Baki | Q13: 31933 | R13: 39.358904 | S13: 2TR9LZV | T13: Azerbaijan | U13: AZE 16939587 | W13: Full time | Y13: Male | Z13: +994555050881 | AB13: - | AD13: Bakı Şəh.,Sabunçu Ray.,Bakıxanov Qəs.,Y.Əliyev Küç.,Ev 3/51 | AE13: Bakı Şəh.,Bakıxanov Qəs.,Y.Əliyev Küç.,Ev 3/51 | AF13: married | AG13: 2 | AI13: Sabail rayonu, Gülbala Əliyev 54C
A14: Active | B14: ID-22 | C14: A | D14: Vasif Garibli, Hafiz | E14: Qəribli Vasif Hafiz oğlu | F14: Terminal business support department | G14: Terminal biznesinə dəstək departamenti | H14: Terminal technical support division | I14: Terminallara texniki dəstək şöbəsi | J14: Technical worker on terminal payments | K14: Terminal ödənişləri üzrə texniki işçi | L14: Əlizadə Nicat Əşrəf oğlu | M14: 41673 | O14: Indefinite | Q14: 33608 | R14: 34.769863 | S14: 4U72XH4 | T14: Azerbaijan | U14: AZE 16693991 | W14: Full time | Y14: Male | Z14: +994555050729 | AB14: - | AD14: İmişli Şəh., Ş.Qurbanov Küç., Ev.1 | AE14: Bakı Şəh.,Yasamal R-Nu, 2-Ci Alatava Ev 6A | AF14: married | AG14: 0 | AI14: Şirvan RİM
A15: Active | B15: ID-21 | C15: S | D15: Nijat Soltanov, Zulfigar | E15: Soltanov Nicat Zülfiqar oğlu | F15: Terminal business support department | G15: Terminal biznesinə dəstək departamenti | H15: Terminal business support division | I15: Terminal biznesinə dəstək şöbəsi | J15: Leading Warehouseman | K15: Aparıcı Anbardar | L15: Fərzəliyev Zaur Tofiq oğlu | M15: 41673 | O15: Indefinite | Q15: 31799 | R15: 39.726027 | S15: 1G7BF52 | T15: Azerbaijan | U15: AZE 13601703 | W15: Full time | Y15: Male | Z15: +994555050854 | AA15: +994555050854 | AB15: nicat.soltanov@pashapay.az | AD15: Bakı Şəh., Balandin- 42 | AE15: Bakı Şəh.,Suraxanı R-Nu Qaraçuxur Qəs.,Zaur Şərifov Küç., Ev.6, M. 5 | AF15: married | AG15: 2 | AI15: Sabail rayonu, Gülbala Əliyev 54C
A16: Active | B16: ID-23 | C16: M | D16: Nijat Alizade, Ashraf | E16: Əlizadə Nicat Əşrəf oğlu | F16: Terminal business support department | G16: Terminal biznesinə dəstək departamenti | H16: Terminal technical support division | I16: Terminallara texniki dəstək şöbəsi | J16: Technical Support Division Manager | K16: Texniki Dəstək üzrə Menecer | L16: Abbasov Toğrul Vaqif oğlu | M16: 41682 | O16: Indefinite | Q16: 32621 | R16: 37.473973 | S16: 4TARMCF | T16: Azerbaijan | U16: AZE 14910111 | W16: Full time | Y16: Male | Z16: +994555050885 | AA16: +994555050885 | AB16: nicat.alizade@pashapay.az | AD16: Füzuli Şəh., H.Hacıyev Küç.,Ev.17 | AE16: Bakı Şəh.,Sabunçu R-Nu Bakıxanov Qəs., Y.Əliyev Küç., Ev.1, M.41 | AF16: married | AG16: 1 | AI16: Sabail rayonu, Gülbala Əliyev 54C
A17: Active | B17: ID-24 | C17: A | D17: Emil Huseynov, Vagif | E17: Hüseynov Emil Vaqif oğlu | F17: - | G17: - | H17: Encashment division | I17: İnkassasiya Şöbəsi | J17: Cash Collector | K17: Kassir inkassator | L17: Abbasova Nurlana Ramiz qızı | M17: 41745 | O17: Indefinite | P17: Gəncə RİM | Q17: 31979 | R17: 39.232877 | S17: 26VBFGM | T17: Azerbaijan | U17: AA3901744 | V17: 48428 | W17: Full time | Y17: Male | Z17: +994555050829 | AB17: - | AD17: Gəncə Şəh.,Gülüstan Qəs.,Ev 47V,Mənzil 10 | AE17: Gəncə Şəh., M.Hacıyev Küç.,Ev 17 , M. 79 | AF17: married | AG17: 2 | AI17: Gəncə RİM
A18: Active | B18: ID-27 | C18: A | D18: Farid Ramazanov, Tanriverdi | E18: Ramazanov Fərid Tanrıverdi oğlu | F18: Terminal business support department | G18: Terminal biznesinə dəstək departamenti | H18: Terminal technical support division | I18: Terminallara texniki dəstək şöbəsi | J18: Technical worker on terminal payments | K18: Terminal ödənişləri üzrə texniki işçi | L18: Əlizadə Nicat Əşrəf oğlu | M18: 41792 | O18: Indefinite | Q18: 32432 | R18: 37.991781 | S18: 2K8WVV2 | T18: Azerbaijan | U18: AA3681121 | V18: 48265 | W18: Full time | Y18: Male | Z18: +994555050725 | AB18: - | AD18: Gəncə Şəh.,Nizami Ray.,Nizami Küç.,12-Dal.,Ev.22 | AE18: Gəncə Şəh.,Nizami Ray.,Nizami Küç.,12-Dal.,Ev.22 | AF18: single | AG18: 0 | AI18: Gəncə RİM
A19: Active | B19: ID-28 | C19: A | D19: Ilkin Aghazade, Ilgar | E19: Ağazadə İlkin İlqar oğlu | F19: - | G19: - | H19: Encashment division | I19: İnkassasiya Şöbəsi | J19: Cash Collector | K19: Kassir inkassator | L19: Abbasova Nurlana Ramiz qızı | M19: 41815 | O19: Indefinite | P19: Sumqayıt RİM | Q19: 34093 | R19: 33.441096 | S19: 5KH5LQE | T19: Azerbaijan | U19: AZE 17486581 | W19: Full time | Y19: Male | Z19: +994555050837 | AB19: - | AD19: Bakı Şəh.,Binəqədi Qəs.,Mədən-2 Kor-94, Ev.7 | AE19: Bakı Şəh.,Binəqədi Qəs.,Mədən-2 Kor-94, Ev.7 | AF19: single | AG19: 0 | AI19: Sumqayıt RİM
A20: Active | B20: ID-29 | C20: TL | D20: Sarkhan Mahmudov, Bakhtijamal | E20: Mahmudov Sərxan Bəxticamal oğlu | F20: - | G20: - | H20: Encashment division | I20: İnkassasiya Şöbəsi | J20: Cash Team Leader | K20: Kassa üzrə Qrup Rəhbəri | L20: Abbasova Nurlana Ramiz qızı | M20: 41834 | O20: Indefinite | Q20: 34190 | R20: 33.175342 | S20: 5QNKESL | T20: Azerbaijan | U20: AZE 07794353 | W20: Full time | Y20: Male | Z20: +994555050713 | AA20: +994555050713 | AB20: sarxan.mahmudov@pashapay.az | AD20: Gəncə Şəh.,Ordubadi Küç.,Ev.52 | AE20: Gəncə Şəh.,Ordubadi Küç.,Ev.52 | AF20: single | AG20: 0 | AI20: Tovuz RİM
A21: Active | B21: ID-31 | C21: A | D21: Samir Mammadov, Rafig | E21: Məmmədov Samir Rafiq oğlu | F21: Terminal business support department | G21: Terminal biznesinə dəstək departamenti | H21: Terminal business support division | I21: Terminal biznesinə dəstək şöbəsi | J21: Labourer | K21: Fəhlə | L21: Fərzəliyev Zaur Tofiq oğlu | M21: 41900 | O21: Indefinite | Q21: 31001 | R21: 41.912329 | S21: 5N6TJJ2 | T21: Azerbaijan | U21: AA 1564987 | W21: Full time | Y21: Male | Z21: +994775413114 | AB21: - | AD21: Bakı Şəh., Binəqədi Ray.,Xocəsən Qəs.F.Ağazadə Küç., Ev.9. | AE21: Bakı Şəh., Xocəsən Qəs.F.Ağazadə Küç., Ev.9. | AF21: married | AG21: 2 | AI21: Sabail rayonu, Gülbala Əliyev 54C
A22: Active | B22: ID-32 | C22: A | D22: Novruz Aliyev, Gardashkhan | E22: Əliyev Novruz Qardaşxan oğlu | F22: - | G22: - | H22: Encashment division | I22: İnkassasiya Şöbəsi | J22: Driver Incasator | K22: Sürücü inkassator | L22: Abbasova Nurlana Ramiz qızı | M22: 41913 | O22: Indefinite | P22: Baki | Q22: 21253 | R22: 68.619178 | S22: 0XWH4TN | T22: Azerbaijan | U22: AZE 07490998 | W22: Full time | Y22: Male | Z22: +994554305274 | AB22: - | AD22: Bakı Şəh., Y/Günəşli Qəs., V Y/S., Ev.6., M. 64 | AE22: Bakı Şəh., Y/Günəşli Qəs., V Y/S., Ev.6., M. 64 | AF22: married | AG22: 2 | AI22: Sabail rayonu, Gülbala Əliyev 54C
A23: Active | B23: ID-38 | C23: A | D23: Elvin Rzayev, Anvar | E23: Rzayev Elvin Ənvər oğlu | F23: - | G23: - | H23: Encashment division | I23: İnkassasiya Şöbəsi | J23: Cash Collector | K23: Kassir inkassator | L23: Abbasova Nurlana Ramiz qızı | M23: 41975 | O23: Indefinite | P23: Lənkaran RİM | Q23: 31329 | R23: 41.013699 | S23: 1SDS8RN | T23: Azerbaijan | U23: AZE 13790923 | W23: Full time | Y23: Male | Z23: +994555050886 | AB23: - | AD23: Astara Ray., Maşxan Kəndi | AE23: Astara Ray., Maşxan Kəndi | AF23: married | AG23: 3 | AI23: Lənkaran RİM
A24: Active | B24: ID-39 | C24: S | D24: Amina Mammadli, Tahir | E24: Məmmədli Əminə Tahir qızı | F24: Customer excellence department | G24: Müştəri mükəmməlliyi departamenti | H24: Customer care division | I24: Müştəri xidmətləri şöbəsi | J24: Leading Front Office Specialist | K24: Ön Masa üzrə Aparıcı Mütəxəssis | L24: Əmirov Savalan İsrəfil oğlu | M24: 41984 | O24: Indefinite | Q24: 33528 | R24: 34.989041 | S24: 5B32QXX | T24: Azerbaijan | U24: AZE 16698689 | W24: Full time | Y24: Female | Z24: +994555050827 | AA24: +994555050827 | AB24: amina.karimli@pashapay.az | AD24: Lənkəran Şəh., S. Bayramov Küç., Ev.15 | AE24: Lənkəran Şəh., S. Bayramov Küç., Ev.15 | AF24: married | AG24: 1 | AI24: Lənkaran RİM
A25: Active | B25: ID-40 | C25: A | D25: Yegana Hajiyeva, Safar | E25: Hacıyeva Yeganə Səfər qızı | F25: - | G25: - | H25: - | I25: - | J25: Cleaning Lady | K25: Xidmətçi | L25: KB-yə Kassa və inkassasiya prosesləri departamentinə keçirilir, rəsmiləşmədədirlər. | M25: 42010 | O25: Indefinite | Q25: 26712 | R25: 53.663014 | S25: 2H535C8 | T25: Azerbaijan | U25: AZE 15009421 | W25: Full time | Y25: Female | Z25: +994514914125 | AB25: - | AD25: Lənkəran Ray., İstisu Qəs. | AE25: Lənkəran Ray., İstisu Qəs. | AF25: married | AG25: 2 | AI25: Lənkaran RİM
A26: Disabled | B26: ID-41 | C26: S | D26: Akif Salmanov, Israfil | E26: Salmanov Akif İsrafil oğlu | F26: Terminal business support department | G26: Terminal biznesinə dəstək departamenti | H26: Terminal maintenance division | I26: Texniki təmir şöbəsi | J26: Technician Specialist | K26: Texniki İşlər üzrə Mütəxəssis | L26: Nəbiyev Namiq Şahbəddin oğlu | M26: 42061 | O26: Indefinite | Q26: 22369 | R26: 65.561644 | S26: 2KD6A24 | T26: Azerbaijan | U26: AZE 09241005 | W26: Full time | Y26: Male | Z26: +994505475742 | AB26: - | AD26: Abşeron Ray., Masazır Kəndi, Yolaltı 1 Küç. | AE26: Abşeron Ray., Əliağa Vahid Küç.14 | AF26: married | AG26: 2 | AI26: Distant
A27: Active | B27: ID-43 | C27: A | D27: Iltimas Guliyeva, Mammadali | E27: Quliyeva İltimas Məmmədəli qızı | F27: - | G27: - | H27: - | I27: - | J27: Cleaning Lady | K27: Xidmətçi | L27: KB-yə Kassa və inkassasiya prosesləri departamentinə keçirilir, rəsmiləşmədədirlər. | M27: 42074 | O27: Indefinite | Q27: 22255 | R27: 65.873973 | S27: 3N5CSXL | T27: Azerbaijan | U27: AZE 09191323 | W27: Full time | Y27: Female | Z27: +994558204812 | AB27: - | AD27: Gəncə Şəh., Qaçaq Nəbi Küç., Ev.18 | AE27: Gəncə Şəh., Qaçaq Nəbi Küç., Ev.18 | AF27: married | AG27: 2 | AI27: Gəncə RİM
