Workbook

Sheet ştat sayları
A1: Keçmiş Struktur adı | B1: Keçmiş Ştat sayı | C1: Yeni Struktur adı | D1: Yeni Ştat sayı | E1: Müxtəlif mənbələrdən əlavə edilmiş ştat sayı | F1: Cəm ştat sayı | G1: Pashapay | H1: Birmarket | I1: Paşa holding | J1: Future lab | K1: Keçid cəm | L1: Fərq səbəbi | M1: Səbəb | N1: Qeyd | R1: 46279
A2: Arxitektura ekspert mərkəzi | B2: 14 | C2: Arxitektura ekspert mərkəzi | D2: 8 | E2: - | F2: 8 | G2: =COUNTIFS(baza!B:B,'ştat sayları'!C:C,baza!H:H,"Bir Payment") -> 0 | H2: =COUNTIFS(baza!B:B,'ştat sayları'!C:C,baza!H:H,"BirMarket") -> 0 | I2: =COUNTIFS(baza!B:B,'ştat sayları'!C:C,baza!H:H,"Paşa Holding") -> 0 | J2: =COUNTIFS(baza!B:B,'ştat sayları'!C:C,baza!H:H,"Future lab") -> 0 | K2: =G2+H2+I2+J2 -> 0 | L2: 2 si Ödəniş biznesinin arxitektura və İT idarəetmə prosesi prosesi, 4 İT proseslərinin idarə edilməsi funksional sahəsi | M2: Struktur dəyişiklik
A3: Dizayn ekspert mərkəzi | B3: 45 | C3: Dizayn ekspert mərkəzi | D3: 59 | E3: 1 pashapay, 3 future lab keçid | F3: 63 | G3: =COUNTIFS(baza!B:B,'ştat sayları'!C:C,baza!H:H,"Bir Payment") -> 10 | H3: =COUNTIFS(baza!B:B,'ştat sayları'!C:C,baza!H:H,"BirMarket") -> 6 | I3: =COUNTIFS(baza!B:B,'ştat sayları'!C:C,baza!H:H,"Paşa Holding") -> 0 | J3: =COUNTIFS(baza!B:B,'ştat sayları'!C:C,baza!H:H,"Future lab") -> 3 | K3: =G3+H3+I3+J3 -> 19 | L3: 1- müştəri təcrübəsi ekspert mərkəzinə geri verilib | M3: Keçidlər
A4: İnzibati idarəetmə departamenti | B4: 141 | C4: İnzibati idarəetmə departamenti | D4: 161 | E4: 1 pashapay | F4: 162 | G4: 19 | H4: =COUNTIFS(baza!B:B,'ştat sayları'!C:C,baza!H:H,"BirMarket") -> 2 | I4: =COUNTIFS(baza!B:B,'ştat sayları'!C:C,baza!H:H,"Paşa Holding") -> 0 | J4: =COUNTIFS(baza!B:B,'ştat sayları'!C:C,baza!H:H,"Future lab") -> 0 | K4: =G4+H4+I4+J4 -> 21 | M4: Keçidlər
A5: Komplayens departamenti | B5: 48 | C5: Komplayens departamenti | D5: 52 | E5: - | F5: 52 | G5: =COUNTIFS(baza!B:B,'ştat sayları'!C:C,baza!H:H,"Bir Payment") -> 3 | H5: =COUNTIFS(baza!B:B,'ştat sayları'!C:C,baza!H:H,"BirMarket") -> 1 | I5: =COUNTIFS(baza!B:B,'ştat sayları'!C:C,baza!H:H,"Paşa Holding") -> 0 | J5: =COUNTIFS(baza!B:B,'ştat sayları'!C:C,baza!H:H,"Future lab") -> 0 | K5: =G5+H5+I5+J5 -> 4 | M5: Keçidlər
A6: Korporativ katiblik şöbəsi | B6: 34.5 | C6: Korporativ katiblik şöbəsi | D6: 36.5 | E6: 1 future lab | F6: 37.5 | G6: 1 | H6: 1 | I6: =COUNTIFS(baza!B:B,'ştat sayları'!C:C,baza!H:H,"Paşa Holding") -> 0 | J6: 1 | K6: =G6+H6+I6+J6 -> 3 | M6: Keçidlər
A7: Ekosistemin partnyor şəbəkəsi departamenti | B7: 74 | C7: Biznes sahələrinin inkişafı və partnyor şəbəkəsi departamenti | D7: 99 | E7: - | F7: 99 | G7: =COUNTIFS(baza!B:B,'ştat sayları'!C:C,baza!H:H,"Bir Payment") -> 24 | H7: =COUNTIFS(baza!B:B,'ştat sayları'!C:C,baza!H:H,"BirMarket") -> 1 | I7: =COUNTIFS(baza!B:B,'ştat sayları'!C:C,baza!H:H,"Paşa Holding") -> 1 | J7: =COUNTIFS(baza!B:B,'ştat sayları'!C:C,baza!H:H,"Future lab") -> 0 | K7: =G7+H7+I7+J7 -> 26 | L7: 1-nağd pulların idarə edilməsi dep verilib | M7: Struktur dəyişiklik və keçidlər
A8: Müştəri təcrübəsi ekspert mərkəzi | B8: 13 | C8: Müştəri təcrübəsi ekspert mərkəzi | D8: 16 | E8: 2 future lab, 7 payment | F8: 25 | G8: =COUNTIFS(baza!B:B,'ştat sayları'!C:C,baza!H:H,"Bir Payment") -> 7 | H8: =COUNTIFS(baza!B:B,'ştat sayları'!C:C,baza!H:H,"BirMarket") -> 0 | I8: =COUNTIFS(baza!B:B,'ştat sayları'!C:C,baza!H:H,"Paşa Holding") -> 0 | J8: =COUNTIFS(baza!B:B,'ştat sayları'!C:C,baza!H:H,"Future lab") -> 2 | K8: =G8+H8+I8+J8 -> 9 | L8: 3-marketinqdən,pashapaydan , dizayn ekspert mərkəzindən | M8: Keçidlər
A9: yeni struktur | B9: 0 | C9: Kredit portfelinə nəzarət departamenti | D9: 35 | E9: 1 i fintech analitika və ai verildi | F9: 34 | G9: =COUNTIFS(baza!B:B,'ştat sayları'!C:C,baza!H:H,"Bir Payment") -> 0 | H9: =COUNTIFS(baza!B:B,'ştat sayları'!C:C,baza!H:H,"BirMarket") -> 0 | I9: =COUNTIFS(baza!B:B,'ştat sayları'!C:C,baza!H:H,"Paşa Holding") -> 0 | J9: =COUNTIFS(baza!B:B,'ştat sayları'!C:C,baza!H:H,"Future lab") -> 0 | K9: =G9+H9+I9+J9 -> 0 | L9: 31 nəzarət,+3 maliyyə risk id ed, +1 biznes risk texnologiyaları sahəsi, +1 pərakəndə risk texnologiyaları sahəsi, -1 fintech mühəndislik , -1 fintech analitika | M9: Struktur dəyişiklik
A10: başqa sahənin parçalanması | B10: 0 | C10: FinTech TechOps funksional sahəsi | D10: 16 | E10: - | F10: 16 | G10: =COUNTIFS(baza!B:B,'ştat sayları'!C:C,baza!H:H,"Bir Payment") -> 0 | H10: =COUNTIFS(baza!B:B,'ştat sayları'!C:C,baza!H:H,"BirMarket") -> 0 | I10: =COUNTIFS(baza!B:B,'ştat sayları'!C:C,baza!H:H,"Paşa Holding") -> 0 | J10: =COUNTIFS(baza!B:B,'ştat sayları'!C:C,baza!H:H,"Future lab") -> 0 | K10: =G10+H10+I10+J10 -> 0 | L10: 15 devops ekspert mərkəzi, 1 fintech mühəndislik | M10: Struktur dəyişiklik
A11: Biznesə dəstək departamenti | B11: 190 | C11: Biznesə dəstək departamenti | D11: 116 | E11: - | F11: 116 | G11: =COUNTIFS(baza!B:B,'ştat sayları'!C:C,baza!H:H,"Bir Payment") -> 0 | H11: =COUNTIFS(baza!B:B,'ştat sayları'!C:C,baza!H:H,"BirMarket") -> 0 | I11: =COUNTIFS(baza!B:B,'ştat sayları'!C:C,baza!H:H,"Paşa Holding") -> 0 | J11: =COUNTIFS(baza!B:B,'ştat sayları'!C:C,baza!H:H,"Future lab") -> 0 | K11: =G11+H11+I11+J11 -> 0 | L11: 18 verildi xkied, -35 nağd pulların id edilməsi, -8 kart klirinqi və hesablaşmalar, -30 texniki dəstək, +11 satış kanalları, +6 maliyyə hesabatlıq | M11: Struktur dəyişiklik
A12: Məhsulların rəsmiləşdirilməsi sahəsi | B12: 5 | C12: Məhsulların rəsmiləşdirilməsi sahəsi | D12: 5 | E12: - | F12: 5 | G12: =COUNTIFS(baza!B:B,'ştat sayları'!C:C,baza!H:H,"Bir Payment") -> 0 | H12: =COUNTIFS(baza!B:B,'ştat sayları'!C:C,baza!H:H,"BirMarket") -> 0 | I12: =COUNTIFS(baza!B:B,'ştat sayları'!C:C,baza!H:H,"Paşa Holding") -> 0 | J12: =COUNTIFS(baza!B:B,'ştat sayları'!C:C,baza!H:H,"Future lab") -> 0 | K12: =G12+H12+I12+J12 -> 0 | M12: Struktur dəyişiklik
A13: Kart biznesi ekspert mərkəzi | B13: 23 | C13: Kart biznesi ekspert mərkəzi | D13: 12 | E13: - | F13: 12 | G13: =COUNTIFS(baza!B:B,'ştat sayları'!C:C,baza!H:H,"Bir Payment") -> 0 | H13: =COUNTIFS(baza!B:B,'ştat sayları'!C:C,baza!H:H,"BirMarket") -> 0 | I13: =COUNTIFS(baza!B:B,'ştat sayları'!C:C,baza!H:H,"Paşa Holding") -> 0 | J13: =COUNTIFS(baza!B:B,'ştat sayları'!C:C,baza!H:H,"Future lab") -> 0 | K13: =G13+H13+I13+J13 -> 0 | L13: 11 rəqəmsal dələduzluğa qarşı mübarizə dep | M13: Struktur dəyişiklik
A14: Təhlükəsizlik departamenti | B14: 70 | C14: Təhlükəsizlik departamenti | D14: 79 | E14: - | F14: 79 | G14: =COUNTIFS(baza!B:B,'ştat sayları'!C:C,baza!H:H,"Bir Payment") -> 3 | H14: =COUNTIFS(baza!B:B,'ştat sayları'!C:C,baza!H:H,"BirMarket") -> 4 | I14: =COUNTIFS(baza!B:B,'ştat sayları'!C:C,baza!H:H,"Paşa Holding") -> 0 | J14: =COUNTIFS(baza!B:B,'ştat sayları'!C:C,baza!H:H,"Future lab") -> 0 | K14: =G14+H14+I14+J14 -> 7 | L14: 1 birmarket boş ştat, 1 nəzarət dep verilib | M14: Keçidlər | N14: 5 birmarket ştatı verilib, 4 ü istifade edilib
A15: başqa sahənin parçalanması | B15: 0 | C15: İT proseslərinin idarə edilməsi funksional sahəsi | D15: 5 | E15: - | F15: 5 | G15: =COUNTIFS(baza!B:B,'ştat sayları'!C:C,baza!H:H,"Bir Payment") -> 0 | H15: =COUNTIFS(baza!B:B,'ştat sayları'!C:C,baza!H:H,"BirMarket") -> 0 | I15: =COUNTIFS(baza!B:B,'ştat sayları'!C:C,baza!H:H,"Paşa Holding") -> 0 | J15: =COUNTIFS(baza!B:B,'ştat sayları'!C:C,baza!H:H,"Future lab") -> 0 | K15: =G15+H15+I15+J15 -> 0 | L15: 4 arxitektura ekspert mərkəzindən,1 ödəniş biznesinin analitika və ai sahəsindən | M15: Struktur dəyişiklik
A16: İşçi təcrübəsi sahəsi | B16: 6 | C16: Rəqəmsal həllər sahəsi | D16: 6 | E16: - | F16: 6 | G16: =COUNTIFS(baza!B:B,'ştat sayları'!C:C,baza!H:H,"Bir Payment") -> 0 | H16: =COUNTIFS(baza!B:B,'ştat sayları'!C:C,baza!H:H,"BirMarket") -> 0 | I16: =COUNTIFS(baza!B:B,'ştat sayları'!C:C,baza!H:H,"Paşa Holding") -> 0 | J16: =COUNTIFS(baza!B:B,'ştat sayları'!C:C,baza!H:H,"Future lab") -> 0 | K16: =G16+H16+I16+J16 -> 0 | M16: Struktur dəyişiklik
A17: yeni struktur | B17: 0 | C17: Strategiya və layihələrin idarə edilməsi departamenti | D17: 28 | E17: - | F17: 28 | G17: =COUNTIFS(baza!B:B,'ştat sayları'!C:C,baza!H:H,"Bir Payment") -> 3 | H17: =COUNTIFS(baza!B:B,'ştat sayları'!C:C,baza!H:H,"BirMarket") -> 0 | I17: =COUNTIFS(baza!B:B,'ştat sayları'!C:C,baza!H:H,"Paşa Holding") -> 4 | J17: =COUNTIFS(baza!B:B,'ştat sayları'!C:C,baza!H:H,"Future lab") -> 0 | K17: =G17+H17+I17+J17 -> 7 | L17: 2 agile və məhsul eksp m, 10 layihələrin id ed eksp m,5 maliyyə menecmenti dep, +1 agile və məhs eksp m(orxan), 3 boş ştat(1 pashapay,1 holdinq, 1 birmarket) | M17: yeni sahə və keçid
A18: Ekosistem platforma və İD sahəsi | B18: 4 | C18: Ekosistem platforma və İD sahəsi | D18: 5 | E18: - | F18: 5 | G18: =COUNTIFS(baza!B:B,'ştat sayları'!C:C,baza!H:H,"Bir Payment") -> 0 | H18: =COUNTIFS(baza!B:B,'ştat sayları'!C:C,baza!H:H,"BirMarket") -> 0 | I18: =COUNTIFS(baza!B:B,'ştat sayları'!C:C,baza!H:H,"Paşa Holding") -> 0 | J18: =COUNTIFS(baza!B:B,'ştat sayları'!C:C,baza!H:H,"Future lab") -> 0 | K18: =G18+H18+I18+J18 -> 0 | L18: 1 pashapay işdən çıxan əməkdaşın ştatı əlavə edildi | M18: struktur dəyişikliyi yoxdur
A19: Filial | B19: 2018 | C19: Filial | D19: 2008 | E19: 1 vip verildi, -57 ştat ixtisar olunmalı | F19: 1950 | G19: =COUNTIFS(baza!B:B,'ştat sayları'!C:C,baza!H:H,"Bir Payment") -> 0 | H19: =COUNTIFS(baza!B:B,'ştat sayları'!C:C,baza!H:H,"BirMarket") -> 0 | I19: =COUNTIFS(baza!B:B,'ştat sayları'!C:C,baza!H:H,"Paşa Holding") -> 0 | J19: =COUNTIFS(baza!B:B,'ştat sayları'!C:C,baza!H:H,"Future lab") -> 0 | K19: =G19+H19+I19+J19 -> 0 | L19: 1 biznesə dəstək, -2 proqram müh coe(mikro biznes),-1 QA(mikro biznes dep), -1 Fintech analitika(xkied), -1 Təhlükəsizlik, -4 fintech müh(rəqəmsal həllər), -1 vip şöbəsi | M19: struktur dəyişikliyi yoxdur | N19: 57 ştat ləğv olunsun
A20: Ekosistem korporativ maliyyə və investor əlaqələri departamenti | B20: 6 | C20: Korporativ inkişaf və investor əlaqələri departamenti | D20: 6 | E20: - | F20: 6 | G20: =COUNTIFS(baza!B:B,'ştat sayları'!C:C,baza!H:H,"Bir Payment") -> 0 | H20: =COUNTIFS(baza!B:B,'ştat sayları'!C:C,baza!H:H,"BirMarket") -> 0 | I20: =COUNTIFS(baza!B:B,'ştat sayları'!C:C,baza!H:H,"Paşa Holding") -> 0 | J20: =COUNTIFS(baza!B:B,'ştat sayları'!C:C,baza!H:H,"Future lab") -> 0 | K20: =G20+H20+I20+J20 -> 0 | M20: Struktur dəyişiklik
A21: Satış kanalları departamenti | B21: 656 | C21: Satış kanalları departamenti | D21: 669 | E21: - | F21: 669 | G21: =COUNTIFS(baza!B:B,'ştat sayları'!C:C,baza!H:H,"Bir Payment") -> 0 | H21: =COUNTIFS(baza!B:B,'ştat sayları'!C:C,baza!H:H,"BirMarket") -> 0 | I21: =COUNTIFS(baza!B:B,'ştat sayları'!C:C,baza!H:H,"Paşa Holding") -> 0 | J21: =COUNTIFS(baza!B:B,'ştat sayları'!C:C,baza!H:H,"Future lab") -> 0 | K21: =G21+H21+I21+J21 -> 0 | L21: 41mikro biznes dep, -11 Biznesə dəstək dep, -2 Fintech marketinq(müştəri dəyərləri), -2 Fintech Analitika və Aİ(müştəri dəyərləri),-3 Fintech mühəndislik (müştəri dəyərləri),-1 Müştəri dəyərləri, -4 fintech mühəndislik məhsulların rəsmiləşd.sahəsi, -1 Fintech analitika və ai(skd), -2 Rəqəmsal dələduzluğa qarşı mübarizə dep, +1 Fintech analitika və ai(skd)(lazım olmadı geri qaytarıldı), -3 Mühəndislik və texnoloji platform | M21: struktur dəyişikliyi yoxdur
A22: Xəzinədarlıq departamenti | B22: 20 | C22: Xəzinədarlıq departamenti | D22: 21 | E22: - | F22: 21 | G22: =COUNTIFS(baza!B:B,'ştat sayları'!C:C,baza!H:H,"Bir Payment") -> 0 | H22: =COUNTIFS(baza!B:B,'ştat sayları'!C:C,baza!H:H,"BirMarket") -> 0 | I22: =COUNTIFS(baza!B:B,'ştat sayları'!C:C,baza!H:H,"Paşa Holding") -> 0 | J22: =COUNTIFS(baza!B:B,'ştat sayları'!C:C,baza!H:H,"Future lab") -> 0 | K22: =G22+H22+I22+J22 -> 0 | L22: 1OPCO 13N 14.06.2026 | M22: struktur dəyişikliyi yoxdur
A23: İT infrastruktur departamenti | B23: 91 | C23: İT infrastruktur departamenti | D23: 99 | E23: - | F23: 99 | G23: 5 | H23: =COUNTIFS(baza!B:B,'ştat sayları'!C:C,baza!H:H,"BirMarket") -> 1 | I23: =COUNTIFS(baza!B:B,'ştat sayları'!C:C,baza!H:H,"Paşa Holding") -> 0 | J23: =COUNTIFS(baza!B:B,'ştat sayları'!C:C,baza!H:H,"Future lab") -> 0 | K23: =G23+H23+I23+J23 -> 6 | L23: 11 Pashapay, +5 devops coe, +1 analitika coe, -10 İnformasiya təhlükəsizliyi, +1Birmarket keçid üçün | M23: Keçidlər | N23: 11 pashapay ştatı verilib, hələki 5 i keçib
A24: Pərakəndə biznes platformaları sahəsi | B24: 6 | C24: Pərakəndə biznes platformaları sahəsi | D24: 7 | E24: - | F24: 7 | G24: =COUNTIFS(baza!B:B,'ştat sayları'!C:C,baza!H:H,"Bir Payment") -> 0 | H24: =COUNTIFS(baza!B:B,'ştat sayları'!C:C,baza!H:H,"BirMarket") -> 0 | I24: =COUNTIFS(baza!B:B,'ştat sayları'!C:C,baza!H:H,"Paşa Holding") -> 0 | J24: =COUNTIFS(baza!B:B,'ştat sayları'!C:C,baza!H:H,"Future lab") -> 0 | K24: =G24+H24+I24+J24 -> 0 | L24: 1 Fintech müh(pərakəndə biznes platform)-OPCO N 20, 27.07.2026 | M24: struktur dəyişikliyi yoxdur
A25: yeni struktur | B25: 0 | C25: Ekosistemin inkişafı və analitikası departamenti | D25: 11 | E25: - | F25: 11 | G25: =COUNTIFS(baza!B:B,'ştat sayları'!C:C,baza!H:H,"Bir Payment") -> 1 | H25: =COUNTIFS(baza!B:B,'ştat sayları'!C:C,baza!H:H,"BirMarket") -> 0 | I25: =COUNTIFS(baza!B:B,'ştat sayları'!C:C,baza!H:H,"Paşa Holding") -> 8 | J25: =COUNTIFS(baza!B:B,'ştat sayları'!C:C,baza!H:H,"Future lab") -> 0 | K25: =G25+H25+I25+J25 -> 9 | L25: 2 paşa holdinq boş ştat | M25: yeni sahə və keçid
A26: yeni struktur | B26: 0 | C26: Beynəlxalq hesabatlıq və MİS departamenti | D26: 13 | E26: - | F26: 13 | G26: =COUNTIFS(baza!B:B,'ştat sayları'!C:C,baza!H:H,"Bir Payment") -> 0 | H26: =COUNTIFS(baza!B:B,'ştat sayları'!C:C,baza!H:H,"BirMarket") -> 0 | I26: =COUNTIFS(baza!B:B,'ştat sayları'!C:C,baza!H:H,"Paşa Holding") -> 0 | J26: =COUNTIFS(baza!B:B,'ştat sayları'!C:C,baza!H:H,"Future lab") -> 0 | K26: =G26+H26+I26+J26 -> 0 | L26: dəqiqləşməli | M26: yeni sahə
A27: başqa sahənin parçalanması | B27: 0 | C27: FinTech arxitektura və İT idarəetmə prosesi | D27: 3 | E27: - | F27: 3 | G27: =COUNTIFS(baza!B:B,'ştat sayları'!C:C,baza!H:H,"Bir Payment") -> 0 | H27: =COUNTIFS(baza!B:B,'ştat sayları'!C:C,baza!H:H,"BirMarket") -> 0 | I27: =COUNTIFS(baza!B:B,'ştat sayları'!C:C,baza!H:H,"Paşa Holding") -> 0 | J27: =COUNTIFS(baza!B:B,'ştat sayları'!C:C,baza!H:H,"Future lab") -> 0 | K27: =G27+H27+I27+J27 -> 0 | L27: 1 asiman ştatı pmem dən,1 Fintech mühəndislik(texnoloji platformalar)(MF İD 11988), +1 Fintech müh(fintech platform)(MF İD = 11987 nin relokasiyası) | M27: yeni sahə
A28: başqa sahənin parçalanması | B28: 0 | C28: Ödəniş biznesinin arxitektura və İT idarəetmə prosesi | D28: 5 | E28: - | F28: 5 | G28: =COUNTIFS(baza!B:B,'ştat sayları'!C:C,baza!H:H,"Bir Payment") -> 0 | H28: =COUNTIFS(baza!B:B,'ştat sayları'!C:C,baza!H:H,"BirMarket") -> 0 | I28: =COUNTIFS(baza!B:B,'ştat sayları'!C:C,baza!H:H,"Paşa Holding") -> 0 | J28: =COUNTIFS(baza!B:B,'ştat sayları'!C:C,baza!H:H,"Future lab") -> 0 | K28: =G28+H28+I28+J28 -> 0 | L28: 2 arxitektura coe, +3 IT Governance Expert,Area Lead ,Architect ştat alındı | M28: yeni sahə
A29: Daxili audit departamenti | B29: 55 | C29: Daxili audit departamenti | D29: 55 | E29: - | F29: 55 | G29: =COUNTIFS(baza!B:B,'ştat sayları'!C:C,baza!H:H,"Bir Payment") -> 0 | H29: =COUNTIFS(baza!B:B,'ştat sayları'!C:C,baza!H:H,"BirMarket") -> 0 | I29: =COUNTIFS(baza!B:B,'ştat sayları'!C:C,baza!H:H,"Paşa Holding") -> 0 | J29: =COUNTIFS(baza!B:B,'ştat sayları'!C:C,baza!H:H,"Future lab") -> 0 | K29: =G29+H29+I29+J29 -> 0 | M29: struktur dəyişikliyi yoxdur
A30: Korporativ satışlar departamenti | B30: 30 | C30: Korporativ satışlar departamenti | D30: 29 | E30: - | F30: 29 | G30: =COUNTIFS(baza!B:B,'ştat sayları'!C:C,baza!H:H,"Bir Payment") -> 0 | H30: =COUNTIFS(baza!B:B,'ştat sayları'!C:C,baza!H:H,"BirMarket") -> 0 | I30: =COUNTIFS(baza!B:B,'ştat sayları'!C:C,baza!H:H,"Paşa Holding") -> 0 | J30: =COUNTIFS(baza!B:B,'ştat sayları'!C:C,baza!H:H,"Future lab") -> 0 | K30: =G30+H30+I30+J30 -> 0 | L30: 1 xkied | M30: struktur dəyişikliyi yoxdur
A31: Kredit risklərinin təhlili departamenti | B31: 133 | C31: Kredit risklərinin təhlili departamenti | D31: 133 | E31: - | F31: 133 | G31: =COUNTIFS(baza!B:B,'ştat sayları'!C:C,baza!H:H,"Bir Payment") -> 0 | H31: =COUNTIFS(baza!B:B,'ştat sayları'!C:C,baza!H:H,"BirMarket") -> 0 | I31: =COUNTIFS(baza!B:B,'ştat sayları'!C:C,baza!H:H,"Paşa Holding") -> 0 | J31: =COUNTIFS(baza!B:B,'ştat sayları'!C:C,baza!H:H,"Future lab") -> 0 | K31: =G31+H31+I31+J31 -> 0 | M31: struktur dəyişikliyi yoxdur
A32: Kreditlərin hüquqi təqibi departamenti | B32: 58 | C32: Kreditlərin hüquqi təqibi departamenti | D32: 58 | E32: - | F32: 58 | G32: =COUNTIFS(baza!B:B,'ştat sayları'!C:C,baza!H:H,"Bir Payment") -> 0 | H32: =COUNTIFS(baza!B:B,'ştat sayları'!C:C,baza!H:H,"BirMarket") -> 0 | I32: =COUNTIFS(baza!B:B,'ştat sayları'!C:C,baza!H:H,"Paşa Holding") -> 0 | J32: =COUNTIFS(baza!B:B,'ştat sayları'!C:C,baza!H:H,"Future lab") -> 0 | K32: =G32+H32+I32+J32 -> 0 | M32: struktur dəyişikliyi yoxdur
A33: Maliyyə menecmenti departamenti | B33: 33 | C33: Maliyyə menecmenti departamenti | D33: 28 | E33: - | F33: 28 | G33: =COUNTIFS(baza!B:B,'ştat sayları'!C:C,baza!H:H,"Bir Payment") -> 0 | H33: =COUNTIFS(baza!B:B,'ştat sayları'!C:C,baza!H:H,"BirMarket") -> 0 | I33: =COUNTIFS(baza!B:B,'ştat sayları'!C:C,baza!H:H,"Paşa Holding") -> 0 | J33: =COUNTIFS(baza!B:B,'ştat sayları'!C:C,baza!H:H,"Future lab") -> 0 | K33: =G33+H33+I33+J33 -> 0 | L33: 5 strategiya və layihələrin id ed | M33: struktur dəyişikliyi yoxdur
A34: Model risklərinin idarəedilməsi ekspert mərkəzi | B34: 12 | C34: Model risklərinin idarəedilməsi ekspert mərkəzi | D34: 12 | E34: - | F34: 12 | G34: =COUNTIFS(baza!B:B,'ştat sayları'!C:C,baza!H:H,"Bir Payment") -> 0 | H34: =COUNTIFS(baza!B:B,'ştat sayları'!C:C,baza!H:H,"BirMarket") -> 0 | I34: =COUNTIFS(baza!B:B,'ştat sayları'!C:C,baza!H:H,"Paşa Holding") -> 0 | J34: =COUNTIFS(baza!B:B,'ştat sayları'!C:C,baza!H:H,"Future lab") -> 0 | K34: =G34+H34+I34+J34 -> 0 | M34: struktur dəyişikliyi yoxdur
A35: İstedadların idarə edilməsi departamenti | B35: 72 | C35: İstedadların idarə edilməsi departamenti | D35: 23 | E35: - | F35: 23 | G35: =COUNTIFS(baza!B:B,'ştat sayları'!C:C,baza!H:H,"Bir Payment") -> 0 | H35: =COUNTIFS(baza!B:B,'ştat sayları'!C:C,baza!H:H,"BirMarket") -> 1 | I35: =COUNTIFS(baza!B:B,'ştat sayları'!C:C,baza!H:H,"Paşa Holding") -> 0 | J35: =COUNTIFS(baza!B:B,'ştat sayları'!C:C,baza!H:H,"Future lab") -> 0 | K35: =G35+H35+I35+J35 -> 1 | L35: 1 Daxili komm və korp sosial məs verildi, +1 birmarket, -48 təşkilati inkişaf və hr texn, -1 Təşkilati inkişaf və HR(xuraman həsənova), -1 Müjgan Rüstəmli ştatı(Təşkilati inkişaf və HR verildi) | M35: Keçidlər
A36: başqa sahənin parçalanması | B36: 0 | C36: Təşkilati inkişaf və HR texnologiyaları departamenti | D36: 83 | E36: - | F36: 83 | G36: =COUNTIFS(baza!B:B,'ştat sayları'!C:C,baza!H:H,"Bir Payment") -> 9 | H36: =COUNTIFS(baza!B:B,'ştat sayları'!C:C,baza!H:H,"BirMarket") -> 12 | I36: =COUNTIFS(baza!B:B,'ştat sayları'!C:C,baza!H:H,"Paşa Holding") -> 2 | J36: =COUNTIFS(baza!B:B,'ştat sayları'!C:C,baza!H:H,"Future lab") -> 1 | K36: =G36+H36+I36+J36 -> 24 | L36: 48 iied, 8 daxili komm, +1İstedadların idarə edilməsi dep, +1 Pashapaydan Zabeta ştatı, +1 İİEDdən(Müjgan Rüstəmli ştatı), | M36: Struktur dəyişiklik və keçidlər
A37: Hüquq departamenti | B37: 53.5 | C37: Hüquq departamenti | D37: 71.5 | E37: - | F37: 71.5 | G37: =COUNTIFS(baza!B:B,'ştat sayları'!C:C,baza!H:H,"Bir Payment") -> 7 | H37: =COUNTIFS(baza!B:B,'ştat sayları'!C:C,baza!H:H,"BirMarket") -> 8 | I37: =COUNTIFS(baza!B:B,'ştat sayları'!C:C,baza!H:H,"Paşa Holding") -> 0 | J37: =COUNTIFS(baza!B:B,'ştat sayları'!C:C,baza!H:H,"Future lab") -> 0 | K37: =G37+H37+I37+J37 -> 15 | L37: 2 birmarket, 1 pashapay ştat boş | M37: Keçidlər | N37: 10 birmarket, 8 pashapay ştatı verilib
A38: Kiçik və orta sahibkarlarla iş departamenti | B38: 94 | C38: Kiçik və orta sahibkarlarla iş departamenti | D38: 94 | E38: - | F38: 94 | G38: =COUNTIFS(baza!B:B,'ştat sayları'!C:C,baza!H:H,"Bir Payment") -> 0 | H38: =COUNTIFS(baza!B:B,'ştat sayları'!C:C,baza!H:H,"BirMarket") -> 0 | I38: =COUNTIFS(baza!B:B,'ştat sayları'!C:C,baza!H:H,"Paşa Holding") -> 0 | J38: =COUNTIFS(baza!B:B,'ştat sayları'!C:C,baza!H:H,"Future lab") -> 0 | K38: =G38+H38+I38+J38 -> 0 | M38: struktur dəyişikliyi yoxdur
A39: Kreditlərin ilkin təqibi departamenti | B39: 207 | C39: Kreditlərin ilkin təqibi departamenti | D39: 204 | E39: - | F39: 204 | G39: =COUNTIFS(baza!B:B,'ştat sayları'!C:C,baza!H:H,"Bir Payment") -> 0 | H39: =COUNTIFS(baza!B:B,'ştat sayları'!C:C,baza!H:H,"BirMarket") -> 0 | I39: =COUNTIFS(baza!B:B,'ştat sayları'!C:C,baza!H:H,"Paşa Holding") -> 0 | J39: =COUNTIFS(baza!B:B,'ştat sayları'!C:C,baza!H:H,"Future lab") -> 0 | K39: =G39+H39+I39+J39 -> 0 | L39: 2 Fintech müh(kredit portf nəzarət dep) verildi, -1 Maliyyə risk.id.olunması | M39: struktur dəyişikliyi yoxdur
A40: Prosessinq sahəsi | B40: 3 | C40: Prosessinq sahəsi | D40: 3 | E40: - | F40: 3 | G40: =COUNTIFS(baza!B:B,'ştat sayları'!C:C,baza!H:H,"Bir Payment") -> 0 | H40: =COUNTIFS(baza!B:B,'ştat sayları'!C:C,baza!H:H,"BirMarket") -> 0 | I40: =COUNTIFS(baza!B:B,'ştat sayları'!C:C,baza!H:H,"Paşa Holding") -> 0 | J40: =COUNTIFS(baza!B:B,'ştat sayları'!C:C,baza!H:H,"Future lab") -> 0 | K40: =G40+H40+I40+J40 -> 0 | M40: struktur dəyişikliyi yoxdur
...

Sheet əlavə ştat
A1: OPCO | F1: 85 | L1: Digər ştat məsələləri | M1: Keçid edən ştat | N1: Qeyd | O1: Əsas
A2: Hansı sahə | B2: Neçə ştat | C2: Tarix | D2: Protokol/ təsdiq | L2: Ekosistemin inkişafı və analitikası departamenti | M2: 2 | N2: holdinq
A3: Paymentsə verilən | B3: 23 | C3: 46239 | D3: OPCO N 22 | L3: Hüquq departamenti | M3: 3 | N3: 1 pashapay, 2 birmarket boş
A4: İnformasiya təhlükəsizliyi | B4: 17 | C4: 46157 | D4: OPCO N 38 | L4: İnformasiya təhlükəsizliyi departamenti | M4: 4 | N4: pashapay
A5: Mühəndislik və texnoloji platform, data və Aİ | B5: 7 | C5: 46177 | D5: OPCO N 15 | L5: İT infrastruktur departamenti | M5: 6 | N5: pashapay
A6: Birapp, Bir search | B6: 2 | C6: 46160 | D6: OPCO N14 | L6: Müştəri təcrübəsi ekspert mərkəzi | M6: 1 | N6: pashapaydan bura | O6: 07.07.2026 tamillla x ok
A7: Birinvest | B7: 1 | C7: 46156 | D7: OPCO N 13 | L7: Nağd pulların idarə edilməsi departamenti | M7: 2 | N7: pashapaydan bura | O7: 11.09.2026 tamilla x ok
A8: Cəmi | B8: 50 | L8: Ödəniş biznesinin mühəndislik ekspert mərkəzi | M8: 6 | N8: pashapaydan bura | O8: aylin maillər-pavel varapai,yuliya və.s
L9: Strategiya və layihələrin idarə edilməsi departamenti | M9: 3 | N9: 1 pashapay, 1 holdinq, 1 birmarket
L10: Təhlükəsizlik departamenti | M10: 1 | N10: Birmarket
L11: Təşkilati və qeyri-maliyyə risklərinin idarə edilməsi departamenti | M11: 4 | N11: pashapay
L12: Marketinq ekspert mərkəzi | M12: 1 | N12: əsaslandırılmalı
L13: Beynəlxalq hesabatlıq MİS | M13: 13 | N13: Maliyyədən silinməli idi
L14: Rəqəmsal dələduzluq | M14: 5
L16: Cəmi | M16: =SUM(M2:M14) -> 51

Sheet yekun ştat və vakant
A1: New | B1: Cəmi | C1: İşçi sayı | D1: müvəqqəti | E1: vakant | F1: Non agile, agile, filial
A2: Arxitektura ekspert mərkəzi | B2: 8 | C2: 7 | D2: 0 | E2: 1 | F2: Agile | I2: Agile | J2: =SUMIFS(E:E,F:F,"Agile") -> 198
A3: Dizayn ekspert mərkəzi | B3: 63 | C3: 57 | D3: 0 | E3: 6 | F3: Agile | I3: Non-Agile | J3: =SUMIFS(E:E,F:F,"Non-Agile") -> 236 | L3: =J3+J4+J2 -> 482
A4: İnzibati idarəetmə departamenti | B4: 162 | C4: 158 | D4: 2 | E4: 6 | F4: Non-Agile | I4: Filial | J4: =SUMIFS(E:E,F:F,"Filial") -> 48
A5: Komplayens departamenti | B5: 52 | C5: 54 | D5: 2 | E5: 0 | F5: Non-Agile
A6: Korporativ katiblik şöbəsi | B6: 37.5 | C6: 30 | D6: 0 | E6: 7.5 | F6: Non-Agile
A7: Biznes sahələrinin inkişafı və partnyor şəbəkəsi departamenti | B7: 99 | C7: 84 | D7: 0 | E7: 15 | F7: Non-Agile
A8: Müştəri təcrübəsi ekspert mərkəzi | B8: 25 | C8: 23 | D8: 0 | E8: 2 | F8: Agile
A9: Kredit portfelinə nəzarət departamenti | B9: 34 | C9: 31 | D9: 0 | E9: 3 | F9: Agile
A10: FinTech TechOps funksional sahəsi | B10: 16 | C10: 14 | D10: 0 | E10: 2 | F10: Agile
A11: Biznesə dəstək departamenti | B11: 116 | C11: 109 | D11: 0 | E11: 7 | F11: Non-Agile
A12: Məhsulların rəsmiləşdirilməsi sahəsi | B12: 5 | C12: 4 | D12: 0 | E12: 1 | F12: Agile
A13: Kart biznesi ekspert mərkəzi | B13: 12 | C13: 12 | D13: 0 | E13: 0 | F13: Agile
A14: Təhlükəsizlik departamenti | B14: 79 | C14: 74 | D14: 0 | E14: 5 | F14: Non-Agile
A15: İT proseslərinin idarə edilməsi funksional sahəsi | B15: 5 | C15: 4 | D15: 0 | E15: 1 | F15: Agile
A16: Rəqəmsal həllər sahəsi | B16: 6 | C16: 6 | D16: 0 | E16: 0 | F16: Agile
... A93: Data menecment ofisi | B93: 1 | C93: 1 | D93: 0 | E93: 0 | F93: Agile
B94: 6622 | C94: 6288 | D94: 148 | E94: 482

Sheet baza
A1: Personal kod | B1: Departament (Department) | C1: Şöbə (Section) | D1: Bölmə (Subsection) | E1: Vəzifə (Position) | F1: Aktiv, Passiv, HX, SM (Active, Passive,Social vacation) | G1: Kapital Banka işə qəbul olunduğu tarix (Hire date) | H1: keçid etdiyi şirkət | I1: Qeyd | J1: Non agile filial | N1: keçid etdiyi şirkət
A2: 16457 | B2: Müşahidə Şurası | C2: # | D2: # | E2: Müşahidə şurasının sədri (əvəzçilik qaydasında) | F2: A | G2: 45405 | J2: Non-Agile
A3: 10843 | B3: Müşahidə Şurası | C3: # | D3: # | E3: Müşahidə şurasının üzvü, Audit komitəsinin sədri (əvəzçilik qaydasında) | F3: A | G3: 41654 | J3: Non-Agile | N3: BirMarket
A4: 10925 | B4: Rəhbərlik | C4: # | D4: # | E4: İdarə Heyətinin sədri, Baş icraçı direktor | F4: A | G4: 42125 | J4: Non-Agile | N4: Bir Payment
A5: 10722 | B5: Rəhbərlik | C5: # | D5: # | E5: İdarə Heyəti sədrinin I müavini | F5: A | G5: 41736 | J5: Non-Agile | N5: Paşa Holding
A6: 10610 | B6: Rəhbərlik | C6: # | D6: # | E6: İdarə Heyəti sədrinin müavini, Baş Korporativ satış inzibatçısı | F6: A | G6: 41484 | J6: Non-Agile | N6: Future lab
A7: 18167 | B7: Rəhbərlik | C7: # | D7: # | E7: İdarə Heyəti sədrinin müavini | F7: A | G7: 46027 | J7: Non-Agile
A8: 10002 | B8: Rəhbərlik | C8: # | D8: # | E8: İdarə Heyəti sədrinin müavini | F8: A | G8: 37893 | J8: Non-Agile
A9: 10611 | B9: Rəhbərlik | C9: # | D9: # | E9: Baş komplayens inzibatçısı | F9: A | G9: 41484 | J9: Non-Agile
A10: 10963 | B10: Rəhbərlik | C10: # | D10: # | E10: Baş Risk inzibatçısı | F10: A | G10: 42219 | J10: Non-Agile
A11: 18369 | B11: Rəhbərlik | C11: # | D11: # | E11: Baş Maliyyə inzibatçısı | F11: A | G11: 46113 | J11: Non-Agile
A12: 10658 | B12: Rəhbərlik | C12: # | D12: # | E12: İdarə Heyəti sədrinin müşaviri | F12: A | G12: 41611 | J12: Non-Agile
A13: 18916 | B13: Rəhbərlik | C13: # | D13: # | E13: İdarə Heyəti sədrinin müşaviri | F13: A | G13: 46237 | J13: Non-Agile
A14: 18890 | B14: Rəhbərlik | C14: # | D14: # | E14: İdarə Heyəti sədrinin müşaviri | F14: A | G14: 46241 | H14: BirMarket | J14: Non-Agile
A15: 18188 | B15: Rəhbərlik | C15: # | D15: # | E15: İdarə Heyəti sədrinin müşaviri (əvəzçilik qaydasında) | F15: A | G15: 46034 | H15: BirMarket | J15: Non-Agile
A16: 15131 | B16: Rəhbərlik | C16: # | D16: # | E16: Müşavir (İdarə Heyətinin sədri/baş icraçı direktorun ekosistem üzrə) (əvəzçilik üzrə) | F16: A | G16: 44958 | J16: Non-Agile
A17: 11584 | B17: Rəhbərlik | C17: # | D17: # | E17: Ofis lideri | F17: A | G17: 42877 | J17: Agile
A18: 19018 | B18: Rəhbərlik | C18: # | D18: # | E18: Aparat rəhbəri | F18: A | G18: 46254 | H18: Bir Payment | J18: Agile
A19: 15541 | B19: İnformasiya texnologiyaları idarəsi | C19: # | D19: # | E19: Baş direktor | F19: A | G19: 45114 | J19: Agile
A20: 16327 | B20: Məhsul və marketinq idarəsi | C20: # | D20: # | E20: Baş direktor | F20: A | G20: 45344 | J20: Agile
A21: 18522 | B21: Data və Aİ idarəsi | C21: # | D21: # | E21: Baş direktor | F21: A | G21: 46143 | H21: Paşa Holding | J21: Agile
A22: 18523 | B22: Strategiya idarəsi | C22: # | D22: # | E22: Baş direktor | F22: A | G22: 46143 | H22: Paşa Holding | J22: Non-Agile
A23: 160032 | B23: Əməliyyatlar ofisi | C23: # | D23: # | E23: Ofis lideri | F23: A | G23: 42311 | J23: Non-Agile
A24: 10431 | B24: Ödəniş məhsulları ofisi | C24: # | D24: # | E24: Ofis lideri | F24: A | G24: 40253 | J24: Agile
A25: 13317 | B25: Data menecment ofisi | C25: # | D25: # | E25: Ofis lideri | F25: A | G25: 44382 | J25: Agile
A26: 10967 | B26: Ödəniş texnologiyaları ofisi | C26: # | D26: # | E26: Ofis lideri | F26: A | G26: 42222 | J26: Agile
A27: 10516 | B27: Maliyyə ofisi | C27: # | D27: # | E27: Ofis lideri | F27: A | G27: 41022 | J27: Non-Agile
A28: 13059 | B28: Maliyyə risklərinin idarə edilməsi ofisi | C28: # | D28: # | E28: Ofis lideri | F28: A | G28: 44228 | J28: Non-Agile
A29: 16326 | B29: İnformasiya texnologiyaları idarəsi | C29: # | D29: # | E29: Tribe tech lead | F29: A | G29: 45344 | J29: Agile
A30: 16075 | B30: Ödəniş biznesinin mühəndislik ekspert mərkəzi | C30: # | D30: # | E30: Tribe tech lead | F30: A | G30: 45278 | J30: Agile
A31: 18483 | B31: Ödəniş biznesinin mühəndislik ekspert mərkəzi | C31: softwate chapter | D31: # | E31: Tech lead | F31: A | G31: 46146 | J31: Agile
A32: 18815 | B32: Ödəniş biznesinin mühəndislik ekspert mərkəzi | C32: softwate chapter | D32: # | E32: Tech lead (0,5 ştat vahidi üzrə əvəzçilik qaydasında) | F32: A | G32: 46213 | H32: Bir Payment | J32: Agile
A33: 18182 | B33: Kart məhsulları sahəsi | C33: # | D33: # | E33: Tribe tech lead | F33: A | G33: 46035 | J33: Agile
A34: 11886 | B34: FinTech mühəndislik ekspert mərkəzi | C34: # | D34: # | E34: Tribe tech lead | F34: A | G34: 43242 | J34: Agile
A35: 17254 | B35: Ödəniş biznesinin mühəndislik ekspert mərkəzi | C35: # | D35: # | E35: Ekspert mərkəzinin lideri | F35: A | G35: 45691 | J35: Agile
A36: 16234 | B36: Ödəniş biznesinin TechOps funksional sahəsi | C36: # | D36: # | E36: Servis dayanıqlığı üzrə mühəndis | F36: A | G36: 45323 | J36: Agile
A37: 17485 | B37: BirApp texnologiyası sahəsi | C37: # | D37: # | E37: Tribe tech lead | F37: A | G37: 45762 | J37: Agile
A38: 11527 | B38: BirApp texnologiyası sahəsi | C38: Birbank Platform | D38: # | E38: Məhsul sahibi | F38: A | G38: 42797 | J38: Agile
A39: 11536 | B39: Ödəniş biznesinin mühəndislik ekspert mərkəzi | C39: # | D39: # | E39: Tribe tech lead | F39: A | G39: 42808 | J39: Agile
A40: 18202 | B40: Korporativ inkişaf və investor əlaqələri departamenti | C40: # | D40: # | E40: Menecer | F40: A | G40: 46055 | J40: Non-Agile
...

Sheet birmarket
A1: Unit | B1: Number of employee
A3: Commercial Block | B3: 1
A4: Electronics Vertical | B4: 10
A5: Beauty Vertical | B5: 6
A6: Home goods Vertical | B6: 8
A7: FMCG Vertical | B7: 8
A8: Seller Excellence Department | B8: 46
A9: Content Operations Division | B9: 37
A10: Seller Product tribe | B10: 5
A11: C-level | B11: 1
A12: Vacant HCs | B12: 7
A14: Supply Chain Block | B14: 1
A15: Routes planning&Delivery division | B15: 38
... A59: HSE Division | B59: 1

Sheet pashapay
A3: Struktur adı | B3: Staff | C3: Vacant | D3: Qeyd | E3: qeyd
A4: Audit komitəsi | B4: 3 | C4: 1
A5: Baş Komplayens inzibatçısı | B5: 1 | C5: 0
A6: Biznesin optimallaşdırılması şöbəsi | B6: 1 | C6: 0
A7: Daxili audit departamenti | B7: 2 | C7: 0
A8: Daxili nəzarət şöbəsi | B8: 3 | C8: 0
A9: Frauda qarşı mübarizə şöbəsi | B9: 10 | C9: 0
A10: Hesablaşmalar departamenti | B10: 11 | C10: 2
A11: Hüquq Şöbəsi | B11: 3 | C11: 1
A12: İnformasiya təhlükəsizliyi şöbəsi | B12: 3 | C12: 0
A13: İnkassasiya Şöbəsi | B13: 162 | C13: 26 | D13: 86 vakant yerdən 60 FTE-in relokasiyasına icazə verilmişdir. Bu vakantlar 34 FTE-in relokasiyası üçün istifadə olunacaqdır. İnkassasiya şöbəsində 26 vakant qalacaq.
A14: İstedadların idarə edilməsi departamenti | B14: 4 | C14: 2
A15: İT şöbəsi | B15: 11 | C15: 0
A16: Kross-sərhəd və satış sahəsi | B16: 10 | C16: 3
A17: Maliyyə menecmenti departamenti | B17: 13 | C17: =1+3 -> 4 | D17: Hazırda 1 vakant var, lakin 3 FTE də bura relokasiya olunacaqdır. 34 FTE excelinin içində bu barədə məlumat var.
A18: Məhsullar Şöbəsi | B18: 26 | C18: 5
A19: Mühasibatlıq departamenti | B19: 2 | C19: 0
A20: Müştəri mükəmməlliyi departamenti | B20: 117 | C20: =10+3 -> 13 | D20: 3 FTE relokasiya olunacaq bura, 34 FTE-in içində qeyd olunub.
A21: none structure | B21: 38
A22: Təhlükəsizlik departamenti | B22: 8 | C22: 0
A23: Terminal biznesinə dəstək departamenti | B23: 141 | C23: 0
A24: Terminal və ATM şəbəkəsinin idarə edilməsi departamenti | B24: 28 | C24: 0
A25: Grand Total | B25: 597 | C25: =SUM(C4:C24) -> 57
