Workbook

Sheet Summary
B1: Summary by Department
B4: Summary by Department (Horizontal) | C4: 31 August 2026 (actual) | G4: 31 Dec 2027 (plan) | H4: Change in Active
B5: Department | C5: Active | D5: Passive | E5: Vacant | F5: Total | G5: Active | H5: Absolute | I5: %
B6: Management | C6: =SUMIFS('Summary by Division'!$D$6:$D$297,'Summary by Division'!$B$6:$B$297,$B6,'Summary by Division'!$A$6:$A$297,"<>"&$B$38,'Summary by Division'!$A$6:$A$297,"<>"&$B$73) -> 0 | D6: =SUMIFS('Summary by Division'!$E$6:$E$297,'Summary by Division'!$B$6:$B$297,$B6,'Summary by Division'!$A$6:$A$297,"<>"&$B$38,'Summary by Division'!$A$6:$A$297,"<>"&$B$73) -> 0 | E6: =SUMIFS('Summary by Division'!$F$6:$F$297,'Summary by Division'!$B$6:$B$297,$B6,'Summary by Division'!$A$6:$A$297,"<>"&$B$38,'Summary by Division'!$A$6:$A$297,"<>"&$B$73) -> 0 | F6: =SUMIFS('Summary by Division'!$G$6:$G$297,'Summary by Division'!$B$6:$B$297,$B6,'Summary by Division'!$A$6:$A$297,"<>"&$B$38,'Summary by Division'!$A$6:$A$297,"<>"&$B$73) -> 0 | G6: =SUMIFS('Summary by Division'!$H$6:$H$297,'Summary by Division'!$B$6:$B$297,$B6,'Summary by Division'!$A$6:$A$297,"<>"&$B$38,'Summary by Division'!$A$6:$A$297,"<>"&$B$73) -> 0 | H6: =G6-C6 -> 0 | I6: =IF(C6=0,0,H6/C6) -> 0
B7: Corporate Secretary Division | C7: =SUMIFS('Summary by Division'!$D$6:$D$297,'Summary by Division'!$B$6:$B$297,$B7,'Summary by Division'!$A$6:$A$297,"<>"&$B$38,'Summary by Division'!$A$6:$A$297,"<>"&$B$73) -> 30 | D7: =SUMIFS('Summary by Division'!$E$6:$E$297,'Summary by Division'!$B$6:$B$297,$B7,'Summary by Division'!$A$6:$A$297,"<>"&$B$38,'Summary by Division'!$A$6:$A$297,"<>"&$B$73) -> 2 | E7: =SUMIFS('Summary by Division'!$F$6:$F$297,'Summary by Division'!$B$6:$B$297,$B7,'Summary by Division'!$A$6:$A$297,"<>"&$B$38,'Summary by Division'!$A$6:$A$297,"<>"&$B$73) -> 7.5 | F7: =SUMIFS('Summary by Division'!$G$6:$G$297,'Summary by Division'!$B$6:$B$297,$B7,'Summary by Division'!$A$6:$A$297,"<>"&$B$38,'Summary by Division'!$A$6:$A$297,"<>"&$B$73) -> 39.5 | G7: =SUMIFS('Summary by Division'!$H$6:$H$297,'Summary by Division'!$B$6:$B$297,$B7,'Summary by Division'!$A$6:$A$297,"<>"&$B$38,'Summary by Division'!$A$6:$A$297,"<>"&$B$73) -> 37.5 | H7: =G7-C7 -> 7.5 | I7: =IF(C7=0,0,H7/C7) -> 0.25
B8: Agile and Product Center of Expertise | C8: =SUMIFS('Summary by Division'!$D$6:$D$297,'Summary by Division'!$B$6:$B$297,$B8,'Summary by Division'!$A$6:$A$297,"<>"&$B$38,'Summary by Division'!$A$6:$A$297,"<>"&$B$73) -> 19 | D8: =SUMIFS('Summary by Division'!$E$6:$E$297,'Summary by Division'!$B$6:$B$297,$B8,'Summary by Division'!$A$6:$A$297,"<>"&$B$38,'Summary by Division'!$A$6:$A$297,"<>"&$B$73) -> 2 | E8: =SUMIFS('Summary by Division'!$F$6:$F$297,'Summary by Division'!$B$6:$B$297,$B8,'Summary by Division'!$A$6:$A$297,"<>"&$B$38,'Summary by Division'!$A$6:$A$297,"<>"&$B$73) -> 4 | F8: =SUMIFS('Summary by Division'!$G$6:$G$297,'Summary by Division'!$B$6:$B$297,$B8,'Summary by Division'!$A$6:$A$297,"<>"&$B$38,'Summary by Division'!$A$6:$A$297,"<>"&$B$73) -> 25 | G8: =SUMIFS('Summary by Division'!$H$6:$H$297,'Summary by Division'!$B$6:$B$297,$B8,'Summary by Division'!$A$6:$A$297,"<>"&$B$38,'Summary by Division'!$A$6:$A$297,"<>"&$B$73) -> 26 | H8: =G8-C8 -> 7 | I8: =IF(C8=0,0,H8/C8) -> 0.36842105
B9: AI Governance Center of Expertise | C9: =SUMIFS('Summary by Division'!$D$6:$D$297,'Summary by Division'!$B$6:$B$297,$B9,'Summary by Division'!$A$6:$A$297,"<>"&$B$38,'Summary by Division'!$A$6:$A$297,"<>"&$B$73) -> 16 | D9: =SUMIFS('Summary by Division'!$E$6:$E$297,'Summary by Division'!$B$6:$B$297,$B9,'Summary by Division'!$A$6:$A$297,"<>"&$B$38,'Summary by Division'!$A$6:$A$297,"<>"&$B$73) -> 0 | E9: =SUMIFS('Summary by Division'!$F$6:$F$297,'Summary by Division'!$B$6:$B$297,$B9,'Summary by Division'!$A$6:$A$297,"<>"&$B$38,'Summary by Division'!$A$6:$A$297,"<>"&$B$73) -> 27 | F9: =SUMIFS('Summary by Division'!$G$6:$G$297,'Summary by Division'!$B$6:$B$297,$B9,'Summary by Division'!$A$6:$A$297,"<>"&$B$38,'Summary by Division'!$A$6:$A$297,"<>"&$B$73) -> 43 | G9: =SUMIFS('Summary by Division'!$H$6:$H$297,'Summary by Division'!$B$6:$B$297,$B9,'Summary by Division'!$A$6:$A$297,"<>"&$B$38,'Summary by Division'!$A$6:$A$297,"<>"&$B$73) -> 48 | H9: =G9-C9 -> 32 | I9: =IF(C9=0,0,H9/C9) -> 2
B10: Architecture Center of Expertise | C10: =SUMIFS('Summary by Division'!$D$6:$D$297,'Summary by Division'!$B$6:$B$297,$B10,'Summary by Division'!$A$6:$A$297,"<>"&$B$38,'Summary by Division'!$A$6:$A$297,"<>"&$B$73) -> 7 | D10: =SUMIFS('Summary by Division'!$E$6:$E$297,'Summary by Division'!$B$6:$B$297,$B10,'Summary by Division'!$A$6:$A$297,"<>"&$B$38,'Summary by Division'!$A$6:$A$297,"<>"&$B$73) -> 0 | E10: =SUMIFS('Summary by Division'!$F$6:$F$297,'Summary by Division'!$B$6:$B$297,$B10,'Summary by Division'!$A$6:$A$297,"<>"&$B$38,'Summary by Division'!$A$6:$A$297,"<>"&$B$73) -> 2 | F10: =SUMIFS('Summary by Division'!$G$6:$G$297,'Summary by Division'!$B$6:$B$297,$B10,'Summary by Division'!$A$6:$A$297,"<>"&$B$38,'Summary by Division'!$A$6:$A$297,"<>"&$B$73) -> 9 | G10: =SUMIFS('Summary by Division'!$H$6:$H$297,'Summary by Division'!$B$6:$B$297,$B10,'Summary by Division'!$A$6:$A$297,"<>"&$B$38,'Summary by Division'!$A$6:$A$297,"<>"&$B$73) -> 9 | H10: =G10-C10 -> 2 | I10: =IF(C10=0,0,H10/C10) -> 0.28571429
B11: International Reporting and MIS Department | C11: =SUMIFS('Summary by Division'!$D$6:$D$297,'Summary by Division'!$B$6:$B$297,$B11,'Summary by Division'!$A$6:$A$297,"<>"&$B$38,'Summary by Division'!$A$6:$A$297,"<>"&$B$73) -> 11 | D11: =SUMIFS('Summary by Division'!$E$6:$E$297,'Summary by Division'!$B$6:$B$297,$B11,'Summary by Division'!$A$6:$A$297,"<>"&$B$38,'Summary by Division'!$A$6:$A$297,"<>"&$B$73) -> 3 | E11: =SUMIFS('Summary by Division'!$F$6:$F$297,'Summary by Division'!$B$6:$B$297,$B11,'Summary by Division'!$A$6:$A$297,"<>"&$B$38,'Summary by Division'!$A$6:$A$297,"<>"&$B$73) -> 8 | F11: =SUMIFS('Summary by Division'!$G$6:$G$297,'Summary by Division'!$B$6:$B$297,$B11,'Summary by Division'!$A$6:$A$297,"<>"&$B$38,'Summary by Division'!$A$6:$A$297,"<>"&$B$73) -> 22 | G11: =SUMIFS('Summary by Division'!$H$6:$H$297,'Summary by Division'!$B$6:$B$297,$B11,'Summary by Division'!$A$6:$A$297,"<>"&$B$38,'Summary by Division'!$A$6:$A$297,"<>"&$B$73) -> 22 | H11: =G11-C11 -> 11 | I11: =IF(C11=0,0,H11/C11) -> 1
B12: BirApp Area | C12: =SUMIFS('Summary by Division'!$D$6:$D$297,'Summary by Division'!$B$6:$B$297,$B12,'Summary by Division'!$A$6:$A$297,"<>"&$B$38,'Summary by Division'!$A$6:$A$297,"<>"&$B$73) -> 5 | D12: =SUMIFS('Summary by Division'!$E$6:$E$297,'Summary by Division'!$B$6:$B$297,$B12,'Summary by Division'!$A$6:$A$297,"<>"&$B$38,'Summary by Division'!$A$6:$A$297,"<>"&$B$73) -> 0 | E12: =SUMIFS('Summary by Division'!$F$6:$F$297,'Summary by Division'!$B$6:$B$297,$B12,'Summary by Division'!$A$6:$A$297,"<>"&$B$38,'Summary by Division'!$A$6:$A$297,"<>"&$B$73) -> 0 | F12: =SUMIFS('Summary by Division'!$G$6:$G$297,'Summary by Division'!$B$6:$B$297,$B12,'Summary by Division'!$A$6:$A$297,"<>"&$B$38,'Summary by Division'!$A$6:$A$297,"<>"&$B$73) -> 5 | G12: =SUMIFS('Summary by Division'!$H$6:$H$297,'Summary by Division'!$B$6:$B$297,$B12,'Summary by Division'!$A$6:$A$297,"<>"&$B$38,'Summary by Division'!$A$6:$A$297,"<>"&$B$73) -> 4 | H12: =G12-C12 -> -1 | I12: =IF(C12=0,0,H12/C12) -> -0.2
B13: BirApp Technology Area | C13: =SUMIFS('Summary by Division'!$D$6:$D$297,'Summary by Division'!$B$6:$B$297,$B13,'Summary by Division'!$A$6:$A$297,"<>"&$B$38,'Summary by Division'!$A$6:$A$297,"<>"&$B$73) -> 2 | D13: =SUMIFS('Summary by Division'!$E$6:$E$297,'Summary by Division'!$B$6:$B$297,$B13,'Summary by Division'!$A$6:$A$297,"<>"&$B$38,'Summary by Division'!$A$6:$A$297,"<>"&$B$73) -> 0 | E13: =SUMIFS('Summary by Division'!$F$6:$F$297,'Summary by Division'!$B$6:$B$297,$B13,'Summary by Division'!$A$6:$A$297,"<>"&$B$38,'Summary by Division'!$A$6:$A$297,"<>"&$B$73) -> 1 | F13: =SUMIFS('Summary by Division'!$G$6:$G$297,'Summary by Division'!$B$6:$B$297,$B13,'Summary by Division'!$A$6:$A$297,"<>"&$B$38,'Summary by Division'!$A$6:$A$297,"<>"&$B$73) -> 3 | G13: =SUMIFS('Summary by Division'!$H$6:$H$297,'Summary by Division'!$B$6:$B$297,$B13,'Summary by Division'!$A$6:$A$297,"<>"&$B$38,'Summary by Division'!$A$6:$A$297,"<>"&$B$73) -> 3 | H13: =G13-C13 -> 1 | I13: =IF(C13=0,0,H13/C13) -> 0.5
B14: Data Governance Center of Expertise | C14: =SUMIFS('Summary by Division'!$D$6:$D$297,'Summary by Division'!$B$6:$B$297,$B14,'Summary by Division'!$A$6:$A$297,"<>"&$B$38,'Summary by Division'!$A$6:$A$297,"<>"&$B$73) -> 20 | D14: =SUMIFS('Summary by Division'!$E$6:$E$297,'Summary by Division'!$B$6:$B$297,$B14,'Summary by Division'!$A$6:$A$297,"<>"&$B$38,'Summary by Division'!$A$6:$A$297,"<>"&$B$73) -> 0 | E14: =SUMIFS('Summary by Division'!$F$6:$F$297,'Summary by Division'!$B$6:$B$297,$B14,'Summary by Division'!$A$6:$A$297,"<>"&$B$38,'Summary by Division'!$A$6:$A$297,"<>"&$B$73) -> 10 | F14: =SUMIFS('Summary by Division'!$G$6:$G$297,'Summary by Division'!$B$6:$B$297,$B14,'Summary by Division'!$A$6:$A$297,"<>"&$B$38,'Summary by Division'!$A$6:$A$297,"<>"&$B$73) -> 30 | G14: =SUMIFS('Summary by Division'!$H$6:$H$297,'Summary by Division'!$B$6:$B$297,$B14,'Summary by Division'!$A$6:$A$297,"<>"&$B$38,'Summary by Division'!$A$6:$A$297,"<>"&$B$73) -> 30 | H14: =G14-C14 -> 10 | I14: =IF(C14=0,0,H14/C14) -> 0.5
B15: Data mühəndisliyi və texnologiyaları ekspert mərkəzi | C15: =SUMIFS('Summary by Division'!$D$6:$D$297,'Summary by Division'!$B$6:$B$297,$B15,'Summary by Division'!$A$6:$A$297,"<>"&$B$38,'Summary by Division'!$A$6:$A$297,"<>"&$B$73) -> 23 | D15: =SUMIFS('Summary by Division'!$E$6:$E$297,'Summary by Division'!$B$6:$B$297,$B15,'Summary by Division'!$A$6:$A$297,"<>"&$B$38,'Summary by Division'!$A$6:$A$297,"<>"&$B$73) -> 1 | E15: =SUMIFS('Summary by Division'!$F$6:$F$297,'Summary by Division'!$B$6:$B$297,$B15,'Summary by Division'!$A$6:$A$297,"<>"&$B$38,'Summary by Division'!$A$6:$A$297,"<>"&$B$73) -> 4 | F15: =SUMIFS('Summary by Division'!$G$6:$G$297,'Summary by Division'!$B$6:$B$297,$B15,'Summary by Division'!$A$6:$A$297,"<>"&$B$38,'Summary by Division'!$A$6:$A$297,"<>"&$B$73) -> 28 | G15: =SUMIFS('Summary by Division'!$H$6:$H$297,'Summary by Division'!$B$6:$B$297,$B15,'Summary by Division'!$A$6:$A$297,"<>"&$B$38,'Summary by Division'!$A$6:$A$297,"<>"&$B$73) -> 26 | H15: =G15-C15 -> 3 | I15: =IF(C15=0,0,H15/C15) -> 0.13043478
B16: Data və Analitika departamenti(Marketplace) | C16: =SUMIFS('Summary by Division'!$D$6:$D$297,'Summary by Division'!$B$6:$B$297,$B16,'Summary by Division'!$A$6:$A$297,"<>"&$B$38,'Summary by Division'!$A$6:$A$297,"<>"&$B$73) -> 4 | D16: =SUMIFS('Summary by Division'!$E$6:$E$297,'Summary by Division'!$B$6:$B$297,$B16,'Summary by Division'!$A$6:$A$297,"<>"&$B$38,'Summary by Division'!$A$6:$A$297,"<>"&$B$73) -> 0 | E16: =SUMIFS('Summary by Division'!$F$6:$F$297,'Summary by Division'!$B$6:$B$297,$B16,'Summary by Division'!$A$6:$A$297,"<>"&$B$38,'Summary by Division'!$A$6:$A$297,"<>"&$B$73) -> 0 | F16: =SUMIFS('Summary by Division'!$G$6:$G$297,'Summary by Division'!$B$6:$B$297,$B16,'Summary by Division'!$A$6:$A$297,"<>"&$B$38,'Summary by Division'!$A$6:$A$297,"<>"&$B$73) -> 4 | G16: =SUMIFS('Summary by Division'!$H$6:$H$297,'Summary by Division'!$B$6:$B$297,$B16,'Summary by Division'!$A$6:$A$297,"<>"&$B$38,'Summary by Division'!$A$6:$A$297,"<>"&$B$73) -> 4 | H16: =G16-C16 -> 0 | I16: =IF(C16=0,0,H16/C16) -> 0
B17: Design Center of Expertise | C17: =SUMIFS('Summary by Division'!$D$6:$D$297,'Summary by Division'!$B$6:$B$297,$B17,'Summary by Division'!$A$6:$A$297,"<>"&$B$38,'Summary by Division'!$A$6:$A$297,"<>"&$B$73) -> 53 | D17: =SUMIFS('Summary by Division'!$E$6:$E$297,'Summary by Division'!$B$6:$B$297,$B17,'Summary by Division'!$A$6:$A$297,"<>"&$B$38,'Summary by Division'!$A$6:$A$297,"<>"&$B$73) -> 1 | E17: =SUMIFS('Summary by Division'!$F$6:$F$297,'Summary by Division'!$B$6:$B$297,$B17,'Summary by Division'!$A$6:$A$297,"<>"&$B$38,'Summary by Division'!$A$6:$A$297,"<>"&$B$73) -> 9 | F17: =SUMIFS('Summary by Division'!$G$6:$G$297,'Summary by Division'!$B$6:$B$297,$B17,'Summary by Division'!$A$6:$A$297,"<>"&$B$38,'Summary by Division'!$A$6:$A$297,"<>"&$B$73) -> 63 | G17: =SUMIFS('Summary by Division'!$H$6:$H$297,'Summary by Division'!$B$6:$B$297,$B17,'Summary by Division'!$A$6:$A$297,"<>"&$B$38,'Summary by Division'!$A$6:$A$297,"<>"&$B$73) -> 63 | H17: =G17-C17 -> 10 | I17: =IF(C17=0,0,H17/C17) -> 0.18867925
... B34: Organizational and Non-Financial Risk Management Department | C34: =SUMIFS('Summary by Division'!$D$6:$D$297,'Summary by Division'!$B$6:$B$297,$B34,'Summary by Division'!$A$6:$A$297,"<>"&$B$38,'Summary by Division'!$A$6:$A$297,"<>"&$B$73) -> 58 | D34: =SUMIFS('Summary by Division'!$E$6:$E$297,'Summary by Division'!$B$6:$B$297,$B34,'Summary by Division'!$A$6:$A$297,"<>"&$B$38,'Summary by Division'!$A$6:$A$297,"<>"&$B$73) -> 1 | E34: =SUMIFS('Summary by Division'!$F$6:$F$297,'Summary by Division'!$B$6:$B$297,$B34,'Summary by Division'!$A$6:$A$297,"<>"&$B$38,'Summary by Division'!$A$6:$A$297,"<>"&$B$73) -> 5 | F34: =SUMIFS('Summary by Division'!$G$6:$G$297,'Summary by Division'!$B$6:$B$297,$B34,'Summary by Division'!$A$6:$A$297,"<>"&$B$38,'Summary by Division'!$A$6:$A$297,"<>"&$B$73) -> 64 | G34: =SUMIFS('Summary by Division'!$H$6:$H$297,'Summary by Division'!$B$6:$B$297,$B34,'Summary by Division'!$A$6:$A$297,"<>"&$B$38,'Summary by Division'!$A$6:$A$297,"<>"&$B$73) -> 70 | H34: =G34-C34 -> 12 | I34: =IF(C34=0,0,H34/C34) -> 0.20689655
B35: Total | C35: =SUM(C6:C34) -> 1169 | D35: =SUM(D6:D34) -> 34 | E35: =SUM(E6:E34) -> 181 | F35: =SUM(F6:F34) -> 1384 | G35: =SUM(G6:G34) -> 1384 | H35: =SUM(H6:H34) -> 215 | I35: =IF(C35=0,0,H35/C35) -> 0.18391788
C36: =C35-SUMIFS('Summary by Division'!$D$6:$D$261,'Summary by Division'!$A$6:$A$261,"<>"&$B$38) -> 0 | D36: =D35-SUMIFS('Summary by Division'!$E$6:$E$261,'Summary by Division'!$A$6:$A$261,"<>"&$B$38) -> 0 | E36: =E35-SUMIFS('Summary by Division'!$F$6:$F$261,'Summary by Division'!$A$6:$A$261,"<>"&$B$38) -> 0 | F36: =F35-SUMIFS('Summary by Division'!$G$6:$G$261,'Summary by Division'!$A$6:$A$261,"<>"&$B$38) -> 0 | G36: =G35-SUMIFS('Summary by Division'!$H$6:$H$261,'Summary by Division'!$A$6:$A$261,"<>"&$B$38) -> 0
B38: Fintech | C38: 31 August 2026 (actual) | G38: 31 Dec 2027 (plan) | H38: Change in Active
B39: Department | C39: Active | D39: Passive | E39: Vacant | F39: Total | G39: Active | H39: Absolute | I39: %
B40: Management | C40: =SUMIFS('Summary by Division'!$D$6:$D$297,'Summary by Division'!$B$6:$B$297,$B40,'Summary by Division'!$A$6:$A$297,$B$38) -> 43 | D40: =SUMIFS('Summary by Division'!$E$6:$E$297,'Summary by Division'!$B$6:$B$297,$B40,'Summary by Division'!$A$6:$A$297,$B$38) -> 0 | E40: =SUMIFS('Summary by Division'!$F$6:$F$297,'Summary by Division'!$B$6:$B$297,$B40,'Summary by Division'!$A$6:$A$297,$B$38) -> 0 | F40: =SUMIFS('Summary by Division'!$G$6:$G$297,'Summary by Division'!$B$6:$B$297,$B40,'Summary by Division'!$A$6:$A$297,$B$38) -> 43 | G40: =SUMIFS('Summary by Division'!$H$6:$H$297,'Summary by Division'!$B$6:$B$297,$B40,'Summary by Division'!$A$6:$A$297,$B$38) -> 43 | H40: =G40-C40 -> 0 | I40: =IF(C40=0,0,H40/C40) -> 0
B41: VİP müştərilərlə iş şöbəsi | C41: =SUMIFS('Summary by Division'!$D$6:$D$297,'Summary by Division'!$B$6:$B$297,$B41,'Summary by Division'!$A$6:$A$297,$B$38) -> 8 | D41: =SUMIFS('Summary by Division'!$E$6:$E$297,'Summary by Division'!$B$6:$B$297,$B41,'Summary by Division'!$A$6:$A$297,$B$38) -> 0 | E41: =SUMIFS('Summary by Division'!$F$6:$F$297,'Summary by Division'!$B$6:$B$297,$B41,'Summary by Division'!$A$6:$A$297,$B$38) -> 0 | F41: =SUMIFS('Summary by Division'!$G$6:$G$297,'Summary by Division'!$B$6:$B$297,$B41,'Summary by Division'!$A$6:$A$297,$B$38) -> 8 | G41: =SUMIFS('Summary by Division'!$H$6:$H$297,'Summary by Division'!$B$6:$B$297,$B41,'Summary by Division'!$A$6:$A$297,$B$38) -> 4 | H41: =G41-C41 -> -4 | I41: =IF(C41=0,0,H41/C41) -> -0.5
B42: Birbank biznes sahəsi | C42: =SUMIFS('Summary by Division'!$D$6:$D$297,'Summary by Division'!$B$6:$B$297,$B42,'Summary by Division'!$A$6:$A$297,$B$38) -> 7 | D42: =SUMIFS('Summary by Division'!$E$6:$E$297,'Summary by Division'!$B$6:$B$297,$B42,'Summary by Division'!$A$6:$A$297,$B$38) -> 0 | E42: =SUMIFS('Summary by Division'!$F$6:$F$297,'Summary by Division'!$B$6:$B$297,$B42,'Summary by Division'!$A$6:$A$297,$B$38) -> 2 | F42: =SUMIFS('Summary by Division'!$G$6:$G$297,'Summary by Division'!$B$6:$B$297,$B42,'Summary by Division'!$A$6:$A$297,$B$38) -> 9 | G42: =SUMIFS('Summary by Division'!$H$6:$H$297,'Summary by Division'!$B$6:$B$297,$B42,'Summary by Division'!$A$6:$A$297,$B$38) -> 9 | H42: =G42-C42 -> 2 | I42: =IF(C42=0,0,H42/C42) -> 0.28571429
B43: Biznesə dəstək departamenti | C43: =SUMIFS('Summary by Division'!$D$6:$D$297,'Summary by Division'!$B$6:$B$297,$B43,'Summary by Division'!$A$6:$A$297,$B$38) -> 99 | D43: =SUMIFS('Summary by Division'!$E$6:$E$297,'Summary by Division'!$B$6:$B$297,$B43,'Summary by Division'!$A$6:$A$297,$B$38) -> 0 | E43: =SUMIFS('Summary by Division'!$F$6:$F$297,'Summary by Division'!$B$6:$B$297,$B43,'Summary by Division'!$A$6:$A$297,$B$38) -> 17 | F43: =SUMIFS('Summary by Division'!$G$6:$G$297,'Summary by Division'!$B$6:$B$297,$B43,'Summary by Division'!$A$6:$A$297,$B$38) -> 116 | G43: =SUMIFS('Summary by Division'!$H$6:$H$297,'Summary by Division'!$B$6:$B$297,$B43,'Summary by Division'!$A$6:$A$297,$B$38) -> 116 | H43: =G43-C43 -> 17 | I43: =IF(C43=0,0,H43/C43) -> 0.17171717
B44: Daxili audit departamenti | C44: =SUMIFS('Summary by Division'!$D$6:$D$297,'Summary by Division'!$B$6:$B$297,$B44,'Summary by Division'!$A$6:$A$297,$B$38) -> 39 | D44: =SUMIFS('Summary by Division'!$E$6:$E$297,'Summary by Division'!$B$6:$B$297,$B44,'Summary by Division'!$A$6:$A$297,$B$38) -> 0 | E44: =SUMIFS('Summary by Division'!$F$6:$F$297,'Summary by Division'!$B$6:$B$297,$B44,'Summary by Division'!$A$6:$A$297,$B$38) -> 11 | F44: =SUMIFS('Summary by Division'!$G$6:$G$297,'Summary by Division'!$B$6:$B$297,$B44,'Summary by Division'!$A$6:$A$297,$B$38) -> 50 | G44: =SUMIFS('Summary by Division'!$H$6:$H$297,'Summary by Division'!$B$6:$B$297,$B44,'Summary by Division'!$A$6:$A$297,$B$38) -> 50 | H44: =G44-C44 -> 11 | I44: =IF(C44=0,0,H44/C44) -> 0.28205128
B45: FinTech Agile funksional sahəsi | C45: =SUMIFS('Summary by Division'!$D$6:$D$297,'Summary by Division'!$B$6:$B$297,$B45,'Summary by Division'!$A$6:$A$297,$B$38) -> 3 | D45: =SUMIFS('Summary by Division'!$E$6:$E$297,'Summary by Division'!$B$6:$B$297,$B45,'Summary by Division'!$A$6:$A$297,$B$38) -> 0 | E45: =SUMIFS('Summary by Division'!$F$6:$F$297,'Summary by Division'!$B$6:$B$297,$B45,'Summary by Division'!$A$6:$A$297,$B$38) -> 4 | F45: =SUMIFS('Summary by Division'!$G$6:$G$297,'Summary by Division'!$B$6:$B$297,$B45,'Summary by Division'!$A$6:$A$297,$B$38) -> 7 | G45: =SUMIFS('Summary by Division'!$H$6:$H$297,'Summary by Division'!$B$6:$B$297,$B45,'Summary by Division'!$A$6:$A$297,$B$38) -> 7 | H45: =G45-C45 -> 4 | I45: =IF(C45=0,0,H45/C45) -> 1.3333333
B46: Fintech Analitika və Aİ ekspert mərkəzi | C46: =SUMIFS('Summary by Division'!$D$6:$D$297,'Summary by Division'!$B$6:$B$297,$B46,'Summary by Division'!$A$6:$A$297,$B$38) -> 30 | D46: =SUMIFS('Summary by Division'!$E$6:$E$297,'Summary by Division'!$B$6:$B$297,$B46,'Summary by Division'!$A$6:$A$297,$B$38) -> 0 | E46: =SUMIFS('Summary by Division'!$F$6:$F$297,'Summary by Division'!$B$6:$B$297,$B46,'Summary by Division'!$A$6:$A$297,$B$38) -> 0 | F46: =SUMIFS('Summary by Division'!$G$6:$G$297,'Summary by Division'!$B$6:$B$297,$B46,'Summary by Division'!$A$6:$A$297,$B$38) -> 30 | G46: =SUMIFS('Summary by Division'!$H$6:$H$297,'Summary by Division'!$B$6:$B$297,$B46,'Summary by Division'!$A$6:$A$297,$B$38) -> 30 | H46: =G46-C46 -> 0 | I46: =IF(C46=0,0,H46/C46) -> 0
B47: FinTech arxitektura və İT idarəetmə prosesi | C47: =SUMIFS('Summary by Division'!$D$6:$D$297,'Summary by Division'!$B$6:$B$297,$B47,'Summary by Division'!$A$6:$A$297,$B$38) -> 3 | D47: =SUMIFS('Summary by Division'!$E$6:$E$297,'Summary by Division'!$B$6:$B$297,$B47,'Summary by Division'!$A$6:$A$297,$B$38) -> 0 | E47: =SUMIFS('Summary by Division'!$F$6:$F$297,'Summary by Division'!$B$6:$B$297,$B47,'Summary by Division'!$A$6:$A$297,$B$38) -> 2 | F47: =SUMIFS('Summary by Division'!$G$6:$G$297,'Summary by Division'!$B$6:$B$297,$B47,'Summary by Division'!$A$6:$A$297,$B$38) -> 5 | G47: =SUMIFS('Summary by Division'!$H$6:$H$297,'Summary by Division'!$B$6:$B$297,$B47,'Summary by Division'!$A$6:$A$297,$B$38) -> 5 | H47: =G47-C47 -> 2 | I47: =IF(C47=0,0,H47/C47) -> 0.66666667
B48: FinTech mühəndislik ekspert mərkəzi | C48: =SUMIFS('Summary by Division'!$D$6:$D$297,'Summary by Division'!$B$6:$B$297,$B48,'Summary by Division'!$A$6:$A$297,$B$38) -> 19 | D48: =SUMIFS('Summary by Division'!$E$6:$E$297,'Summary by Division'!$B$6:$B$297,$B48,'Summary by Division'!$A$6:$A$297,$B$38) -> 0 | E48: =SUMIFS('Summary by Division'!$F$6:$F$297,'Summary by Division'!$B$6:$B$297,$B48,'Summary by Division'!$A$6:$A$297,$B$38) -> 0 | F48: =SUMIFS('Summary by Division'!$G$6:$G$297,'Summary by Division'!$B$6:$B$297,$B48,'Summary by Division'!$A$6:$A$297,$B$38) -> 19 | G48: =SUMIFS('Summary by Division'!$H$6:$H$297,'Summary by Division'!$B$6:$B$297,$B48,'Summary by Division'!$A$6:$A$297,$B$38) -> 19 | H48: =G48-C48 -> 0 | I48: =IF(C48=0,0,H48/C48) -> 0
B49: FinTech platformalar sahəsi | C49: =SUMIFS('Summary by Division'!$D$6:$D$297,'Summary by Division'!$B$6:$B$297,$B49,'Summary by Division'!$A$6:$A$297,$B$38) -> 2 | D49: =SUMIFS('Summary by Division'!$E$6:$E$297,'Summary by Division'!$B$6:$B$297,$B49,'Summary by Division'!$A$6:$A$297,$B$38) -> 0 | E49: =SUMIFS('Summary by Division'!$F$6:$F$297,'Summary by Division'!$B$6:$B$297,$B49,'Summary by Division'!$A$6:$A$297,$B$38) -> 0 | F49: =SUMIFS('Summary by Division'!$G$6:$G$297,'Summary by Division'!$B$6:$B$297,$B49,'Summary by Division'!$A$6:$A$297,$B$38) -> 2 | G49: =SUMIFS('Summary by Division'!$H$6:$H$297,'Summary by Division'!$B$6:$B$297,$B49,'Summary by Division'!$A$6:$A$297,$B$38) -> 2 | H49: =G49-C49 -> 0 | I49: =IF(C49=0,0,H49/C49) -> 0
B50: FinTech TechOps funksional sahəsi | C50: =SUMIFS('Summary by Division'!$D$6:$D$297,'Summary by Division'!$B$6:$B$297,$B50,'Summary by Division'!$A$6:$A$297,$B$38) -> 14 | D50: =SUMIFS('Summary by Division'!$E$6:$E$297,'Summary by Division'!$B$6:$B$297,$B50,'Summary by Division'!$A$6:$A$297,$B$38) -> 0 | E50: =SUMIFS('Summary by Division'!$F$6:$F$297,'Summary by Division'!$B$6:$B$297,$B50,'Summary by Division'!$A$6:$A$297,$B$38) -> 5 | F50: =SUMIFS('Summary by Division'!$G$6:$G$297,'Summary by Division'!$B$6:$B$297,$B50,'Summary by Division'!$A$6:$A$297,$B$38) -> 19 | G50: =SUMIFS('Summary by Division'!$H$6:$H$297,'Summary by Division'!$B$6:$B$297,$B50,'Summary by Division'!$A$6:$A$297,$B$38) -> 19 | H50: =G50-C50 -> 5 | I50: =IF(C50=0,0,H50/C50) -> 0.35714286
B51: İstedadların idarə edilməsi departamenti | C51: =SUMIFS('Summary by Division'!$D$6:$D$297,'Summary by Division'!$B$6:$B$297,$B51,'Summary by Division'!$A$6:$A$297,$B$38) -> 21 | D51: =SUMIFS('Summary by Division'!$E$6:$E$297,'Summary by Division'!$B$6:$B$297,$B51,'Summary by Division'!$A$6:$A$297,$B$38) -> 0 | E51: =SUMIFS('Summary by Division'!$F$6:$F$297,'Summary by Division'!$B$6:$B$297,$B51,'Summary by Division'!$A$6:$A$297,$B$38) -> 0 | F51: =SUMIFS('Summary by Division'!$G$6:$G$297,'Summary by Division'!$B$6:$B$297,$B51,'Summary by Division'!$A$6:$A$297,$B$38) -> 21 | G51: =SUMIFS('Summary by Division'!$H$6:$H$297,'Summary by Division'!$B$6:$B$297,$B51,'Summary by Division'!$A$6:$A$297,$B$38) -> 21 | H51: =G51-C51 -> 0 | I51: =IF(C51=0,0,H51/C51) -> 0
... B69: Branches | C69: =SUMIFS('Summary by Division'!$D$6:$D$297,'Summary by Division'!$B$6:$B$297,$B69,'Summary by Division'!$A$6:$A$297,$B$38) -> 1860 | D69: =SUMIFS('Summary by Division'!$E$6:$E$297,'Summary by Division'!$B$6:$B$297,$B69,'Summary by Division'!$A$6:$A$297,$B$38) -> 0 | E69: =SUMIFS('Summary by Division'!$F$6:$F$297,'Summary by Division'!$B$6:$B$297,$B69,'Summary by Division'!$A$6:$A$297,$B$38) -> 6 | F69: =SUMIFS('Summary by Division'!$G$6:$G$297,'Summary by Division'!$B$6:$B$297,$B69,'Summary by Division'!$A$6:$A$297,$B$38) -> 1866 | G69: =SUMIFS('Summary by Division'!$H$6:$H$297,'Summary by Division'!$B$6:$B$297,$B69,'Summary by Division'!$A$6:$A$297,$B$38) -> 1860 | H69: =G69-C69 -> 0 | I69: =IF(C69=0,0,H69/C69) -> 0
B70: Fintech total | C70: =SUM(C40:C69) -> 3431 | D70: =SUM(D40:D69) -> 0 | E70: =SUM(E40:E69) -> 158 | F70: =SUM(F40:F69) -> 3589 | G70: =SUM(G40:G69) -> 3559 | H70: =SUM(H40:H69) -> 128 | I70: =IF(C70=0,0,H70/C70) -> 0.037306908
C71: =C70-SUMIFS('Summary by Division'!$D$6:$D$261,'Summary by Division'!$A$6:$A$261,$B$38) -> 0 | D71: =D70-SUMIFS('Summary by Division'!$E$6:$E$261,'Summary by Division'!$A$6:$A$261,$B$38) -> 0 | E71: =E70-SUMIFS('Summary by Division'!$F$6:$F$261,'Summary by Division'!$A$6:$A$261,$B$38) -> 0 | F71: =F70-SUMIFS('Summary by Division'!$G$6:$G$261,'Summary by Division'!$A$6:$A$261,$B$38) -> 0 | G71: =G70-SUMIFS('Summary by Division'!$H$6:$H$261,'Summary by Division'!$A$6:$A$261,$B$38) -> 0
B73: Payment | C73: =C38 -> 31 August 2026 (actual) | G73: =G38 -> 31 Dec 2027 (plan) | H73: =H38 -> Change in Active
B74: Department | C74: =C39 -> Active | D74: =D39 -> Passive | E74: =E39 -> Vacant | F74: =F39 -> Total | G74: =G39 -> Active | H74: =H39 -> Absolute | I74: =I39 -> %
B75: ='Summary by Division'!B262 -> Management | C75: =SUMIFS('Summary by Division'!$D$6:$D$297,'Summary by Division'!$B$6:$B$297,$B75,'Summary by Division'!$A$6:$A$297,$B$73) -> 11 | D75: =SUMIFS('Summary by Division'!$E$6:$E$297,'Summary by Division'!$B$6:$B$297,$B75,'Summary by Division'!$A$6:$A$297,$B$73) -> 0 | E75: =SUMIFS('Summary by Division'!$F$6:$F$297,'Summary by Division'!$B$6:$B$297,$B75,'Summary by Division'!$A$6:$A$297,$B$73) -> 0 | F75: =SUMIFS('Summary by Division'!$G$6:$G$297,'Summary by Division'!$B$6:$B$297,$B75,'Summary by Division'!$A$6:$A$297,$B$73) -> 11 | G75: =SUMIFS('Summary by Division'!$H$6:$H$297,'Summary by Division'!$B$6:$B$297,$B75,'Summary by Division'!$A$6:$A$297,$B$73) -> 11 | H75: =G75-C75 -> 0 | I75: =IF(C75=0,0,H75/C75) -> 0
B76: ='Summary by Division'!B263 -> Birbonus sahəsi | C76: =SUMIFS('Summary by Division'!$D$6:$D$297,'Summary by Division'!$B$6:$B$297,$B76,'Summary by Division'!$A$6:$A$297,$B$73) -> 4 | D76: =SUMIFS('Summary by Division'!$E$6:$E$297,'Summary by Division'!$B$6:$B$297,$B76,'Summary by Division'!$A$6:$A$297,$B$73) -> 0 | E76: =SUMIFS('Summary by Division'!$F$6:$F$297,'Summary by Division'!$B$6:$B$297,$B76,'Summary by Division'!$A$6:$A$297,$B$73) -> 0 | F76: =SUMIFS('Summary by Division'!$G$6:$G$297,'Summary by Division'!$B$6:$B$297,$B76,'Summary by Division'!$A$6:$A$297,$B$73) -> 4 | G76: =SUMIFS('Summary by Division'!$H$6:$H$297,'Summary by Division'!$B$6:$B$297,$B76,'Summary by Division'!$A$6:$A$297,$B$73) -> 4 | H76: =G76-C76 -> 0 | I76: =IF(C76=0,0,H76/C76) -> 0
B77: ='Summary by Division'!B264 -> Biznes sahələrinin inkişafı və partnyor şəbəkəsi departamenti | C77: =SUMIFS('Summary by Division'!$D$6:$D$297,'Summary by Division'!$B$6:$B$297,$B77,'Summary by Division'!$A$6:$A$297,$B$73) -> 82 | D77: =SUMIFS('Summary by Division'!$E$6:$E$297,'Summary by Division'!$B$6:$B$297,$B77,'Summary by Division'!$A$6:$A$297,$B$73) -> 0 | E77: =SUMIFS('Summary by Division'!$F$6:$F$297,'Summary by Division'!$B$6:$B$297,$B77,'Summary by Division'!$A$6:$A$297,$B$73) -> 0 | F77: =SUMIFS('Summary by Division'!$G$6:$G$297,'Summary by Division'!$B$6:$B$297,$B77,'Summary by Division'!$A$6:$A$297,$B$73) -> 82 | G77: =SUMIFS('Summary by Division'!$H$6:$H$297,'Summary by Division'!$B$6:$B$297,$B77,'Summary by Division'!$A$6:$A$297,$B$73) -> 89 | H77: =G77-C77 -> 7 | I77: =IF(C77=0,0,H77/C77) -> 0.085365854
...

Sheet Summary by Division
A1: Summary by Division
D4: 31 August 2026 (actual) | H4: 31 December 2027 (plan) | I4: Change in Active
B5: Department | C5: Division | D5: Active | E5: Passive | F5: Vacant | G5: Total | H5: Active | I5: Absolute | J5: % | L5: Qeydlər
A6: Horizontal | B6: ='2027'!C4 -> Management | C6: ='2027'!D4 -> C-level, Director, Deputy Director | D6: ='2027'!F4 -> 0 | E6: ='2027'!G4 -> 0 | F6: ='2027'!H4 -> 0 | G6: =SUM(D6:F6) -> 0 | H6: ='2027'!V4 -> 0 | I6: =H6-D6 -> 0 | J6: =IF(D6=0,0,I6/D6) -> 0
A7: Horizontal | B7: ='2027'!C5 -> Corporate Secretary Division | C7: ='2027'!D5 -> # | D7: ='2027'!F5 -> 1 | E7: ='2027'!G5 -> 0 | F7: ='2027'!H5 -> 0 | G7: =SUM(D7:F7) -> 1 | H7: ='2027'!V5 -> 1 | I7: =H7-D7 -> 0 | J7: =IF(D7=0,0,I7/D7) -> 0 | L7: Əlavə 7.5 vakant yer nəzərdə tutulub.
A8: Horizontal | B8: ='2027'!C6 -> Corporate Secretary Division | C8: ='2027'!D6 -> Corporate Secretary Division | D8: ='2027'!F6 -> 29 | E8: ='2027'!G6 -> 2 | F8: ='2027'!H6 -> 7.5 | G8: =SUM(D8:F8) -> 38.5 | H8: ='2027'!V6 -> 36.5 | I8: =H8-D8 -> 7.5 | J8: =IF(D8=0,0,I8/D8) -> 0.25862069
A9: Horizontal | B9: ='2027'!C7 -> Agile and Product Center of Expertise | C9: ='2027'!D7 -> Agile and product development chapter | D9: ='2027'!F7 -> 3 | E9: ='2027'!G7 -> 0 | F9: ='2027'!H7 -> 1 | G9: =SUM(D9:F9) -> 4 | H9: ='2027'!V7 -> 4 | I9: =H9-D9 -> 1 | J9: =IF(D9=0,0,I9/D9) -> 0.33333333 | L9: Əlavə 4 vakant yer nəzərdə tutulub.
A10: Horizontal | B10: ='2027'!C8 -> Agile and Product Center of Expertise | C10: ='2027'!D8 -> Fintech chapter | D10: ='2027'!F8 -> 4 | E10: ='2027'!G8 -> 1 | F10: ='2027'!H8 -> 2 | G10: =SUM(D10:F10) -> 7 | H10: ='2027'!V8 -> 7 | I10: =H10-D10 -> 3 | J10: =IF(D10=0,0,I10/D10) -> 0.75
A11: Horizontal | B11: ='2027'!C9 -> Agile and Product Center of Expertise | C11: ='2027'!D9 -> Payment Chapter | D11: ='2027'!F9 -> 12 | E11: ='2027'!G9 -> 1 | F11: ='2027'!H9 -> 1 | G11: =SUM(D11:F11) -> 14 | H11: ='2027'!V9 -> 15 | I11: =H11-D11 -> 3 | J11: =IF(D11=0,0,I11/D11) -> 0.25
A12: Horizontal | B12: ='2027'!C11 -> AI Governance Center of Expertise | C12: ='2027'!D11 -> # | D12: ='2027'!F11 -> 1 | E12: ='2027'!G11 -> 0 | F12: ='2027'!H11 -> 0 | G12: =SUM(D12:F12) -> 1 | H12: ='2027'!V11 -> 0 | I12: =H12-D12 -> -1 | J12: =IF(D12=0,0,I12/D12) -> -1 | L12: Əlavə 27 vakant yer nəzərdə tutulub. HR tərəfindən təqdim olunan faylda sadəcə bir vakant və 3 müvəqqəti nəzərə alınıb.
A13: Horizontal | B13: ='2027'!C10 -> AI Governance Center of Expertise | C13: ='2027'!D10 -> Ecosystem Analytics | D13: ='2027'!F10 -> 13 | E13: ='2027'!G10 -> 0 | F13: ='2027'!H10 -> 16 | G13: =SUM(D13:F13) -> 29 | H13: ='2027'!V10 -> 29 | I13: =H13-D13 -> 16 | J13: =IF(D13=0,0,I13/D13) -> 1.2307692
A14: Horizontal | B14: ='2027'!C12 -> AI Governance Center of Expertise | C14: ='2027'!D12 -> AI Engineering | D14: ='2027'!F12 -> 1 | E14: ='2027'!G12 -> 0 | F14: ='2027'!H12 -> 8 | G14: =SUM(D14:F14) -> 9 | H14: ='2027'!V12 -> 15 | I14: =H14-D14 -> 14 | J14: =IF(D14=0,0,I14/D14) -> 14
A15: Horizontal | B15: ='2027'!C13 -> AI Governance Center of Expertise | C15: ='2027'!D13 -> AI Governance | D15: ='2027'!F13 -> 0 | E15: ='2027'!G13 -> 0 | F15: ='2027'!H13 -> 2 | G15: =SUM(D15:F15) -> 2 | H15: ='2027'!V13 -> 2 | I15: =H15-D15 -> 2 | J15: =IF(D15=0,0,I15/D15) -> 0
A16: Horizontal | B16: ='2027'!C14 -> AI Governance Center of Expertise | C16: ='2027'!D14 -> AI Platforms | D16: ='2027'!F14 -> 1 | E16: ='2027'!G14 -> 0 | F16: ='2027'!H14 -> 1 | G16: =SUM(D16:F16) -> 2 | H16: ='2027'!V14 -> 2 | I16: =H16-D16 -> 1 | J16: =IF(D16=0,0,I16/D16) -> 1
A17: Horizontal | B17: ='2027'!C15 -> Architecture Center of Expertise | C17: ='2027'!D15 -> # | D17: ='2027'!F15 -> 1 | E17: ='2027'!G15 -> 0 | F17: ='2027'!H15 -> 0 | G17: =SUM(D17:F17) -> 1 | H17: ='2027'!V15 -> 1 | I17: =H17-D17 -> 0 | J17: =IF(D17=0,0,I17/D17) -> 0 | L17: Əlavə 2 vakant yer nəzərdə tutulub.
A18: Horizontal | B18: ='2027'!C16 -> Architecture Center of Expertise | C18: ='2027'!D16 -> Architecture Center of Expertise | D18: ='2027'!F16 -> 6 | E18: ='2027'!G16 -> 0 | F18: ='2027'!H16 -> 2 | G18: =SUM(D18:F18) -> 8 | H18: ='2027'!V16 -> 8 | I18: =H18-D18 -> 2 | J18: =IF(D18=0,0,I18/D18) -> 0.33333333
A19: Horizontal | B19: ='2027'!C17 -> International Reporting and MIS Department | C19: ='2027'!D17 -> # | D19: ='2027'!F17 -> 1 | E19: ='2027'!G17 -> 0 | F19: ='2027'!H17 -> 0 | G19: =SUM(D19:F19) -> 1 | H19: ='2027'!U17 -> 1 | I19: =H19-D19 -> 0 | J19: =IF(D19=0,0,I19/D19) -> 0 | L19: Əlavə 8 vakant yer nəzərdə tutulub.
A20: Horizontal | B20: ='2027'!C18 -> International Reporting and MIS Department | C20: ='2027'!D18 -> MIS Reporting | D20: ='2027'!F18 -> 4 | E20: ='2027'!G18 -> 1 | F20: ='2027'!H18 -> 0 | G20: =SUM(D20:F20) -> 5 | H20: ='2027'!U18 -> 5 | I20: =H20-D20 -> 1 | J20: =IF(D20=0,0,I20/D20) -> 0.25
A21: Horizontal | B21: ='2027'!C19 -> International Reporting and MIS Department | C21: ='2027'!D19 -> IFRS Reporting | D21: ='2027'!F19 -> 2 | E21: ='2027'!G19 -> 2 | F21: ='2027'!H19 -> 4 | G21: =SUM(D21:F21) -> 8 | H21: ='2027'!U19 -> 9 | I21: =H21-D21 -> 7 | J21: =IF(D21=0,0,I21/D21) -> 3.5
A22: Horizontal | B22: ='2027'!C20 -> International Reporting and MIS Department | C22: ='2027'!D20 -> Modelling, Valuation and Consolidated Reporting | D22: ='2027'!F20 -> 4 | E22: ='2027'!G20 -> 0 | F22: ='2027'!H20 -> 4 | G22: =SUM(D22:F22) -> 8 | H22: ='2027'!U20 -> 7 | I22: =H22-D22 -> 3 | J22: =IF(D22=0,0,I22/D22) -> 0.75
A23: Horizontal | B23: ='2027'!C21 -> BirApp Area | C23: ='2027'!D21 -> # | D23: ='2027'!F21 -> 1 | E23: ='2027'!G21 -> 0 | F23: ='2027'!H21 -> 0 | G23: =SUM(D23:F23) -> 1 | H23: ='2027'!V21 -> 1 | I23: =H23-D23 -> 0 | J23: =IF(D23=0,0,I23/D23) -> 0 | K23: =IF('2027'!A21="","",'2027'!A21) | L23: Vakant yer nəzərdə tutulmayıb. HR tərəfindən təqdim olunan faylda 6 əməkdaş və bir vakant gosterir.
A24: Horizontal | B24: ='2027'!C22 -> BirApp Area | C24: ='2027'!D22 -> Bir Enabler | D24: ='2027'!F22 -> 1 | E24: ='2027'!G22 -> 0 | F24: ='2027'!H22 -> 0 | G24: =SUM(D24:F24) -> 1 | H24: ='2027'!V22 -> 1 | I24: =H24-D24 -> 0 | J24: =IF(D24=0,0,I24/D24) -> 0
A25: Horizontal | B25: ='2027'!C23 -> BirApp Area | C25: ='2027'!D23 -> Birbank Mainpage | D25: ='2027'!F23 -> 1 | E25: ='2027'!G23 -> 0 | F25: ='2027'!H23 -> 0 | G25: =SUM(D25:F25) -> 1 | H25: ='2027'!V23 -> 1 | I25: =H25-D25 -> 0 | J25: =IF(D25=0,0,I25/D25) -> 0
A26: Horizontal | B26: ='2027'!C24 -> BirApp Area | C26: ='2027'!D24 -> Travel | D26: ='2027'!F24 -> 1 | E26: ='2027'!G24 -> 0 | F26: ='2027'!H24 -> 0 | G26: =SUM(D26:F26) -> 1 | H26: ='2027'!V24 -> 0 | I26: =H26-D26 -> -1 | J26: =IF(D26=0,0,I26/D26) -> -1
A27: Horizontal | B27: ='2027'!C25 -> BirApp Area | C27: ='2027'!D25 -> Bir Search | D27: ='2027'!F25 -> 1 | E27: ='2027'!G25 -> 0 | F27: ='2027'!H25 -> 0 | G27: =SUM(D27:F27) -> 1 | H27: ='2027'!V25 -> 1 | I27: =H27-D27 -> 0 | J27: =IF(D27=0,0,I27/D27) -> 0
A28: Horizontal | B28: ='2027'!C26 -> BirApp Technology Area | C28: ='2027'!D26 -> # | D28: ='2027'!F26 -> 1 | E28: ='2027'!G26 -> 0 | F28: ='2027'!H26 -> 0 | G28: =SUM(D28:F28) -> 1 | H28: ='2027'!V26 -> 1 | I28: =H28-D28 -> 0 | J28: =IF(D28=0,0,I28/D28) -> 0 | L28: Əlavə 1 vakant yer nəzərdə tutulub.
A29: Horizontal | B29: ='2027'!C27 -> BirApp Technology Area | C29: ='2027'!D27 -> Birbank Platform | D29: ='2027'!F27 -> 1 | E29: ='2027'!G27 -> 0 | F29: ='2027'!H27 -> 1 | G29: =SUM(D29:F29) -> 2 | H29: ='2027'!V27 -> 2 | I29: =H29-D29 -> 1 | J29: =IF(D29=0,0,I29/D29) -> 1
A30: Horizontal | B30: ='2027'!C28 -> BirApp Technology Area | C30: ='2027'!D28 -> Birbank SRE | D30: ='2027'!F28 -> 0 | E30: ='2027'!G28 -> 0 | F30: ='2027'!H28 -> 0 | G30: =SUM(D30:F30) -> 0 | H30: ='2027'!V28 -> 0 | I30: =H30-D30 -> 0 | J30: =IF(D30=0,0,I30/D30) -> 0
A31: Horizontal | B31: ='2027'!C29 -> Data Governance Center of Expertise | C31: ='2027'!D29 -> # | D31: ='2027'!F29 -> 1 | E31: ='2027'!G29 -> 0 | F31: ='2027'!H29 -> 0 | G31: =SUM(D31:F31) -> 1 | H31: ='2027'!V29 -> 1 | I31: =H31-D31 -> 0 | J31: =IF(D31=0,0,I31/D31) -> 0 | K31: =IF('2027'!A29="","",'2027'!A29) | L31: Əlavə 8 vakant yer nəzərdə tutulub. Lakin HR-ın təqdim etdiyi sənəddə vakant qeyd olunmayıb.
A32: Horizontal | B32: ='2027'!C30 -> Data Governance Center of Expertise | C32: ='2027'!D30 -> Data Process Management | D32: ='2027'!F30 -> 3 | E32: ='2027'!G30 -> 0 | F32: ='2027'!H30 -> 2 | G32: =SUM(D32:F32) -> 5 | H32: ='2027'!V30 -> 5 | I32: =H32-D32 -> 2 | J32: =IF(D32=0,0,I32/D32) -> 0.66666667 | K32: =IF('2027'!A30="","",'2027'!A30)
A33: Horizontal | B33: ='2027'!C31 -> Data Governance Center of Expertise | C33: ='2027'!D31 -> Data Quality | D33: ='2027'!F31 -> 6 | E33: ='2027'!G31 -> 0 | F33: ='2027'!H31 -> 2 | G33: =SUM(D33:F33) -> 8 | H33: ='2027'!V31 -> 8 | I33: =H33-D33 -> 2 | J33: =IF(D33=0,0,I33/D33) -> 0.33333333 | K33: =IF('2027'!A31="","",'2027'!A31)
A34: Horizontal | B34: ='2027'!C32 -> Data Governance Center of Expertise | C34: ='2027'!D32 -> Data Steward | D34: ='2027'!F32 -> 10 | E34: ='2027'!G32 -> 0 | F34: ='2027'!H32 -> 6 | G34: =SUM(D34:F34) -> 16 | H34: ='2027'!V32 -> 16 | I34: =H34-D34 -> 6 | J34: =IF(D34=0,0,I34/D34) -> 0.6 | K34: =IF('2027'!A32="","",'2027'!A32)
A35: Horizontal | B35: ='2027'!C33 -> Data mühəndisliyi və texnologiyaları ekspert mərkəzi | C35: ='2027'!D33 -> # | D35: ='2027'!F33 -> 1 | E35: ='2027'!G33 -> 0 | F35: ='2027'!H33 -> 0 | G35: =SUM(D35:F35) -> 1 | H35: ='2027'!V33 -> 1 | I35: =H35-D35 -> 0 | J35: =IF(D35=0,0,I35/D35) -> 0 | L35: Əlavə 4 vakant yer nəzərdə tutulub.
A36: Horizontal | B36: ='2027'!C34 -> Data mühəndisliyi və texnologiyaları ekspert mərkəzi | C36: ='2027'!D34 -> Data engineering 1 | D36: ='2027'!F34 -> 6 | E36: ='2027'!G34 -> 0 | F36: ='2027'!H34 -> 1 | G36: =SUM(D36:F36) -> 7 | H36: ='2027'!V34 -> 7 | I36: =H36-D36 -> 1 | J36: =IF(D36=0,0,I36/D36) -> 0.16666667
A37: Horizontal | B37: ='2027'!C35 -> Data mühəndisliyi və texnologiyaları ekspert mərkəzi | C37: ='2027'!D35 -> Data engineering 2 | D37: ='2027'!F35 -> 6 | E37: ='2027'!G35 -> 1 | F37: ='2027'!H35 -> 2 | G37: =SUM(D37:F37) -> 9 | H37: ='2027'!V35 -> 7 | I37: =H37-D37 -> 1 | J37: =IF(D37=0,0,I37/D37) -> 0.16666667
A38: Horizontal | B38: ='2027'!C36 -> Data mühəndisliyi və texnologiyaları ekspert mərkəzi | C38: ='2027'!D36 -> Data engineering 3 | D38: ='2027'!F36 -> 5 | E38: ='2027'!G36 -> 0 | F38: ='2027'!H36 -> 1 | G38: =SUM(D38:F38) -> 6 | H38: ='2027'!V36 -> 6 | I38: =H38-D38 -> 1 | J38: =IF(D38=0,0,I38/D38) -> 0.2
A39: Horizontal | B39: ='2027'!C37 -> Data mühəndisliyi və texnologiyaları ekspert mərkəzi | C39: ='2027'!D37 -> Data engineering 4 | D39: ='2027'!F37 -> 5 | E39: ='2027'!G37 -> 0 | F39: ='2027'!H37 -> 0 | G39: =SUM(D39:F39) -> 5 | H39: ='2027'!V37 -> 5 | I39: =H39-D39 -> 0 | J39: =IF(D39=0,0,I39/D39) -> 0
A40: Horizontal | B40: ='2027'!C38 -> Data və Analitika departamenti(Marketplace) | C40: ='2027'!D38 -> Data Engineering | D40: ='2027'!F38 -> 4 | E40: ='2027'!G38 -> 0 | F40: ='2027'!H38 -> 0 | G40: =SUM(D40:F40) -> 4 | H40: ='2027'!V38 -> 4 | I40: =H40-D40 -> 0 | J40: =IF(D40=0,0,I40/D40) -> 0 | L40: Vakant yer nəzərdə tutulmayıb.
A41: Horizontal | B41: ='2027'!C39 -> Design Center of Expertise | C41: ='2027'!D39 -> # | D41: ='2027'!F39 -> 4 | E41: ='2027'!G39 -> 0 | F41: ='2027'!H39 -> 4 | G41: =SUM(D41:F41) -> 8 | H41: ='2027'!V39 -> 8 | I41: =H41-D41 -> 4 | J41: =IF(D41=0,0,I41/D41) -> 1 | L41: Əlavə 9 vakant yer nəzərdə tutulub.
A42: Horizontal | B42: ='2027'!C40 -> Design Center of Expertise | C42: ='2027'!D40 -> Product Designer 1 | D42: ='2027'!F40 -> 9 | E42: ='2027'!G40 -> 1 | F42: ='2027'!H40 -> 0 | G42: =SUM(D42:F42) -> 10 | H42: ='2027'!V40 -> 10 | I42: =H42-D42 -> 1 | J42: =IF(D42=0,0,I42/D42) -> 0.11111111
...

Sheet 2027
C1: 2027 Headcount Plan – Source Data (by Department and Division)
F2: 31/08/2026 | I2: 31/12/2026 | K2: Number of Employees
A3: Additional notes | B3: Horizontal/Vertical | C3: Departament | D3: Division | E3: Out-seconded FTEs | F3: Active current employee | G3: Passive current employees | H3: Number of vacant positions | I3: 2026 YE (active current employee) | J3: Number of vacant positions | K3: January | L3: February | M3: March | N3: April | O3: May | P3: June | Q3: July | R3: August | S3: September | T3: October | U3: November | V3: December
B4: Horizontal | C4: Management | D4: C-level, Director, Deputy Director | E4: 0 | F4: 0 | G4: 0 | H4: 0 | I4: 0 | J4: 0 | K4: 0 | L4: 0 | M4: 0 | N4: 0 | O4: 0 | P4: 0 | Q4: 0 | R4: 0 | S4: 0 | T4: 0 | U4: 0 | V4: 0
B5: Horizontal | C5: Corporate Secretary Division | D5: # | E5: 0 | F5: 1 | G5: 0 | H5: 0 | I5: 1 | J5: 0 | K5: 1 | L5: 1 | M5: 1 | N5: 1 | O5: 1 | P5: 1 | Q5: 1 | R5: 1 | S5: 1 | T5: 1 | U5: 1 | V5: 1
B6: Horizontal | C6: Corporate Secretary Division | D6: Corporate Secretary Division | E6: 0 | F6: 29 | G6: 2 | H6: 7.5 | I6: 31 | J6: 5.5 | K6: 31 | L6: 31 | M6: 31 | N6: 31 | O6: 31 | P6: 31 | Q6: 31 | R6: 31 | S6: 31 | T6: 31 | U6: 31 | V6: =31+5.5 -> 36.5
B7: Horizontal | C7: Agile and Product Center of Expertise | D7: Agile and product development chapter | E7: 0 | F7: 3 | G7: 0 | H7: 1 | I7: 3 | J7: 1 | K7: 4 | L7: 4 | M7: 4 | N7: 4 | O7: 4 | P7: 4 | Q7: 4 | R7: 4 | S7: 4 | T7: 3 | U7: 3 | V7: 4
B8: Horizontal | C8: Agile and Product Center of Expertise | D8: Fintech chapter | E8: 0 | F8: 4 | G8: 1 | H8: 2 | I8: 7 | J8: 0 | K8: 7 | L8: 7 | M8: 7 | N8: 7 | O8: 7 | P8: 7 | Q8: 7 | R8: 7 | S8: 7 | T8: 7 | U8: 7 | V8: 7
B9: Horizontal | C9: Agile and Product Center of Expertise | D9: Payment Chapter | E9: 0 | F9: 12 | G9: 1 | H9: 1 | I9: 14 | J9: 1 | K9: 14 | L9: 14 | M9: 14 | N9: 14 | O9: 14 | P9: 14 | Q9: 14 | R9: 14 | S9: 14 | T9: 14 | U9: 14 | V9: 15
B10: Horizontal | C10: AI Governance Center of Expertise | D10: Ecosystem Analytics | E10: 0 | F10: 13 | G10: 0 | H10: 16 | I10: 16 | J10: 13 | K10: 13 | L10: 14 | M10: 18 | N10: 22 | O10: 24 | P10: 26 | Q10: 28 | R10: 29 | S10: 29 | T10: 29 | U10: 29 | V10: 29
B11: Horizontal | C11: AI Governance Center of Expertise | D11: # | E11: 0 | F11: 1 | G11: 0 | H11: 0 | I11: 0 | J11: 0 | K11: 0 | L11: 0 | M11: 0 | N11: 0 | O11: 0 | P11: 0 | Q11: 0 | R11: 0 | S11: 0 | T11: 0 | U11: 0 | V11: 0
B12: Horizontal | C12: AI Governance Center of Expertise | D12: AI Engineering | E12: 0 | F12: 1 | G12: 0 | H12: 8 | I12: 1 | J12: 8 | K12: 8 | L12: 10 | M12: 10 | N12: 12 | O12: 12 | P12: 15 | Q12: 15 | R12: 15 | S12: 15 | T12: 15 | U12: 15 | V12: 15
B13: Horizontal | C13: AI Governance Center of Expertise | D13: AI Governance | E13: 0 | F13: 0 | G13: 0 | H13: 2 | I13: 0 | J13: 2 | K13: 2 | L13: 2 | M13: 2 | N13: 2 | O13: 2 | P13: 2 | Q13: 2 | R13: 2 | S13: 2 | T13: 2 | U13: 2 | V13: 2
B14: Horizontal | C14: AI Governance Center of Expertise | D14: AI Platforms | E14: 0 | F14: 1 | G14: 0 | H14: 1 | I14: 1 | J14: 1 | K14: 2 | L14: 2 | M14: 2 | N14: 2 | O14: 2 | P14: 2 | Q14: 2 | R14: 2 | S14: 2 | T14: 2 | U14: 2 | V14: 2
B15: Horizontal | C15: Architecture Center of Expertise | D15: # | E15: 0 | F15: 1 | G15: 0 | H15: 0 | I15: 1 | J15: 0 | K15: 1 | L15: 1 | M15: 1 | N15: 1 | O15: 1 | P15: 1 | Q15: 1 | R15: 1 | S15: 1 | T15: 1 | U15: 1 | V15: 1
B16: Horizontal | C16: Architecture Center of Expertise | D16: Architecture Center of Expertise | E16: 0 | F16: 6 | G16: 0 | H16: 2 | I16: 6 | J16: 2 | K16: 6 | L16: 6 | M16: 7 | N16: 7 | O16: 7 | P16: 8 | Q16: 8 | R16: 8 | S16: 8 | T16: 8 | U16: 8 | V16: 8
B17: Horizontal | C17: International Reporting and MIS Department | D17: # | E17: 0 | F17: 1 | H17: 0 | I17: 1 | J17: 0 | K17: 1 | L17: 1 | M17: 1 | N17: 1 | O17: 1 | P17: 1 | Q17: 1 | R17: 1 | S17: 1 | T17: 1 | U17: 1 | V17: 1
B18: Horizontal | C18: International Reporting and MIS Department | D18: MIS Reporting | E18: 0 | F18: 4 | G18: 1 | H18: 0 | I18: 4 | J18: 0 | K18: 4 | L18: 4 | M18: 4 | N18: 4 | O18: 4 | P18: 4 | Q18: 5 | R18: 5 | S18: 5 | T18: 5 | U18: 5 | V18: 5
B19: Horizontal | C19: International Reporting and MIS Department | D19: IFRS Reporting | E19: 0 | F19: 2 | G19: 2 | H19: 4 | I19: 7 | J19: 0 | K19: 6 | L19: 6 | M19: 6 | N19: 6 | O19: 6 | P19: 6 | Q19: 7 | R19: 7 | S19: 7 | T19: 9 | U19: 9 | V19: 9
B20: Horizontal | C20: International Reporting and MIS Department | D20: Modelling, Valuation and Consolidated Reporting | E20: 0 | F20: 4 | G20: 0 | H20: 4 | I20: 6 | J20: 2 | K20: 7 | L20: 7 | M20: 7 | N20: 7 | O20: 7 | P20: 7 | Q20: 7 | R20: 7 | S20: 7 | T20: 7 | U20: 7 | V20: 7
B21: Horizontal | C21: BirApp Area | D21: # | E21: 0 | F21: 1 | G21: 0 | H21: 0 | I21: 1 | J21: 0 | K21: 1 | L21: 1 | M21: 1 | N21: 1 | O21: 1 | P21: 1 | Q21: 1 | R21: 1 | S21: 1 | T21: 1 | U21: 1 | V21: 1
B22: Horizontal | C22: BirApp Area | D22: Bir Enabler | E22: 0 | F22: 1 | G22: 0 | H22: 0 | I22: 1 | J22: 0 | K22: 1 | L22: 1 | M22: 1 | N22: 1 | O22: 1 | P22: 1 | Q22: 1 | R22: 1 | S22: 1 | T22: 1 | U22: 1 | V22: 1
B23: Horizontal | C23: BirApp Area | D23: Birbank Mainpage | E23: 0 | F23: 1 | G23: 0 | H23: 0 | I23: 1 | J23: 0 | K23: 1 | L23: 1 | M23: 1 | N23: 1 | O23: 1 | P23: 1 | Q23: 1 | R23: 1 | S23: 1 | T23: 1 | U23: 1 | V23: 1
B24: Horizontal | C24: BirApp Area | D24: Travel | E24: 0 | F24: 1 | G24: 0 | H24: 0 | I24: 1 | J24: 0 | K24: 0 | L24: 0 | M24: 0 | N24: 0 | O24: 0 | P24: 0 | Q24: 0 | R24: 0 | S24: 0 | T24: 0 | U24: 0 | V24: 0
B25: Horizontal | C25: BirApp Area | D25: Bir Search | E25: 0 | F25: 1 | G25: 0 | H25: 0 | I25: 1 | J25: 0 | K25: 1 | L25: 1 | M25: 1 | N25: 1 | O25: 1 | P25: 1 | Q25: 1 | R25: 1 | S25: 1 | T25: 1 | U25: 1 | V25: 1
B26: Horizontal | C26: BirApp Technology Area | D26: # | F26: 1 | I26: 1 | K26: 1 | L26: 1 | M26: 1 | N26: 1 | O26: 1 | P26: 1 | Q26: 1 | R26: 1 | S26: 1 | T26: 1 | U26: 1 | V26: 1
B27: Horizontal | C27: BirApp Technology Area | D27: Birbank Platform | E27: 0 | F27: 1 | G27: 0 | H27: 1 | I27: 1 | J27: 1 | K27: =I27 -> 1 | L27: =K27 -> 1 | M27: =L27 -> 1 | N27: =M27 -> 1 | O27: =N27 -> 1 | P27: =O27 -> 1 | Q27: =P27+J27 -> 2 | R27: =Q27 -> 2 | S27: =R27 -> 2 | T27: =S27 -> 2 | U27: =T27 -> 2 | V27: =U27 -> 2
B28: Horizontal | C28: BirApp Technology Area | D28: Birbank SRE | E28: 0 | F28: 0 | G28: 0 | H28: 0 | I28: 0 | J28: 0 | K28: 0 | L28: 0 | M28: 0 | N28: 0 | O28: 0 | P28: 0 | Q28: 0 | R28: 0 | S28: 0 | T28: 0 | U28: 0 | V28: 0
B29: Horizontal | C29: Data Governance Center of Expertise | D29: # | E29: 0 | F29: 1 | G29: 0 | H29: 0 | I29: 1 | J29: 0 | K29: 1 | L29: 1 | M29: 1 | N29: 1 | O29: 1 | P29: 1 | Q29: 1 | R29: 1 | S29: 1 | T29: 1 | U29: 1 | V29: 1
B30: Horizontal | C30: Data Governance Center of Expertise | D30: Data Process Management | E30: 0 | F30: 3 | G30: 0 | H30: 2 | I30: 3 | J30: 2 | K30: 3 | L30: 3 | M30: 4 | N30: 4 | O30: 5 | P30: 5 | Q30: 5 | R30: 5 | S30: 5 | T30: 5 | U30: 5 | V30: 5
B31: Horizontal | C31: Data Governance Center of Expertise | D31: Data Quality | E31: 0 | F31: 6 | G31: 0 | H31: 2 | I31: 6 | J31: 2 | K31: 6 | L31: 6 | M31: 6 | N31: 7 | O31: 7 | P31: 8 | Q31: 8 | R31: 8 | S31: 8 | T31: 8 | U31: 8 | V31: 8
B32: Horizontal | C32: Data Governance Center of Expertise | D32: Data Steward | E32: 0 | F32: 10 | G32: 0 | H32: 6 | I32: 10 | J32: 6 | K32: 10 | L32: 10 | M32: 12 | N32: 14 | O32: 14 | P32: 16 | Q32: 16 | R32: 16 | S32: 16 | T32: 16 | U32: 16 | V32: 16
B33: Horizontal | C33: Data mühəndisliyi və texnologiyaları ekspert mərkəzi | D33: # | E33: 0 | F33: 1 | G33: 0 | H33: 0 | I33: 1 | J33: 0 | K33: 1 | L33: =K33 -> 1 | M33: =L33 -> 1 | N33: =M33 -> 1 | O33: =N33 -> 1 | P33: =O33 -> 1 | Q33: =P33 -> 1 | R33: =Q33 -> 1 | S33: =R33 -> 1 | ... U33: =T33 -> 1 | V33: 1
B34: Horizontal | C34: Data mühəndisliyi və texnologiyaları ekspert mərkəzi | D34: Data engineering 1 | E34: 0 | F34: 6 | G34: 0 | H34: 1 | I34: 6 | J34: 1 | K34: 7 | L34: 7 | M34: 7 | N34: 7 | O34: 7 | P34: 7 | Q34: 7 | R34: 7 | S34: 7 | T34: 7 | U34: 7 | V34: 7
B35: Horizontal | C35: Data mühəndisliyi və texnologiyaları ekspert mərkəzi | D35: Data engineering 2 | E35: 0 | F35: 6 | G35: 1 | H35: 2 | I35: 6 | J35: 1 | K35: 7 | L35: 7 | M35: 7 | N35: 7 | O35: 7 | P35: 7 | Q35: 7 | R35: 7 | S35: 7 | T35: 7 | U35: 7 | V35: 7
B36: Horizontal | C36: Data mühəndisliyi və texnologiyaları ekspert mərkəzi | D36: Data engineering 3 | E36: 0 | F36: 5 | G36: 0 | H36: 1 | I36: 5 | J36: 1 | K36: 6 | L36: 6 | M36: 6 | N36: 6 | O36: 6 | P36: 6 | Q36: 6 | R36: 6 | S36: 6 | T36: 6 | U36: 6 | V36: 6
B37: Horizontal | C37: Data mühəndisliyi və texnologiyaları ekspert mərkəzi | D37: Data engineering 4 | E37: 0 | F37: 5 | G37: 0 | H37: 0 | I37: 5 | J37: 0 | K37: 5 | L37: 5 | M37: 5 | N37: 5 | O37: 5 | P37: 5 | Q37: 5 | R37: 5 | S37: 5 | T37: 5 | U37: 5 | V37: 5
B38: Horizontal | C38: Data və Analitika departamenti(Marketplace) | D38: Data Engineering | E38: 0 | F38: 4 | G38: 0 | H38: 0 | I38: 4 | J38: 0 | K38: 4 | L38: 4 | M38: 4 | N38: 4 | O38: 4 | P38: 4 | Q38: 4 | R38: 4 | S38: 4 | T38: 4 | U38: 4 | V38: 4
B39: Horizontal | C39: Design Center of Expertise | D39: # | E39: 0 | F39: 4 | G39: 0 | H39: 4 | I39: 7 | J39: 1 | K39: 0 | L39: 0 | M39: 0 | N39: 0 | O39: 0 | P39: 0 | Q39: 0 | R39: 0 | S39: 0 | T39: 0 | U39: 0 | V39: 8
B40: Horizontal | C40: Design Center of Expertise | D40: Product Designer 1 | E40: 0 | F40: 9 | G40: 1 | H40: 0 | I40: 9 | J40: 1 | K40: 0 | L40: 0 | M40: 0 | N40: 0 | O40: 0 | P40: 0 | Q40: 0 | R40: 0 | S40: 0 | T40: 0 | U40: 0 | V40: 10
...

Sheet Full list (horizontal)
B2: Company | C2: Full name | E2: Department | F2: Division | G2: Position | H2: Status
B3: Kapital Bank | C3: Ağayeva Aysel Babakişi | E3: Korporativ katiblik şöbəsi | F3: Korporativ katiblik şöbəsi | G3: Şöbə müdiri | H3: HR listinde var
B4: Kapital Bank | C4: Bayramova Aynur Zirəddin | E4: Korporativ katiblik şöbəsi | F4: Korporativ katiblik şöbəsi | G4: Korporativ katib | H4: HR listinde var
B5: Kapital Bank | C5: Qasımlı Nəsibə Etibar | E5: Korporativ katiblik şöbəsi | F5: Korporativ katiblik şöbəsi | G5: Aparıcı mütəxəssis | H5: HR listinde var
B6: Kapital Bank | C6: Vəliyeva Nəsrin İsmayıl | E6: Korporativ katiblik şöbəsi | F6: Korporativ katiblik şöbəsi | G6: Aparıcı mütəxəssis | H6: HR listinde var
B7: Kapital Bank | C7: Əliyeva Lalə Sənan | E7: Korporativ katiblik şöbəsi | F7: Korporativ katiblik şöbəsi | G7: Mütəxəssis | H7: HR listinde var
B8: Kapital Bank | C8: Ağayeva Xanım Çingiz | E8: Korporativ katiblik şöbəsi | F8: Korporativ katiblik şöbəsi | G8: Mütəxəssis | H8: HR listinde var
B9: Kapital Bank | C9: Teymurzadə Səma Bəylər | E9: Korporativ katiblik şöbəsi | F9: Korporativ katiblik şöbəsi | G9: Mütəxəssis | H9: HR listinde var
B10: Kapital Bank | C10: Abdullayeva Leyla Rüstəm | E10: Korporativ katiblik şöbəsi | F10: Korporativ katiblik şöbəsi | G10: Mütəxəssis | H10: HR listinde var
B11: Kapital Bank | C11: Mehdiyeva Fərəh Şahin | E11: Korporativ katiblik şöbəsi | F11: Korporativ katiblik şöbəsi | G11: Şəxsi köməkçi | H11: HR listinde var
B12: Kapital Bank | C12: Hacıyev Anar Nadir | E12: Korporativ katiblik şöbəsi | F12: Korporativ katiblik şöbəsi | G12: Şəxsi köməkçi | H12: HR listinde var
B13: Kapital Bank | C13: Tağıyeva Elnarə Əli | E13: Korporativ katiblik şöbəsi | F13: Korporativ katiblik şöbəsi | G13: Şəxsi köməkçi | H13: HR listinde var
... B18: Kapital Bank | C18: İsmayılova Şükufə Muxalif | E18: Korporativ katiblik şöbəsi | F18: Korporativ katiblik şöbəsi | G18: Şəxsi köməkçi | H18: HR listinde var
B19: Future Lab | C19: Məmmədova Xumar Elşən | D19: =VLOOKUP(C19,'[1]Birbank İşçi Siyahı'!$B:$I,8,) -> Future lab | E19: Korporativ katiblik şöbəsi | F19: Korporativ katiblik şöbəsi | G19: Şəxsi köməkçi | H19: HR listinde var
B20: Kapital Bank | C20: Yahyayeva Emiliya Rasim | E20: Korporativ katiblik şöbəsi | F20: Korporativ katiblik şöbəsi | G20: Şəxsi köməkçi | H20: HR listinde var
B21: Kapital Bank | C21: Məmmədova Nərgiz Aydın | E21: Korporativ katiblik şöbəsi | F21: Korporativ katiblik şöbəsi | G21: Şəxsi köməkçi | H21: HR listinde var
B22: Kapital Bank | C22: Vəlili İranə İlmas | E22: Korporativ katiblik şöbəsi | F22: Korporativ katiblik şöbəsi | G22: Şəxsi köməkçi | H22: HR listinde var
B23: Kapital Bank | C23: Məmmədova Fidan Tahir | E23: Korporativ katiblik şöbəsi | F23: Korporativ katiblik şöbəsi | G23: Şəxsi köməkçi (əvəzçilik qaydasında) | H23: HR listinde var
B24: Kapital Bank | C24: Kərimova Mehparə Məmmədsadıq | E24: Korporativ katiblik şöbəsi | F24: Korporativ katiblik şöbəsi | G24: Menecer | H24: HR listinde var
B25: Kapital Bank | C25: Rzayeva Ülkər Bəhram | E25: Korporativ katiblik şöbəsi | F25: Korporativ katiblik şöbəsi | G25: Aparıcı mütəxəssis | H25: HR listinde var
B26: Kapital Bank | C26: Məmmədova Ramilə Vaqif | E26: Korporativ katiblik şöbəsi | F26: Korporativ katiblik şöbəsi | G26: Aparıcı mütəxəssis | H26: HR listinde var
B27: Kapital Bank | C27: Səfərli Vüsalə Novruz | E27: Korporativ katiblik şöbəsi | F27: Korporativ katiblik şöbəsi | G27: Aparıcı mütəxəssis | H27: HR listinde var
B28: Kapital Bank | C28: Aslanlı Tərlan Yusif | E28: Korporativ katiblik şöbəsi | F28: Korporativ katiblik şöbəsi | G28: Mütəxəssis | H28: HR listinde var
B29: Kapital Bank | C29: İsmayılova Aysel Qələmdar | E29: Korporativ katiblik şöbəsi | F29: Korporativ katiblik şöbəsi | G29: Mütəxəssis | H29: HR listinde var
B30: Kapital Bank | C30: Şeydayeva Ceyla Zəki | E30: Korporativ katiblik şöbəsi | F30: Korporativ katiblik şöbəsi | G30: Mütəxəssis | H30: HR listinde var
B31: Kapital Bank | C31: Raşimov Süleyman Rafik | E31: Korporativ katiblik şöbəsi | F31: Korporativ katiblik şöbəsi | G31: Mütəxəssis | H31: HR listinde var
... B36: Competo | C36: Əliyeva Sona Azad | E36: Korporativ katiblik şöbəsi | F36: Korporativ katiblik şöbəsi | G36: Reception (Rəsmiləşmə mərhələsində) | H36: HR listinde yox idi
B37: Kapital Bank | C37: Kərimova Gülnar Sahib | D37: =VLOOKUP(C37,'[1]Birbank İşçi Siyahı'!$B:$I,8,) -> #N/A | E37: Korporativ katiblik şöbəsi | F37: Korporativ katiblik şöbəsi | G37: Şəxsi köməkçi | H37: HR listinde yox idi
B38: Kapital Bank | C38: Qarayeva Melisa İsmayil | D38: =VLOOKUP(C38,'[1]Birbank İşçi Siyahı'!$B:$I,8,) -> #N/A | E38: Korporativ katiblik şöbəsi | F38: Korporativ katiblik şöbəsi | G38: Şəxsi köməkçi | H38: Staff listində yoxdur
B39: Kapital Bank | C39: Nuri Şahnaz Səməd | E39: Agile və məhsul ekspert mərkəzi | F39: Agile və məhsul ekspert mərkəzi | G39: Funksional sahə lideri | H39: HR listinde var
B40: Kapital Bank | C40: Səidova Samirə Balasultan | E40: Agile və məhsul ekspert mərkəzi | F40: Agile və məhsul ekspert mərkəzi | G40: Funksional lider | H40: HR listinde var
B41: Kapital Bank | C41: Qurbanova Fatma Xasməmməd | E41: Agile və məhsul ekspert mərkəzi | F41: Agile və məhsul ekspert mərkəzi | G41: Proseslər üzrə ekspert | H41: HR listinde var
B42: Pashapay | C42: BARANOVSKAYA SVETLANA | D42: =VLOOKUP(C42,'[1]Birbank İşçi Siyahı'!$B:$I,8,) -> Bir Payment | E42: Agile və məhsul ekspert mərkəzi | F42: Agile və məhsul ekspert mərkəzi | G42: Agile kouç | H42: HR listinde var
B43: Kapital Bank | C43: Əlizadə Turqut Elşən | E43: Agile və məhsul ekspert mərkəzi | F43: Agile və məhsul ekspert mərkəzi | G43: Scrum master | H43: HR listinde var
B44: Pashapay | C44: Adilzadə Aysu Elnur | D44: =VLOOKUP(C44,'[1]Birbank İşçi Siyahı'!$B:$I,8,) -> Bir Payment | E44: Agile və məhsul ekspert mərkəzi | F44: Agile və məhsul ekspert mərkəzi | G44: Scrum master | H44: HR listinde var
B45: Kapital Bank | C45: FOMINA MARIIA | D45: =VLOOKUP(C45,'[1]Birbank İşçi Siyahı'!$B:$I,8,) -> #N/A | E45: Agile və məhsul ekspert mərkəzi | F45: Agile və məhsul ekspert mərkəzi | G45: Agile kouç | H45: HR listinde var
B46: Kapital Bank | C46: Əhmədov Azər Qabil | E46: Agile və məhsul ekspert mərkəzi | F46: Agile və məhsul ekspert mərkəzi | G46: Scrum master | H46: HR listinde var
B47: Kapital Bank | C47: Musayeva Səmanə Kəmaləddin | E47: Agile və məhsul ekspert mərkəzi | F47: Agile və məhsul ekspert mərkəzi | G47: Proseslər üzrə ekspert | H47: HR listinde var
B48: Kapital Bank | C48: Əkbərova Vəsilə Vidadi | E48: Agile və məhsul ekspert mərkəzi | F48: Agile və məhsul ekspert mərkəzi | G48: Scrum master(müvəqqəti) | H48: HR listinde var
B49: Kapital Bank | C49: Şirinov Azər Qafar | E49: Agile və məhsul ekspert mərkəzi | F49: Agile və məhsul ekspert mərkəzi | G49: Agile kouç | H49: HR listinde var
...
